Workbook
Name Input_Date: '[1]9.91 OPERA (84)'!$BV$4:$BV$22
Name Input_Date_2: '[1]9.92 OPERA (85)'!$BV$4:$BV$21
Name Input_Date_3: '[1]9.94 OPERA (87)'!$CT$4:$CT$22
Name YEAR: '[1]9.40 Malaysia (Trent XWB)'!$BV$22:$BV$41

Sheet SoA Summary
B2: Current Debt Position
B3: Type | C3: Amount overdue
B4: TotalCare | C4: ='SoA 26.1.26'!F19 -> 0
B5: CRC | C5: ='SoA 26.1.26'!F65 -> 19419421
B6: Spare Parts | C6: ='SoA 26.1.26'!F109 -> 581179
B7: LPI | C7: ='SoA 26.1.26'!F125 -> 1087289.2
B8: Total Overdue | C8: =SUM(C4:C7) -> 21087889
B10: Available Credit
B11: Type | C11: Value
B12: CRC ULW | C12: ='SoA 26.1.26'!F66 -> -40166155
B13: Other | C13: ='SoA 26.1.26'!F10 -> -28217715
B14: Total Credit | C14: =SUM(C12:C13) -> -68383870
B16: LPI
B17: Type | C17: Value
B18: Invoiced | C18: =SUMIF('SoA 26.1.26'!H69:H119,"Late Payment Invoice",'SoA 26.1.26'!F69:F119) -> 1050679.4
B19: Not yet invoiced (cum.) | C19: =SUM('SoA 26.1.26'!O:O) -> 465124.51
B20: Total | C20: =SUM(C18:C19) -> 1515803.9

Sheet SoA 26.1.26
A1: Ethiopian Statement of Account with Rolls-Royce
A2: Customer Name: | C2: Ethiopian Airlines / EA Enterprise | K2: LPI rate > | L2: 0.00035
A3: Customer Nº: | C3: 1009374 / 1014433
A4: Contact email: | C4: Eyerusalemta@ethiopianairlines.com | K4: Today > | L4: =TODAY() -> 46069
K5: AVERAGE DAYS LATE = | L5: =AVERAGE(L12:L68) -> 113.93103
A7: Company Code | B7: Account | C7: Reference | D7: Document Date | E7: Net due date | F7: Amount in doc. curr. | G7: Curr | H7: Text | I7: Assignment | J7: R-R Comments | K7: Action Owner / Awaiting Approval | L7: DAYS LATE | M7: ETH Comments | N7: ETH PO Reference | O7: LPI Cumulated
A8: Credits usable | Q8: INVOICE
C9: 1620061217 | D9: 45806 | F9: -28217715 | G9: USD | H9: TRENT 1000 NON-EXCUSABLE DELAY CREDIT. | J9: 1 Apr - 31 Dec 24, 1 Jan - 30 Apr 25 | M9: Used in part for CRC offset June 25. | Q9: 1620061893
E10: Total | F10: =SUM(F9:F9) -> -28217715 | Q10: 99600294
Q11: 99630101
A12: TotalCare Charges | Q12: 1620062267
A13: 1200 | B13: 1009374 | C13: 99648079 | D13: 46003 | E13: 46054 | F13: 1701900.7 | G13: USD | H13: TotalCare - Trent 1000-D | I13: DEG 9054 | K13: ET to process | L13: =IF(('SoA 26.1.26'!$L$4-E13)<0,"",'SoA 26.1.26'!$L$4-E13) -> 15 | M13: Not released from Tech Support | O13: =(IF(AND(F13>0,('SoA 26.1.26'!$L$4-E13)>0),((F13*((1+('SoA 26.1.26'!$L$2*30))^(ROUNDDOWN((('SoA 26.1.26'!$L$4-E13)/30),0)))-F13))+(F13+(ROUNDDOWN((('SoA 26.1.26'!$L$4-E13)/30),0)))*'SoA 26.1.26'!$L$2*(30*((('SoA 26.1.26'!$L$4-E13)/30)-(ROUNDDOWN((('SoA 26.1.26'!$L$4-E13)/30),0)))),0)) -> 8934.9785 | Q13: 99540446
A14: 1200 | B14: 1009374 | C14: 99648074 | D14: 46003 | E14: 46054 | F14: 1859754.7 | G14: USD | H14: TotalCare - Trent 1000-K | I14: DEG 9054 | K14: ET to process | L14: =IF(('SoA 26.1.26'!$L$4-E14)<0,"",'SoA 26.1.26'!$L$4-E14) -> 15 | M14: Not released from Tech Support | O14: =(IF(AND(F14>0,('SoA 26.1.26'!$L$4-E14)>0),((F14*((1+('SoA 26.1.26'!$L$2*30))^(ROUNDDOWN((('SoA 26.1.26'!$L$4-E14)/30),0)))-F14))+(F14+(ROUNDDOWN((('SoA 26.1.26'!$L$4-E14)/30),0)))*'SoA 26.1.26'!$L$2*(30*((('SoA 26.1.26'!$L$4-E14)/30)-(ROUNDDOWN((('SoA 26.1.26'!$L$4-E14)/30),0)))),0)) -> 9763.7121 | Q14: 99540450
A15: 1200 | B15: 1009374 | C15: 99648089 | D15: 46003 | E15: 46054 | F15: 2183708.8 | G15: USD | H15: TotalCare - Trent XWB-97 | I15: DEG 10215 | K15: ET to process | M15: Not released from Tech Support | Q15: 99645940
A16: 1200 | B16: 1009374 | C16: 99648084 | D16: 46003 | E16: 46054 | F16: 7491732.3 | G16: USD | H16: TotalCare - Trent XWB-84 | I16: DEG 10215 | K16: ET to process | M16: Not released from Tech Support | Q16: 99645934
Q17: 99645930
E18: Total | F18: =SUM(F13:F14:F15:F16) -> 13237096 | Q18: 99542667
E19: Overdue | F19: =SUMIF(L15:L16, ">0", F15:F16) -> 0 | Q19: 99615649
Q20: 99615641
A21: Customer Responsible Charges | Q21: 99615640
A22: 1200 | B22: 1009374 | C22: 1820146074 | D22: 45218 | E22: 45249 | F22: 318419 | G22: USD | H22: CRC - Line Maintenance | I22: CRC for ESN 10499 | J22: Disputed ET engine air leak | K22: R-R | L22: =IF(($L$4-E22)<0,"",$L$4-E22) -> 820 | M22: Waiting ET Line Maintenance Review | O22: =(IF(AND(F22>0,($L$4-E22)>0),((F22*((1+($L$2*30))^(ROUNDDOWN((($L$4-E22)/30),0)))-F22))+(F22+(ROUNDDOWN((($L$4-E22)/30),0)))*$L$2*(30*((($L$4-E22)/30)-(ROUNDDOWN((($L$4-E22)/30),0)))),0)) -> 104857.97 | Q22: 99615643
A23: 1200 | B23: 1009374 | C23: 1620059837 | D23: 45562 | F23: -1042434.1 | G23: USD | H23: Credit note for 21104 LPT | I23: Credit for 21104 | K23: RR to issue invoice | M23: To correct error with LPT | O23: =(IF(AND(F23>0,($L$4-E23)>0),((F23*((1+($L$2*30))^(ROUNDDOWN((($L$4-E23)/30),0)))-F23))+(F23+(ROUNDDOWN((($L$4-E23)/30),0)))*$L$2*(30*((($L$4-E23)/30)-(ROUNDDOWN((($L$4-E23)/30),0)))),0)) -> 0 | Q23: 99615645
A24: 1200 | B24: 1009374 | C24: 2000638764 | D24: 45884 | F24: -168000 | G24: USD | H24: Credit for 11138 | I24: Credit 11138 | M24: Credit to reflect SUM not new | O24: =(IF(AND(F24>0,($L$4-E24)>0),((F24*((1+($L$2*30))^(ROUNDDOWN((($L$4-E24)/30),0)))-F24))+(F24+(ROUNDDOWN((($L$4-E24)/30),0)))*$L$2*(30*((($L$4-E24)/30)-(ROUNDDOWN((($L$4-E24)/30),0)))),0)) -> 0 | Q24: 99615647
A25: 1200 | B25: 1009374 | C25: 2000638769 | D25: 45884 | F25: -123153 | G25: USD | H25: Credit for 10590 | I25: Credit 10590 | M25: Credit to reflect SUM not new | O25: =(IF(AND(F25>0,($L$4-E25)>0),((F25*((1+($L$2*30))^(ROUNDDOWN((($L$4-E25)/30),0)))-F25))+(F25+(ROUNDDOWN((($L$4-E25)/30),0)))*$L$2*(30*((($L$4-E25)/30)-(ROUNDDOWN((($L$4-E25)/30),0)))),0)) -> 0 | Q25: 99615646
A26: 1200 | B26: 1009374 | C26: 99057194 | D26: 45642 | E26: 45672 | F26: 555734.33 | G26: USD | H26: CRC for 21105 | I26: CRC for 21105 | J26: Balance Invoice Disputed. Insurer rejected claim | K26: Alemnah to review | L26: =IF(($L$4-E26)<0,"",$L$4-E26) -> 397 | M26: Balance from bird strike CRC fan blades and acoustic panels. | O26: =(IF(AND(F26>0,($L$4-E26)>0),((F26*((1+($L$2*30))^(ROUNDDOWN((($L$4-E26)/30),0)))-F26))+(F26+(ROUNDDOWN((($L$4-E26)/30),0)))*$L$2*(30*((($L$4-E26)/30)-(ROUNDDOWN((($L$4-E26)/30),0)))),0)) -> 82187.27 | Q26: 99615644
A27: 1200 | B27: 1009374 | C27: 1820158804 | D27: 45849 | E27: 45879 | F27: 47900 | G27: USD | H27: OWS 10509 EGB replacement charges | J27: Disputed | L27: =IF(($L$4-E27)<0,"",$L$4-E27) -> 190 | N27: 4590160364 | Q27: 99615642
A28: 1200 | B28: 1009374 | C28: 1620061893 | D28: 45922 | F28: -341535.28 | G28: USD | H28: Credit note 21299 | I28: Credit 21299 | J28: Ready For Payment | Q28: 99615648
A29: 1200 | B29: 1009374 | C29: 99600294 | D29: 45974 | E29: 46004 | F29: 516997.85 | G29: USD | H29: CRC LLP for 21299 | I29: CRC 21299 | J29: Ready For Payment | L29: =IF(($L$4-E29)<0,"",$L$4-E29) -> 65 | M29: Paid this week, final stage. | Q29: 99661192
A30: 1200 | B30: 1009374 | C30: 1620061894 | D30: 45922 | F30: -5304093.4 | G30: USD | H30: Credit note for 21814 | I30: Credit 21814 | J30: DACS Summary provided. NET OFF CREDIT | Q30: 99666161
A31: 1200 | B31: 1009374 | C31: 99661057 | D31: 46378 | E31: 46043 | F31: 7254617.1 | G31: USD | H31: CRC LLP 21814 | I31: CRC 21814 | J31: Under approval | L31: =IF(($L$4-E31)<0,"",$L$4-E31) -> 26 | M31: Under approval | Q31: 99666160
A32: 1200 | B32: 1009374 | C32: 1620062188 | D32: 45967 | F32: -5424372 | G32: USD | H32: Credit note for 21428 | I32: Credit 21428 | J32: DACS Summary provided | Q32: 99666159
A33: 1200 | B33: 1009374 | C33: 1620062187 | D33: 45967 | F33: -5562918.8 | G33: USD | H33: Credit note 21950 | I33: Credit 21950 | J33: DACS Summary provided | Q33: 99674528
A34: 1200 | B34: 1009374 | C34: 99630101 | D34: 45993 | E34: 46023 | F34: 2227793.9 | G34: USD | H34: CRC LLP 11109 | I34: CRC 11109 | J34: Ready For Payment | L34: =IF(($L$4-E34)<0,"",$L$4-E34) -> 46 | M34: Approved Tech Support pay next week | Q34: 99674529
A35: 1200 | B35: 1009374 | C35: 1620062267 | D35: 45980 | F35: -1759792.7 | G35: USD | H35: Credit note 11109 | I35: Credit 11109 | J35: Ready For Payment | Q35: 99674530
A36: 1200 | B36: 1009374 | C36: 3000121886 | D36: 45909 | F36: -2389260.7 | G36: USD | H36: Credit note 21185 | I36: Credit 21185 | J36: DACS Summary provided | Q36: 99674531
A37: 1200 | B37: 1009374 | C37: 1620062566 | D37: 46015 | F37: -5470072.1 | G37: USD | H37: Credit note 21608 | I37: Credit 21608 | J37: DACS Summary provided | Q37: 99700686
A38: 1200 | B38: 1009374 | C38: 1620062565 | D38: 46015 | F38: -7085775.8 | G38: USD | H38: Credit note 21376 | I38: Credit 21376 | J38: DACS Summary provided | Q38: 99683381
A39: 1200 | B39: 1009374 | C39: 1620062625 | D39: 46036 | F39: -5479868.7 | G39: USD | H39: Credit note 21171 | I39: Credit 21171 | J39: DACS Summary provided | Q39: 99683378
A40: 1200 | B40: 1009374 | C40: 99540446 | D40: 45938 | E40: 45968 | F40: 105107.09 | G40: USD | H40: CRC 21273 | I40: CRC 21273 | J40: Ready For Payment | L40: =IF(($L$4-E40)<0,"",$L$4-E40) -> 101 | M40: Under approval - paid before year end | N40: P0483839 | Q40: 99683379
A41: 1200 | B41: 1009374 | C41: 99540444 | D41: 45938 | E41: 45968 | F41: 145559.38 | G41: USD | H41: CRC 21229 | I41: CRC 21229 | J41: Under review | L41: =IF(($L$4-E41)<0,"",$L$4-E41) -> 101 | M41: Under review | Q41: 99683382
...

Sheet Offset
A2: Offset 28 May 25
A4: 1009374 | B4: 99036727 | C4: 45629 | D4: 45659 | E4: 70308.84 | G4: CRC for 21814
A5: 1009374 | B5: 99036726 | C5: 45629 | D5: 45659 | E5: 187920.02 | G5: CRC for 21602
A6: 1009374 | B6: 99036725 | C6: 45629 | D6: 45659 | E6: 176153.13 | G6: CRC for 21591
A7: 1009374 | B7: 99036724 | C7: 45629 | D7: 45659 | E7: 147596.69 | G7: CRC for 21564
A8: 1009374 | B8: 99036723 | C8: 45629 | D8: 45659 | E8: 209221.99 | G8: CRC for 21528
A9: 1009374 | B9: 99036704 | C9: 45629 | D9: 45659 | E9: 113386.82 | G9: CRC for 21299
A10: 1009374 | B10: 99036705 | C10: 45629 | D10: 45659 | E10: 1276395.1 | G10: CRC for 21299
A11: 1009374 | B11: 99036707 | C11: 45629 | D11: 45659 | E11: 40060.71 | G11: CRC for 21400
A12: 1009374 | B12: 99036709 | C12: 45629 | D12: 45659 | E12: 118120.98 | G12: CRC for 21405
A13: 1009374 | B13: 99036706 | C13: 45629 | D13: 45659 | E13: 16178.63 | G13: CRC for 21400
A14: 1009374 | B14: 99059380 | C14: 45643 | D14: 45673 | E14: 145575.75 | G14: CRC for 21185
A15: 1009374 | B15: 99059382 | C15: 45643 | D15: 45673 | E15: 54002.95 | G15: CRC for 21230
... A17: 1009374 | B17: 99059385 | C17: 45643 | D17: 45673 | E17: 183061.85 | G17: CRC for 21608
E19: =SUM(E4:E17) -> 2792006
A20: Offset 25 June 25
B22: 99179557 | C22: 45720 | D22: 45750 | E22: 28567.49 | G22: CRC for 21599
B23: 99179555 | C23: 45720 | D23: 45750 | E23: 392610.66 | G23: CRC for 21771
B24: 99179553 | C24: 45720 | D24: 45750 | E24: 256884.92 | G24: CRC for 21525
B25: 99179552 | C25: 45720 | D25: 45750 | E25: 268527.82 | G25: CRC for 21406
B26: 99179562 | C26: 45720 | D26: 45750 | E26: 397114.57 | G26: CRC for 21599
B27: 99179576 | C27: 45720 | D27: 45750 | E27: 34552.55 | G27: CRC for 21525
B28: 99179578 | C28: 45720 | D28: 45750 | E28: 470710.66 | G28: CRC for 21104
B29: 99179579 | C29: 45720 | D29: 45750 | E29: 177109.23 | G29: CRC for 21405
B30: 99179582 | C30: 45720 | D30: 45750 | E30: 237185.97 | G30: CRC for 21528
B31: 99179588 | C31: 45720 | D31: 45750 | E31: 296833.18 | G31: CRC for 21140
B32: 99179598 | C32: 45720 | D32: 45750 | E32: 168458.12 | G32: CRC for 21229
B33: 99179600 | C33: 45720 | D33: 45750 | E33: 197661.55 | G33: CRC for 21230
... B64: 99184249 | C64: 45722 | D64: 45752 | E64: 34873.16 | G64: CRC for 21528
E66: 12306643

Sheet Paymen
A1: 46049
A5: 1200 | B5: 1009374 | C5: 99627769 | D5: 45992 | E5: 46023 | F5: 7491732.3 | G5: USD | H5: TotalCare - Trent XWB-84 | I5: DEG 10215 | K5: ET to process | L5: =IF(('SoA 26.1.26'!$L$4-E5)<0,"",'SoA 26.1.26'!$L$4-E5) -> 46 | M5: Under approval payment ? | N5: 4590160127 | O5: =(IF(AND(F5>0,('SoA 26.1.26'!$L$4-E5)>0),((F5*((1+('SoA 26.1.26'!$L$2*30))^(ROUNDDOWN((('SoA 26.1.26'!$L$4-E5)/30),0)))-F5))+(F5+(ROUNDDOWN((('SoA 26.1.26'!$L$4-E5)/30),0)))*'SoA 26.1.26'!$L$2*(30*((('SoA 26.1.26'!$L$4-E5)/30)-(ROUNDDOWN((('SoA 26.1.26'!$L$4-E5)/30),0)))),0)) -> 120616.9
A6: 1200 | B6: 1009374 | C6: 99627772 | D6: 45992 | E6: 46023 | F6: 2183708.8 | G6: USD | H6: TotalCare - Trent XWB-97 | I6: DEG 10215 | K6: ET to process | L6: =IF(('SoA 26.1.26'!$L$4-E6)<0,"",'SoA 26.1.26'!$L$4-E6) -> 46 | M6: Under approval payment ? | N6: 4590160125 | O6: =(IF(AND(F6>0,('SoA 26.1.26'!$L$4-E6)>0),((F6*((1+('SoA 26.1.26'!$L$2*30))^(ROUNDDOWN((('SoA 26.1.26'!$L$4-E6)/30),0)))-F6))+(F6+(ROUNDDOWN((('SoA 26.1.26'!$L$4-E6)/30),0)))*'SoA 26.1.26'!$L$2*(30*((('SoA 26.1.26'!$L$4-E6)/30)-(ROUNDDOWN((('SoA 26.1.26'!$L$4-E6)/30),0)))),0)) -> 35157.717
B7: Rolls-Royce plc
B8: INVOICE | C8: AMOUNT(USD)
B9: 1620061893 | C9: -341535.28
B10: 99600294 | C10: 516997.85
B11: 99630101 | C11: 2227793.9
B12: 1620062267 | C12: -1759792.7
B13: 99540446 | C13: 105107.09
B14: 99540450 | C14: 267054.86
B15: 99645940 | C15: 50336.34
B16: 99645934 | C16: 154410.93
B17: 99645930 | C17: 651811.51
B18: 99542667 | C18: 2384.13
B19: 99615649 | C19: 296.5
B20: 99615641 | C20: 882
... B44: 99700685 | C44: 6676
B45: TOTAL | C45: 2527584.1

Sheet 2022 Cash payments
A1: Ethiopian Statement of Account with Rolls-Royce
A2: Customer Name: | C2: Ethiopian Airlines / EA Enterprise
A3: Customer Nº: | C3: 1009374 / 1014433
A4: Contact email: | C4: Eyerusalemta@ethiopianairlines.com | K4: Today > | L4: =TODAY() -> 46069
K5: AVERAGE DAYS LATE = | L5: =AVERAGE(L9:L62) -> #DIV/0!
A7: Company Code | B7: Account | C7: Reference | D7: Document Date | E7: Net due date | F7: Amount in doc. curr. | G7: Curr | H7: Text | I7: Assignment | J7: Comments | K7: Comments | L7: DAYS LATE | M7: Current status
H8: W/C 07/02/22
A9: 1200 | B9: 1009374 | C9: 97466491 | D9: 44496 | E9: 44531 | F9: 4535354.9 | G9: USD | H9: TotalCare - Trent XWB-84 | I9: DEG 10215 December 2021 | J9: PAID | K9: 44601
A10: 2500 | B10: 1014433 | C10: 97490154 | D10: 44516 | E10: 44561 | F10: 46998 | G10: USD | H10: Lease Engine LLP Charges - Trent 1000 TEN | I10: ESN 11307 JANUARY 2021 | J10: PAID | K10: 44601
A11: 2500 | B11: 1014433 | C11: 97490167 | D11: 44516 | E11: 44561 | F11: 67140 | G11: USD | H11: Lease Engine LLP Charges - Trent 1000 Pack B/C | I11: ESN 10588 June 2021 | J11: PAID | K11: 44601
A12: 2500 | B12: 1014433 | C12: 97540553 | D12: 44561 | E12: 44606 | F12: 59680 | G12: USD | H12: Lease Engine LLP Charges - Trent 1000 Pack B/C | I12: ESN 10588 November 2021 | J12: PAID | K12: 44601
A13: 2500 | B13: 1014433 | C13: 97540559 | D13: 44561 | E13: 44606 | F13: 43600 | G13: USD | H13: Lease Engine LLP Charges - Trent 1000 Pack B/C | I13: ESN 10353 November 2021 | J13: PAID | K13: 44601
F14: =SUM(F9:F13) -> 4752772.9
H15: W/C 14/02/22
A16: 2500 | B16: 1014433 | C16: 97500018 | D16: 44525 | E16: 44570 | F16: 70870 | G16: USD | H16: Lease Engine LLP Charges - Trent 1000 Pack B/C | I16: ESN 10588 September 2021 | J16: PAID | K16: 44607
A17: 2500 | B17: 1014433 | C17: 97490171 | D17: 44516 | E17: 44561 | F17: 58934 | G17: USD | H17: Lease Engine LLP Charges - Trent 1000 Pack B/C | I17: ESN 10588 August 2021 | J17: PAID | K17: 44607
A18: 2500 | B18: 1014433 | C18: 97490162 | D18: 44516 | E18: 44561 | F18: 47744 | G18: USD | H18: Lease Engine LLP Charges - Trent 1000 Pack B/C | I18: ESN 10588 APRIL 2021 | J18: PAID | K18: 44607
A19: 2500 | B19: 1014433 | C19: 97490163 | D19: 44516 | E19: 44561 | F19: 64156 | G19: USD | H19: Lease Engine LLP Charges - Trent 1000 Pack B/C | I19: ESN 10559 APRIL 2021 | J19: PAID | K19: 44608
F20: =SUM(F16:F19) -> 241704
H21: W/C 21/02/22
A22: 1200 | B22: 1009374 | C22: 97417341 | D22: 44452 | E22: 44482 | F22: 806 | G22: USD | H22: Spare Parts | I22: 3A1-P0366840-1 | J22: PAID | K22: 44615
A23: 1200 | B23: 1009374 | C23: 97417342 | D23: 44452 | E23: 44482 | F23: 3680 | G23: USD | H23: Spare Parts | I23: P0366840-2 | J23: PAID | K23: 44615
A24: 1200 | B24: 1009374 | C24: 97417343 | D24: 44452 | E24: 44482 | F24: 2624 | G24: USD | H24: Spare Parts | I24: P0366840-3 | J24: PAID | K24: 44615
A25: 1200 | B25: 1009374 | C25: 97417344 | D25: 44452 | E25: 44482 | F25: 2807 | G25: USD | H25: Spare Parts | I25: P0366840-3 | J25: PAID | K25: 44615
A26: 1200 | B26: 1009374 | C26: 97438098 | D26: 44470 | E26: 44500 | F26: 162 | G26: USD | H26: Spare Parts | I26: 4F-P0357975 | J26: PAID | K26: 44615
A27: 1200 | B27: 1009374 | C27: 97438099 | D27: 44470 | E27: 44500 | F27: 16750 | G27: USD | H27: Spare Parts | I27: 4E-P0366970 | J27: PAID | K27: 44615
A28: 1200 | B28: 1009374 | C28: 97440885 | D28: 44472 | E28: 44502 | F28: 7100 | G28: USD | H28: Spare Parts | I28: 4E-P0366858 | J28: PAID | K28: 44615
A29: 1200 | B29: 1009374 | C29: 97442845 | D29: 44474 | E29: 44504 | F29: 38542 | G29: USD | H29: Spare Parts | I29: 4F-P0366042 | J29: PAID | K29: 44615
A30: 1200 | B30: 1009374 | C30: 97449172 | D30: 44481 | E30: 44511 | F30: 3582 | G30: USD | H30: Spare Parts | I30: 4F-P0368757 | J30: PAID | K30: 44615
A31: 1200 | B31: 1009374 | C31: 97451398 | D31: 44482 | E31: 44512 | F31: 75165 | G31: USD | H31: Spare Parts | I31: 4F-P0364791 | J31: PAID | K31: 44615
A32: 1200 | B32: 1009374 | C32: 97453801 | D32: 44484 | E32: 44514 | F32: 3154.5 | G32: USD | H32: Spare Parts | I32: 5X-P0369712 | J32: PAID | K32: 44615
A33: 1200 | B33: 1009374 | C33: 97455370 | D33: 44487 | E33: 44517 | F33: 453 | G33: USD | H33: Spare Parts | I33: 5X-P0369712 | J33: PAID | K33: 44615
... A54: 1200 | B54: 1009374 | C54: 97543780 | D54: 44565 | E54: 44595 | F54: 6744 | G54: USD | H54: Spare Parts | I54: 4A-P0376419 | J54: PAID | K54: 44615
A55: 1200 | B55: 1009374 | C55: 97452559 | D55: 44483 | E55: 44531 | F55: 1577970 | G55: USD | H55: TotalCare - Trent 1000-D | I55: DEG 9054 December 2021 | J55: PAID | K55: 44617
A56: 1200 | B56: 1009374 | C56: 97452560 | D56: 44483 | E56: 44531 | F56: 1239030 | G56: USD | H56: TotalCare - Trent 1000-K | I56: DEG 9054 December 2021 | J56: PAID | K56: 44617
A57: 2500 | B57: 1014433 | C57: 97490082 | D57: 44516 | E57: 44561 | F57: 49236 | G57: USD | H57: Lease Engine LLP Charges - Trent 1000 Pack B/C | I57: ESN 10588 JANUARY 2021 | J57: PAID | K57: 44617
A58: 2500 | B58: 1014433 | C58: 97490157 | D58: 44516 | E58: 44561 | F58: 12682 | G58: USD | H58: Lease Engine LLP Charges - Trent 1000 Pack B/C | I58: ESN 10559 FEBRUARY 2021 | J58: PAID | K58: 44617
A59: 2500 | B59: 1014433 | C59: 97490168 | D59: 44516 | E59: 44561 | F59: 57442 | G59: USD | H59: Lease Engine LLP Charges - Trent 1000 Pack B/C | I59: ESN 10559 June 2021 | J59: PAID | K59: 44617
A60: 2500 | B60: 1014433 | C60: 97312243 | D60: 44343 | E60: 44388 | F60: 39057 | G60: USD | H60: Lease Engine LLP Charges - Trent 1000 TEN | I60: ESN 11382 APRIL 2021 | J60: PAID | K60: 44617
A61: 2500 | B61: 1014433 | C61: 97490158 | D61: 44516 | E61: 44561 | F61: n | G61: USD | H61: Lease Engine LLP Charges - Trent 1000 Pack B/C | I61: ESN 10353 FEBRUARY 2021 | J61: PAID | K61: 44617
...

Sheet 2022 Credit Usage
A1: Customer Name: | C1: Ethiopian Airlines / EA Enterprise
A2: Customer Nº: | C2: 1009374 / 1014433
A3: Contact email: | C3: Eyerusalemta@ethiopianairlines.com
A6: Company Code | B6: Account | C6: Reference | D6: Document Date | E6: Net due date | F6: Amount in doc. curr. | G6: Curr | H6: Text | I6: Assignment | J6: Comments | K6: Comments
A7: 1200 | B7: 1014433 | C7: 1620053556 | D7: 44386 | E7: 44386 | F7: -693.46 | G7: USD | H7: Credit note balance | I7: ESN10509 Credit - settlement agreement | J7: Usable credit | K7: < Available to use
A8: 1200 | B8: 1014433 | C8: 1620053707 | D8: 44873 | E8: 44873 | F8: -7051465.8 | G8: USD | H8: Credit note balance | I8: 2021 Trent 1000 Reconciliation | J8: Usable credit | K8: < Available to use
E9: Available Credits | F9: =SUM(F7:F7) -> -693.46
A12: Company Code | B12: Account | C12: Reference | D12: Document Date | E12: Net due date | F12: Amount in doc. curr. | G12: Curr | H12: Text | I12: Assignment | J12: Comments | K12: Comments
A13: 1200 | B13: 1014433 | C13: 1620053927 | D13: 44483 | E13: 44483 | F13: -3350377.4 | G13: USD | H13: Credit note balance | I13: Warranty Credit - ULW - CRC ESN 21117 | J13: USED | K13: 97458467
A14: 1200 | B14: 1014433 | C14: 1620053917 | D14: 44482 | E14: 44482 | F14: -3276026.5 | G14: USD | H14: Credit note balance | I14: Warranty Credit - ULW - CRC ESN 21185 | J14: USED | K14: 97458474
A15: 1200 | B15: 1014433 | C15: 1620053925 | D15: 44483 | E15: 44483 | F15: -3279287.5 | G15: USD | H15: Credit note balance | I15: Warranty Credit - ULW - CRC ESN 21230 | J15: USED | K15: 97456818
A16: 1200 | B16: 1014433 | C16: 1620053926 | D16: 44483 | E16: 44483 | F16: -3287443.2 | G16: USD | H16: Credit note balance | I16: Warranty Credit - ULW - CRC ESN 21229 | J16: USED | K16: 97452578
A17: 1200 | B17: 1009374 | C17: 1620054520 | D17: 44610 | E17: 44610 | F17: -285188 | G17: USD | H17: Credit note balance | I17: DEG9054/CN13307 | J17: USED | K17: Numerous on 10/06/22
A18: 1200 | B18: 1014433 | C18: 1620052627 | D18: 44210 | E18: 44210 | F18: -105732.34 | G18: USD | H18: Credit note balance | I18: Q1 2020 Deferred Interim settlement | J18: USED | K18: 97625156
A19: 1200 | B19: 1014433 | C19: 1620053707 | D19: 44431 | E19: 44431 | F19: -11919 | G19: USD | H19: Credit note balance | I19: Failure on ESN 21942 on 24th Jul 2021 | J19: USED | K19: 97625156
A20: 1200 | B20: 1009374 | C20: 1620054739 | D20: 44659 | E20: 44659 | F20: -11711 | G20: USD | H20: WAG4990/CA6811 | I20: DEG6272/WAG4990 | J20: USED | K20: 97625156
A21: 1200 | B21: 1014433 | C21: 1620054140 | D21: 44526 | E21: 44526 | F21: -4499795.7 | G21: USD | H21: Credit note balance | I21: Warranty Credit - ULW - CRC ESN 10410 | J21: USED | K21: 97508399
A22: 1200 | B22: 1009374 | C22: 1620054753 | D22: 44662 | E22: 44692 | F22: -1426282 | G22: USD | H22: Credit note balance | I22: Warranty Credit - ULW - CRC ESN 11139 | J22: USED | K22: 97603008
A23: 1200 | B23: 1009374 | C23: 1620054330 | D23: 44571 | E23: 44571 | F23: -1423146.2 | G23: USD | H23: Credit note balance | I23: Warranty Credit - ULW - CRC ESN 11108 | J23: USED | K23: 97653372
A24: 1200 | B24: 1009374 | C24: 2000557281 | D24: 44729 | E24: 44792 | F24: =#REF! -> #REF! | G24: USD | H24: Credit note balance | I24: Trent XWB Reconciliation Credit | J24: USED | K24: 97730879, 97730878 & 97744202
A25: 1200 | B25: 1009374 | C25: 1620054991 | D25: 44729 | E25: 44759 | F25: -3526043.5 | G25: USD | H25: Credit note balance | I25: Warranty Credit - ULW - CRC ESN 21428 | J25: USED | K25: < Available to use
A26: 1200 | B26: 1009374 | C26: 1620054992 | D26: 44729 | E26: 44759 | F26: -3501286.2 | G26: USD | H26: Credit note balance | I26: Warranty Credit - ULW - CRC ESN 21294 | J26: USED | K26: < Available to use
A27: 1200 | B27: 1009374 | C27: 1620054818 | D27: 44662 | E27: 44692 | F27: -3502526.8 | G27: USD | H27: Credit note balance | I27: Warranty Credit - ULW - CRC ESN 21273 | J27: USED | K27: < Available to use
A28: 1200 | B28: 1009374 | C28: 1620054958 | D28: 44725 | E28: 44755 | F28: -1426282 | G28: USD | H28: Credit note balance | I28: Warranty Credit - ULW - CRC ESN 11138 | J28: USED | K28: < Available to use
A29: 1200 | B29: 1009374 | C29: 1620054993 | D29: 44729 | E29: 44759 | F29: -3315388.1 | G29: USD | H29: Credit note balance | I29: Warranty Credit - ULW - CRC ESN 21186 | J29: USED | K29: 97508400
A30: 1200 | B30: 1014433 | C30: 1620053970 | D30: 44491 | E30: 44491 | F30: -4119030.9 | G30: USD | H30: Credit note balance | I30: Warranty Credit - ULW - CRC ESN 10409 | J30: USED | K30: 97459613
A31: 1200 | B31: 1014433 | C31: 1620053969 | D31: 44491 | E31: 44491 | F31: -4419321.7 | G31: USD | H31: Credit note balance | I31: Warranty Credit - ULW - CRC ESN 10434 | J31: USED | K31: 97460864
E32: Used Credits | F32: =SUM(F13:F31) -> #REF!
