Workbook
Name Slicer_Customer: #N/A
Name Slicer_Engine_Value_Stream: #N/A
Name Slicer_Engine_Value_Stream1: #N/A
Name Slicer_Expected_year_of_signature: #N/A
Name Slicer_Expected_year_of_signature1: #N/A
Name Slicer_Onerous_Non_Onerous: #N/A
Name Slicer_Onerous_Non_Onerous1: #N/A
Name Slicer_Region: #N/A
Name Slicer_Region1: #N/A
Name Slicer_Restructure_Type: #N/A
Name Slicer_Restructure_Type1: #N/A
Name Slicer_Top_Level_EVS: #N/A
Name Slicer_Top_Level_EVS1: #N/A

Sheet COVER
C3: COMMERCIAL OPTIMISATION OPPORTUNITY REPORT
D10: Link to Guidance Document | H10: Guidance | N10: Restructure Type - Definitions
H13: 1. All plans defined as 'Full Contract Restructures' and over £10m CRP term benefit require a project plan. 2. All initiatives defined as 'Simple/Limited Restructures', 'Increase Spare Engine Holding' or under £10m CRP term benefit do not require a project plan and will be monitored using the hopper. 3. All initiatives should be grouped by engine programme (Trent 1000, Trent 900, Trent XWB 84 etc). Each engine programme will require its own project plan. | N13: 1. 'Full Contract Restructure' - When a restructure means changing the contract term, plus any other changes such as price (rate/escalation), or credit restructure. Requires Service Business to re-model the CRP 2. 'Simple/Limited Restructure' - For one or two small changes which do not impact the CRP Term, such as Credit back restructure (standalone), TotalCare Escalation or rate increases/trade, Credit or Guarantee restructure. Requires Customer Finance team to model using a simple spreadsheet. 3. 'Increase Spare Engine Holidng' - When selling incremental Spare Engines to calculates NDSES cost savings. Requires Fleet Business Managers to model using the Poisson tool.
D28: Link to Project Document

Sheet GLOBAL LOG
C3: Global Commercial Optimisation Hopper
C5: Region | D5: Customer | E5: Engine Value Stream | F5: Top Level EVS | G5: VP/Account Manager Owner | H5: Restructure Type | I5: Opportunity Maturity | J5: Onerous/Non Onerous | K5: Initative | L5: Project Plan Requirements | M5: Status | N5: Expected year of signature | O5: Signature AP | P5: CRP Term Benefit £m | Q5: Profit 2026 £m | R5: Profit 2027 £m | S5: Profit 2028 £m | T5: Profit 2029 £m | U5: Profit 2030 £m
C6: Americas | D6: FedEx Corporation | E6: RB211-535 | F6: =IFERROR(VLOOKUP(E6,'Data Validations'!$A$2:$B$13,2,0),"") -> TFAME | G6: Meagan Austgen | H6: Full Contract Restructure | I6: Mature | J6: Not Onerous | K6: FedEx - agreement/amendment to unadministrable TotalCare clauses and incentivisation of SV inductions - RB211-535 | L6: =IF(C6="","",IF(AND(OR(H6="Full Contract Restructure"),P6>9.9),"Required","Not Required")) -> Required | M6: Negotations Started | N6: 2026 | O6: AP6 | P6: 21.15 | Q6: 6.43 | R6: 6.96 | S6: 7.77
C7: Americas | D7: American Airlines | E7: Trent 800 | F7: =IFERROR(VLOOKUP(E7,'Data Validations'!$A$2:$B$13,2,0),"") -> TFAME | G7: David Gonzalez-Gomez | H7: Full Contract Restructure | I7: Mature | J7: Not Onerous | K7: American Airlines requested input on longer extension to 2035 | L7: =IF(C7="","",IF(AND(OR(H7="Full Contract Restructure"),P7>9.9),"Required","Not Required")) -> Required | M7: Financial Modelling Complete | N7: 2026 | O7: AP12 | P7: 318 | Q7: 0
C8: APAC | D8: Thai Airways International Ltd | E8: Trent XWB-84 | F8: =IFERROR(VLOOKUP(E8,'Data Validations'!$A$2:$B$13,2,0),"") -> Trent XWB | G8: Nick Chadwick / Ben Gan | H8: Full Contract Restructure | I8: Mature | J8: Not Onerous | K8: Min term extension involving reinstating some discount, EOCL removal and escalation improvement. Jun-2025 Level 3 approval secured in .Jul 2025 - Proposal presented to THAI with minor trades, Sep 2025 formal proposal requested in, Feb 2026 proposal issued and expect to contract pending THA acceptance Apr 2026 - Senior engagement at AIX, awaiting feedback before next steps, possible adjustment pending ICT confirmation. | L8: =IF(C8="","",IF(AND(OR(H8="Full Contract Restructure"),P8>9.9),"Required","Not Required")) -> Required | M8: Negotations Started | N8: 2026 | O8: AP12 | P8: 294.1 | Q8: tbc | R8: Confirm with Harry | S8: Confirm with Harry | T8: Confirm with Harry | U8: Confirm with Harry
C9: MEA | D9: Emirates | E9: Trent XWB-84 | F9: =IFERROR(VLOOKUP(E9,'Data Validations'!$A$2:$B$13,2,0),"") -> Trent XWB | G9: Matt Whatley / Darren O'neill | H9: Full Contract Restructure | I9: Mature | J9: Not Onerous | K9: Finiq 2 - 3 year-extension + LRU Management + 23 a/c. Term benefit includes a % of DI7 | L9: =IF(C9="","",IF(AND(OR(H9="Full Contract Restructure"),P9>9.9),"Required","Not Required")) -> Required | M9: Contracting Concluded | N9: 2025 | P9: 193 | Q9: 0
C10: APAC | D10: Singapore Airlines | E10: Trent XWB-84 | F10: =IFERROR(VLOOKUP(E10,'Data Validations'!$A$2:$B$13,2,0),"") -> Trent XWB | G10: Paul Hallam | H10: Full Contract Restructure | I10: Mature | J10: Onerous Contract | K10: Project Aegis contractual negotiations continue - final key points (Charging Period, R-R Mitigation, Build Life Guarantee) being worked ahead of final closing meeting between JK and HP Lau Note expected approval to close in March 2026 is £5m and so these figures have not been amended | L10: =IF(C10="","",IF(AND(OR(H10="Full Contract Restructure"),P10>9.9),"Required","Not Required")) -> Required | M10: Contracting Started | N10: 2026 | O10: AP3 | P10: =236-5 -> 231 | Q10: 24 | R10: Confirm with Harry | S10: Confirm with Harry | T10: Confirm with Harry | U10: Confirm with Harry
C11: APAC | D11: Vietnam Airlines | E11: Trent XWB-84 | F11: =IFERROR(VLOOKUP(E11,'Data Validations'!$A$2:$B$13,2,0),"") -> Trent XWB | G11: Paul Hallam | H11: Full Contract Restructure | I11: Mature | J11: Not Onerous | K11: Life min term extension from 2027 to 2031 to align with lease term extension and 2x XWB SPE sales in Q4 2026. Linked with Claim and reconcliation account issues. Initial engagement with customer structurally ok. Construstive Level 2 workshop took place on 8 July and follow up Level 2 strategy to be planned for end of July - considering if we can find a solution that could be used Trent XWB engines, rather than new in 2026. Already commited in XWB 5YP | L11: =IF(C11="","",IF(AND(OR(H11="Full Contract Restructure"),P11>9.9),"Required","Not Required")) -> Required | M11: Negotations Started | N11: 2026 | O11: AP6 | P11: 186 | Q11: 10 | R11: 6 | S11: 7 | T11: 20 | U11: 9
C12: APAC | D12: Singapore Airlines | E12: Trent 1000 | F12: =IFERROR(VLOOKUP(E12,'Data Validations'!$A$2:$B$13,2,0),"") -> TFAME | G12: Paul Hallam | H12: Full Contract Restructure | I12: Immature | J12: Onerous Contract | K12: Strategy being developed 1) lessons learnt from Trent XWB Project Aegis in terms of complexity, time to conclude and not doing the Final Restoration Shop Visit Guarantee. 2) Proposed strategy to split into Phase 1 (Period of Cover(and Phase 2 (post term extension) abd Phase 2 post POC extension including escalated and value trades. 3) Phase 1 customer engagement planned ahead of the CEO meeting (8 April 2026) | L12: =IF(C12="","",IF(AND(OR(H12="Full Contract Restructure"),P12>9.9),"Required","Not Required")) -> Required | M12: ICT formed | N12: 2026 | O12: AP12 | P12: 80 | Q12: 80 | R12: Confirm with Bobby | S12: Confirm with Bobby | T12: Confirm with Bobby | U12: Confirm with Bobby
C13: MEA | D13: Emirates | E13: Trent 900 | F13: Trent 900 | G13: Matt Whatley / Darren O'neill | H13: Full Contract Restructure | I13: Mature | J13: Not Onerous | K13: Pantheon - Trent 900 Full MRO for improved CRP | L13: =IF(C13="","",IF(AND(OR(H13="Full Contract Restructure"),P13>9.9),"Required","Not Required")) -> Required | M13: Financial Modelling Started | N13: 2026 | O13: AP9 | P13: 73 | Q13: 0
C14: Europe | D14: British Airways | E14: Trent XWB-97 | F14: =IFERROR(VLOOKUP(E14,'Data Validations'!$A$2:$B$13,2,0),"") -> Trent XWB | G14: Matt O'Connor | H14: Full Contract Restructure | I14: Mature | J14: Not Onerous | K14: Life Min Term extension to 24 years for owned a/c and 12 years for leased a/c, plus removal of EoCL for a $/efh discount on both Engine & LLPs. | L14: =IF(C14="","",IF(AND(OR(H14="Full Contract Restructure"),P14>9.9),"Required","Not Required")) -> Required | M14: Negotations Started | N14: 2026 | O14: AP6 | P14: 330
C15: APAC | D15: Srilankan Airlines | E15: Trent 700 | F15: =IFERROR(VLOOKUP(E15,'Data Validations'!$A$2:$B$13,2,0),"") -> TFAME | G15: Kendrick Lim | H15: Full Contract Restructure | I15: Mature | J15: Not Onerous | K15: Min term extension of existing contract (Life) of 6 years. This will need to be revised as per FBM direction post Avalon requirements to extend to the next SV as the min term which will in turn amend the financials that was already prepared. Previous IY profit impact was £(7)m negative due to being lower % margin than existing 75% but > 57% fleet average. However, this has not been to L2 approval yet. Work on next SV duration will require urgent resource | L15: =IF(C15="","",IF(AND(OR(H15="Full Contract Restructure"),P15>9.9),"Required","Not Required")) -> Required | M15: Negotations Started | N15: 2026 | O15: AP6 | P15: =150/1.44 -> 104.16667 | Q15: 20 | R15: 2 | S15: 1 | T15: 8 | U15: 15
C16: Europe | D16: World2Fly | E16: Trent XWB-84 | F16: =IFERROR(VLOOKUP(E16,'Data Validations'!$A$2:$B$13,2,0),"") -> Trent XWB | G16: Neeraj Sunger | H16: Increase Spare Engine Holding | I16: Mature | J16: Not Onerous | K16: Min term extension (life) - 1 a/c exit from 2026. 5yr term but 12yr lease term. Contract extension in 2025 Plus sell used SPE to reduce NDSES costs in CRP (Minimal but supports the OE sale) | L16: =IF(C16="","",IF(AND(OR(H16="Full Contract Restructure"),P16>9.9),"Required","Not Required")) -> Not Required | M16: ICT formed | N16: 2026
C17: Europe | D17: British Airways | E17: Trent 1000 | F17: =IFERROR(VLOOKUP(E17,'Data Validations'!$A$2:$B$13,2,0),"") -> TFAME | G17: Matt O'Connor | H17: Full Contract Restructure | I17: Mature | J17: Onerous Contract | K17: Life Min Term extension to 25 years for owned a/c and 12 years for leased a/c, plus removal of EoCL for a $/efh discount on both Engine & LLPs. | L17: =IF(C17="","",IF(AND(OR(H17="Full Contract Restructure"),P17>9.9),"Required","Not Required")) -> Required | M17: Negotations Started | N17: 2026 | O17: AP6 | P17: 303 | Q17: 35
C18: Americas | D18: Hawaiian Airlines | E18: Trent 700 | F18: =IFERROR(VLOOKUP(E18,'Data Validations'!$A$2:$B$13,2,0),"") -> TFAME | G18: Harrison Green | H18: Full Contract Restructure | I18: Mature | J18: Not Onerous | K18: EFH discount in return for addition 20x SV commitment. Negotiations ongoing. | L18: =IF(C18="","",IF(AND(OR(H18="Full Contract Restructure"),P18>9.9),"Required","Not Required")) -> Required | M18: Contracting Concluded | N18: 2025 | O18: AP11 | P18: 53.2 | Q18: 7.6 | R18: 7.6 | S18: 7.6 | T18: 7.6 | U18: 7.6
C19: MEA | D19: Qatar | E19: Trent XWB-84 | F19: =IFERROR(VLOOKUP(E19,'Data Validations'!$A$2:$B$13,2,0),"") -> Trent XWB | G19: Matt Whatley / Issy Walton | H19: Full Contract Restructure | I19: Mature | J19: Not Onerous | K19: Exit for convenience removal -84 | L19: =IF(C19="","",IF(AND(OR(H19="Full Contract Restructure"),P19>9.9),"Required","Not Required")) -> Not Required | M19: Contracting Started | N19: 2026 | O19: AP5 | Q19: 15 | R19: 39 | S19: 16 | T19: 16 | U19: 11
C20: MEA | D20: Etihad | E20: Trent XWB-97 | F20: =IFERROR(VLOOKUP(E20,'Data Validations'!$A$2:$B$13,2,0),"") -> Trent XWB | G20: Gordon Deas | H20: Simple/Limited Restructure | I20: Mature | J20: Not Onerous | K20: TCA Reconciliation (CRP Improvement) | L20: =IF(C20="","",IF(AND(OR(H20="Full Contract Restructure"),P20>9.9),"Required","Not Required")) -> Not Required | M20: Contracting Concluded | N20: 2025 | P20: =3.2/1.38 -> 2.3188406 | Q20: 2.32
C21: MEA | D21: Emirates | E21: Trent XWB-84 | F21: =IFERROR(VLOOKUP(E21,'Data Validations'!$A$2:$B$13,2,0),"") -> Trent XWB | G21: Matt Whatley / Darren O'neill | H21: Simple/Limited Restructure | I21: Immature | J21: Not Onerous | K21: Trent XWB Full MRO for improved CRP | L21: =IF(C21="","",IF(AND(OR(H21="Full Contract Restructure"),P21>9.9),"Required","Not Required")) -> Not Required | M21: Initial idea | N21: 2027 | P21: 33 | Q21: 0
C22: MEA | D22: Qatar | E22: Trent XWB-97 | F22: =IFERROR(VLOOKUP(E22,'Data Validations'!$A$2:$B$13,2,0),"") -> Trent XWB | G22: Matt Whatley / Issy Walton | H22: Full Contract Restructure | I22: Immature | J22: Not Onerous | K22: Exit for convenience removal -97 | L22: =IF(C22="","",IF(AND(OR(H22="Full Contract Restructure"),P22>9.9),"Required","Not Required")) -> Not Required | M22: Initial idea | N22: 2027
C23: MEA | D23: Ethiopian Airlines | E23: Trent XWB-84 | F23: =IFERROR(VLOOKUP(E23,'Data Validations'!$A$2:$B$13,2,0),"") -> Trent XWB | G23: Gordon Deas | H23: Simple/Limited Restructure | I23: Mature | J23: Not Onerous | K23: Restructure exisiting contract -Credit Back Removal As part of A350-900 campaign | L23: =IF(C23="","",IF(AND(OR(H23="Full Contract Restructure"),P23>9.9),"Required","Not Required")) -> Not Required | M23: ICT formed | N23: 2026 | Q23: 0
C24: Europe | D24: Iberia | E24: Trent XWB-84 | F24: =IFERROR(VLOOKUP(E24,'Data Validations'!$A$2:$B$13,2,0),"") -> Trent XWB | G24: Neeraj Sunger | H24: Simple/Limited Restructure | I24: Mature | J24: Not Onerous | K24: Min term extension (life) - 2x leased a/c meet minimum term in 2026. Contract extension to 2030 inline with revised lease terms. Contracted in 2025, linked to matrix extension resolution. | L24: =IF(C24="","",IF(AND(OR(H24="Full Contract Restructure"),P24>9.9),"Required","Not Required")) -> Not Required | M24: Contracting Concluded | N24: 2025
C25: Americas | D25: Air Canada | E25: Trent 700 | F25: =IFERROR(VLOOKUP(E25,'Data Validations'!$A$2:$B$13,2,0),"") -> TFAME | G25: David Gonzalez-Gomez | I25: Immature | J25: Not Onerous | K25: Flex contract extension. Current contract expiring end of 2027. | L25: =IF(C25="","",IF(AND(OR(H25="Full Contract Restructure"),P25>9.9),"Required","Not Required")) -> Not Required | P25: 15 | Q25: =0.001 -> 0.001 | R25: =0.001 -> 0.001 | S25: 5 | T25: 5 | U25: 5
C26: Europe | D26: Lufthansa | E26: Trent XWB-84 | F26: =IFERROR(VLOOKUP(E26,'Data Validations'!$A$2:$B$13,2,0),"") -> Trent XWB | G26: Keith Coull | H26: Simple/Limited Restructure | I26: Mature | J26: Not Onerous | K26: Pull forward of spare engines, working capital improvements (payment terms), reverse lease of engines, EP upsell | L26: =IF(C26="","",IF(AND(OR(H26="Full Contract Restructure"),P26>9.9),"Required","Not Required")) -> Not Required | M26: Negotations Concluded | N26: 2026 | O26: AP3 | P26: 14
C27: APAC | D27: Royal Brunei Airlines | E27: Trent 1000 | F27: =IFERROR(VLOOKUP(E27,'Data Validations'!$A$2:$B$13,2,0),"") -> TFAME | G27: Kendrick Lim | I27: Mature | J27: Onerous Contract | K27: 4th Mar 26 (KL): Awaiting campaign final decision. Either way a requirement to account to aircraft swap dates on existing min term is needed to lock in more TCA vs CRP which only goes out for 12-18mths. RBA has asked for the contract for the new aircraft which will require this to be signed in parallel, so the urgency has gone up. This specific Commercial Optimisation Initiative type should be considered a Term Extension as opposed to New Aircraft. | L27: =IF(C27="","",IF(AND(OR(H27="Full Contract Restructure"),P27>9.9),"Required","Not Required")) -> Not Required | M27: ICT formed | P27: 13 | Q27: 4 | R27: Confirm with Bobby | S27: Confirm with Bobby | T27: Confirm with Bobby | U27: Confirm with Bobby
C28: MEA | D28: Saudia | E28: Trent 700 | F28: =IFERROR(VLOOKUP(E28,'Data Validations'!$A$2:$B$13,2,0),"") -> TFAME | G28: Georges Abou-Nasr | H28: Full Contract Restructure | I28: Immature | J28: Not Onerous | K28: Extend Classic | L28: =IF(C28="","",IF(AND(OR(H28="Full Contract Restructure"),P28>9.9),"Required","Not Required")) -> Not Required | M28: Initial idea | N28: 2027 | Q28: 0 | R28: 0
C29: Europe | D29: LOT Polish Airlines | E29: Trent 1000 | F29: =IFERROR(VLOOKUP(E29,'Data Validations'!$A$2:$B$13,2,0),"") -> TFAME | G29: Sean Burke | H29: Increase Spare Engine Holding | I29: Immature | J29: Not Onerous | K29: 1 new SPE in Q1 linked to 2 Dr Peters transition a/c. Life Min Term extension on purchased existing fleet as part of the 9 a/c campaign. | L29: =IF(C29="","",IF(AND(OR(H29="Full Contract Restructure"),P29>9.9),"Required","Not Required")) -> Not Required | M29: Negotations Started | N29: 2026 | O29: AP6 | P29: 10
C30: Europe | D30: Condor Flugdienst Gmbh | E30: Trent 7000 | F30: =IFERROR(VLOOKUP(E30,'Data Validations'!$A$2:$B$13,2,0),"") -> TFAME | G30: Aaron Taylor | H30: Increase Spare Engine Holding | I30: Mature | J30: Not Onerous | K30: NDSES improvement through SPE sales associated to new deal + FCRG and NED Remedy Improvement | L30: =IF(C30="","",IF(AND(OR(H30="Full Contract Restructure"),P30>9.9),"Required","Not Required")) -> Not Required | M30: Contracting Started | N30: 2026 | P30: =12.9/1.38 -> 9.3478261
C31: Europe | D31: TAP Air Portugal | E31: Trent 7000 | F31: =IFERROR(VLOOKUP(E31,'Data Validations'!$A$2:$B$13,2,0),"") -> TFAME | G31: Richard Docherty | H31: Increase Spare Engine Holding | I31: Mature | J31: Not Onerous | K31: Two aircraft delays to Original Delivery Schedule. Plan to progress 2026 Used SPE, credit pull-forward for CRP improvement and Optional AOG+1 NDSES Service. | L31: =IF(C31="","",IF(AND(OR(H31="Full Contract Restructure"),P31>9.9),"Required","Not Required")) -> Not Required | M31: Negotations Concluded | N31: 2026 | P31: 6
C32: MEA | D32: Gulf | E32: Trent 1000 | F32: =IFERROR(VLOOKUP(E32,'Data Validations'!$A$2:$B$13,2,0),"") -> TFAME | G32: Georgia Chapman | H32: Full Contract Restructure | I32: Mature | J32: Not Onerous | K32: Commerical Offer - 3 Year Extension/ SPE Sales (NDSES Improvement) | L32: =IF(C32="","",IF(AND(OR(H32="Full Contract Restructure"),P32>9.9),"Required","Not Required")) -> Required | M32: Negotations Started | N32: 2026 | O32: AP6 | P32: 32.3 | Q32: -7.4 | R32: 2.5 | S32: 3.4 | T32: 4.6 | U32: 4.1
C33: MEA | D33: Rwanda | E33: Trent 700 | F33: =IFERROR(VLOOKUP(E33,'Data Validations'!$A$2:$B$13,2,0),"") -> TFAME | G33: Gordon Deas | H33: Full Contract Restructure | I33: Immature | J33: Not Onerous | K33: TCA Life Min Term Extension | L33: =IF(C33="","",IF(AND(OR(H33="Full Contract Restructure"),P33>9.9),"Required","Not Required")) -> Not Required | M33: Initial idea | N33: 2026 | P33: 8.88 | Q33: 0 | R33: 0
C34: MEA | D34: Ethiopian Airlines | E34: Trent XWB-84 | F34: =IFERROR(VLOOKUP(E34,'Data Validations'!$A$2:$B$13,2,0),"") -> Trent XWB | G34: Gordon Deas | H34: Full Contract Restructure | I34: Mature | J34: Not Onerous | K34: Restructure exisiting contract - Min Term Extension As part of A350-900 campaign | L34: =IF(C34="","",IF(AND(OR(H34="Full Contract Restructure"),P34>9.9),"Required","Not Required")) -> Not Required | M34: ICT formed | N34: 2026 | Q34: 0
C35: MEA | D35: Egypt | E35: Trent XWB-84 | F35: =IFERROR(VLOOKUP(E35,'Data Validations'!$A$2:$B$13,2,0),"") -> Trent XWB | G35: Georges Abou-Nasr | H35: Full Contract Restructure | I35: Immature | J35: Not Onerous | K35: EP Upsell (2028+ deliveries) | L35: =IF(C35="","",IF(AND(OR(H35="Full Contract Restructure"),P35>9.9),"Required","Not Required")) -> Not Required | M35: Initial idea | N35: 2027
C36: Greater China | D36: China Southern | E36: Trent 700 | F36: =IFERROR(VLOOKUP(E36,'Data Validations'!$A$2:$B$13,2,0),"") -> TFAME | G36: Daniel Hector | H36: Simple/Limited Restructure | I36: Mature | J36: Not Onerous | K36: Updated 27/02/2026: Add ex-Block 1 Spare Engine to Block 2 TCA with Buy-in SV at SelectCare Pricing (less exit credits) delivering dilution benefits. Pricing and use of exit credit appoved at L2 in 2025. SV slot currently identified in Q2 2026 and can be secured if deal can rapidly be done. The method of contracting internally agreed to be added to Block 2 Buy-in fee. Feb 2026: customer going through final internal approvals. 25/07/2025: Add ex-Block 1 Spare Engine to Block 2 TCA with Buy-In SV at SelectCare Pricing (less exit credits) delivering dilution benefits. Pricing and use of exit credit approved at L2 in May-25. First round of discussion with customer in early June. Customer has since been evaluating internally and not yet provided formal feedback. SV slot identified in Q3 2025 and can be secured if deal can rapidly be done. Contracting method confirmed by value stream to be Add to Block 2 with Buy-in Fee. | L36: =IF(C36="","",IF(AND(OR(H36="Full Contract Restructure"),P36>9.9),"Required","Not Required")) -> Not Required | M36: Negotations Started | N36: 2026 | P36: 5 | Q36: 5
C37: Americas | D37: Keylime | E37: AE3007 | F37: =IFERROR(VLOOKUP(E37,'Data Validations'!$A$2:$B$13,2,0),"") -> TFAME | G37: Cory Noel | H37: Simple/Limited Restructure | I37: Mature | J37: Not Onerous | K37: Keylime Air _ AE3007 _ Add 2 in possession aircraft to TotalCare & extend all to 2030 | L37: =IF(C37="","",IF(AND(OR(H37="Full Contract Restructure"),P37>9.9),"Required","Not Required")) -> Not Required | M37: Contracting Concluded | N37: 2025 | P37: 5 | Q37: 0
C38: APAC | D38: All Nippon Airways | E38: Trent 1000 | F38: =IFERROR(VLOOKUP(E38,'Data Validations'!$A$2:$B$13,2,0),"") -> TFAME | G38: Nick Chadwick / Chong Sien Lim | H38: Increase Spare Engine Holding | I38: Immature | K38: Acceleration of backlog assets from Boeing to backstop Trent 1000 fleet health. Financial opportunity relates to direct sale of engines to ANA (Q4 25) and mitigation of NDSES costs/remedies. We have positioned optimising economics to ANA, offsetting a $33m non-contractual claim for Trent 1000 disruption in 2024. L2 approved trading $7.3m of NDSES savings for 2025, to be ‘offset’ against their claim. Proposal communicated to ANA 31/7, contract amendment being drafted for submission by 9/8. (Note: potential for further 2026 NDSES remedy avoidance of ~US30m). | L38: =IF(C38="","",IF(AND(OR(H38="Full Contract Restructure"),P38>9.9),"Required","Not Required")) -> Not Required | M38: Contracting Concluded | N38: 2025 | P38: 4.9 | Q38: =4.9*0.42 -> 2.058
C39: Americas | D39: Sterling | E39: AE2100 | F39: =IFERROR(VLOOKUP(E39,'Data Validations'!$A$2:$B$13,2,0),"") -> TFAME | G39: Cory Noel | H39: Full Contract Restructure | I39: Mature | J39: Not Onerous | K39: Sterling _ AE2100 _ restructure & add spare engines | L39: =IF(C39="","",IF(AND(OR(H39="Full Contract Restructure"),P39>9.9),"Required","Not Required")) -> Not Required | M39: Financial Modelling Complete | N39: 2026 | P39: 3.87 | Q39: 0
C40: MEA | D40: Austral | E40: Trent 1000 | F40: =IFERROR(VLOOKUP(E40,'Data Validations'!$A$2:$B$13,2,0),"") -> TFAME | G40: Georgia Chapman | H40: Full Contract Restructure | I40: Immature | J40: Not Onerous | K40: TCA Extension (Life)/Exit credit trade | L40: =IF(C40="","",IF(AND(OR(H40="Full Contract Restructure"),P40>9.9),"Required","Not Required")) -> Not Required | M40: Initial idea | P40: 3.552 | Q40: 0
C41: MEA | D41: Ethiopian Airlines | E41: Trent 1000 | F41: =IFERROR(VLOOKUP(E41,'Data Validations'!$A$2:$B$13,2,0),"") -> TFAME | G41: Gordon Deas | H41: Full Contract Restructure | I41: Mature | J41: Onerous Contract | K41: TCA Life Min Term Extension (life) As part of 787-9 campaign | L41: =IF(C41="","",IF(AND(OR(H41="Full Contract Restructure"),P41>9.9),"Required","Not Required")) -> Not Required | M41: ICT formed | N41: 2026 | Q41: 23
C42: MEA | D42: Tanzania | E42: Trent 1000 | F42: =IFERROR(VLOOKUP(E42,'Data Validations'!$A$2:$B$13,2,0),"") -> TFAME | G42: Gordon Deas | H42: Increase Spare Engine Holding | I42: Mature | J42: Not Onerous | K42: Sale of incremental spare engine. NDSES CRP | L42: =IF(C42="","",IF(AND(OR(H42="Full Contract Restructure"),P42>9.9),"Required","Not Required")) -> Not Required | M42: Contracting Concluded | N42: 2026 | O42: AP4 | P42: 2.62848 | Q42: 0.525696 | R42: 0.525696
C43: Europe | D43: Virgin Atlantic | E43: Trent 1000 | F43: =IFERROR(VLOOKUP(E43,'Data Validations'!$A$2:$B$13,2,0),"") -> TFAME | G43: Keith Coull | H43: Increase Spare Engine Holding | I43: Mature | J43: Onerous Contract | K43: Sale of incremental Trent 1000 used SPE to meet inventory targets with RRPF S&LB. Review of NDSES cost savings and CRP improvements. | L43: =IF(C43="","",IF(AND(OR(H43="Full Contract Restructure"),P43>9.9),"Required","Not Required")) -> Not Required | M43: Negotations Started | N43: 2026 | O43: AP6 | P43: 2 | Q43: 2
...

Sheet COUNT
C2: COUNT
C8: PROJECTS
G9: PROGRAM | N9: PROBABILITY | Q9: COMPLEXITY | T9: STATUS | Y9: YEARS
C10: PROJECT | D10: COUNT OF ASKS | E10: OF WHICH SPE RELATED | F10: NO.OF SPE | G10: Trent XWB-84 | H10: Trent XWB-97 | I10: Trent 1000 | J10: Trent 500 | K10: Trent 700 | L10: RB211-524 | M10: Trent 7000 | N10: COUNT OF HIGH PROB | O10: COUNT OF MED PROB | P10: COUNT OF LOW PROB | Q10: COUNT OF HIGH COMP | R10: COUNT OF MED COMP | S10: COUNT OF LOW COMP | T10: COUNT OF COMPLETED | U10: COUNT OF CONTRACTING | V10: COUNT OF NEGOTIATIONS | W10: COUNT OF ICT | X10: COUNT OF HOPPER | Y10: 2026 | Z10: 2027 | AA10: SUM OF 26/27 | AB10: SUM OF TERM BENEFIT | AD10: SORTED CUSTOMER | AE10: SORTED TERM IMPACT A | AG10: SORTED CUSTOMER | AH10: SORTED 2026 | AJ10: SORTED CUSTOMER | AK10: SORTED 2027 | AM10: SORTED CUSTOMER | AN10: SORTED 2026/2027
C11: {=_xlfn._xlws.FILTER('Data Validations'!C2:C153,TRUE)} -> Aer Lingus | D11: =COUNTIFS('GLOBAL LOG'!$D$6:$D$128,C11,'GLOBAL LOG'!$K$6:$K$128,"<>") -> 0 | E11: =COUNTIFS('GLOBAL LOG'!$D$6:$D$128,C11,'GLOBAL LOG'!#REF!,"Yes") -> #REF! | F11: =SUMIF('GLOBAL LOG'!$D$6:$D$128,COUNT!C11,'GLOBAL LOG'!#REF!) -> #REF! | G11: =COUNTIFS('GLOBAL LOG'!$E$6:$E$128,G$10,'GLOBAL LOG'!$D$6:$D$128,$C11) -> 0 | H11: =COUNTIFS('GLOBAL LOG'!$E$6:$E$128,H$10,'GLOBAL LOG'!$D$6:$D$128,$C11) -> 0 | I11: =COUNTIFS('GLOBAL LOG'!$E$6:$E$128,I$10,'GLOBAL LOG'!$D$6:$D$128,$C11) -> 0 | J11: =COUNTIFS('GLOBAL LOG'!$E$6:$E$128,J$10,'GLOBAL LOG'!$D$6:$D$128,$C11) -> 0 | K11: =COUNTIFS('GLOBAL LOG'!$E$6:$E$128,K$10,'GLOBAL LOG'!$D$6:$D$128,$C11) -> 0 | L11: =COUNTIFS('GLOBAL LOG'!$E$6:$E$128,L$10,'GLOBAL LOG'!$D$6:$D$128,$C11) -> 0 | M11: =COUNTIFS('GLOBAL LOG'!$E$6:$E$128,M$10,'GLOBAL LOG'!$D$6:$D$128,$C11) -> 0 | N11: =COUNTIFS('GLOBAL LOG'!$D$6:$D$128,$C11,'GLOBAL LOG'!#REF!,"High") -> #REF! | O11: =COUNTIFS('GLOBAL LOG'!$D$6:$D$128,$C11,'GLOBAL LOG'!#REF!,"Med") -> #REF! | P11: =COUNTIFS('GLOBAL LOG'!$D$6:$D$128,$C11,'GLOBAL LOG'!#REF!,"Low") -> #REF! | Q11: =COUNTIFS('GLOBAL LOG'!$D$6:$D$128,$C11,'GLOBAL LOG'!#REF!,"High") -> #REF! | R11: =COUNTIFS('GLOBAL LOG'!$D$6:$D$128,$C11,'GLOBAL LOG'!#REF!,"Med") -> #REF! | S11: =COUNTIFS('GLOBAL LOG'!$D$6:$D$128,$C11,'GLOBAL LOG'!#REF!,"Low") -> #REF! | T11: =COUNTIFS('GLOBAL LOG'!$D$6:$D$128,$C11,'GLOBAL LOG'!#REF!,"Completed") -> #REF! | U11: =COUNTIFS('GLOBAL LOG'!$D$6:$D$128,$C11,'GLOBAL LOG'!#REF!,"Contracting") -> #REF! | V11: =COUNTIFS('GLOBAL LOG'!$D$6:$D$128,$C11,'GLOBAL LOG'!#REF!,"Negotiations") -> #REF! | W11: =COUNTIFS('GLOBAL LOG'!$D$6:$D$128,$C11,'GLOBAL LOG'!#REF!,"ICT") -> #REF! | X11: =COUNTIFS('GLOBAL LOG'!$D$6:$D$128,$C11,'GLOBAL LOG'!#REF!,"Hopper") -> #REF! | Y11: =SUMIF('GLOBAL LOG'!$D$6:$D$128,$C11,'GLOBAL LOG'!$Q$6:$Q$128) -> 0 | Z11: =SUMIF('GLOBAL LOG'!$D$6:$D$128,$C11,'GLOBAL LOG'!$R$6:$R$128) -> 0 | AA11: =Y11+Z11 -> 0 | AB11: =SUMIF('GLOBAL LOG'!$D$6:$D$128,C11,'GLOBAL LOG'!#REF!) -> #REF! | AD11: {=_xlfn.SORTBY(C11:C164,AB11:AB164,-1)} -> Aer Lingus | AE11: {=_xlfn.SORTBY(AB11:AB164,AB11:AB164,-1)} -> #REF! | AG11: {=_xlfn.SORTBY(C11:C164,Y11:Y164,-1)} -> Singapore Airlines | AH11: {=_xlfn.SORTBY(Y11:Y164,Y11:Y164,-1)} -> 104 | AJ11: {=_xlfn.SORTBY(C11:C164,Z11:Z164,-1)} -> Air China | AK11: {=_xlfn.SORTBY(Z11:Z164,Z11:Z164,-1)} -> 33.6 | AM11: {=_xlfn.SORTBY(C11:C164,AA11:AA164,-1)} -> Singapore Airlines | AN11: {=_xlfn.SORTBY(AA11:AA164,AA11:AA164,-1)} -> 104
C12: AerCap | D12: =COUNTIFS('GLOBAL LOG'!$D$6:$D$128,C12,'GLOBAL LOG'!$K$6:$K$128,"<>") -> 0 | E12: =COUNTIFS('GLOBAL LOG'!$D$6:$D$128,C12,'GLOBAL LOG'!#REF!,"Yes") -> #REF! | F12: =SUMIF('GLOBAL LOG'!$D$6:$D$128,COUNT!C12,'GLOBAL LOG'!#REF!) -> #REF! | G12: =COUNTIFS('GLOBAL LOG'!$E$6:$E$128,G$10,'GLOBAL LOG'!$D$6:$D$128,$C12) -> 0 | H12: =COUNTIFS('GLOBAL LOG'!$E$6:$E$128,H$10,'GLOBAL LOG'!$D$6:$D$128,$C12) -> 0 | I12: =COUNTIFS('GLOBAL LOG'!$E$6:$E$128,I$10,'GLOBAL LOG'!$D$6:$D$128,$C12) -> 0 | J12: =COUNTIFS('GLOBAL LOG'!$E$6:$E$128,J$10,'GLOBAL LOG'!$D$6:$D$128,$C12) -> 0 | K12: =COUNTIFS('GLOBAL LOG'!$E$6:$E$128,K$10,'GLOBAL LOG'!$D$6:$D$128,$C12) -> 0 | L12: =COUNTIFS('GLOBAL LOG'!$E$6:$E$128,L$10,'GLOBAL LOG'!$D$6:$D$128,$C12) -> 0 | M12: =COUNTIFS('GLOBAL LOG'!$E$6:$E$128,M$10,'GLOBAL LOG'!$D$6:$D$128,$C12) -> 0 | N12: =COUNTIFS('GLOBAL LOG'!$D$6:$D$128,$C12,'GLOBAL LOG'!#REF!,"High") -> #REF! | O12: =COUNTIFS('GLOBAL LOG'!$D$6:$D$128,$C12,'GLOBAL LOG'!#REF!,"Med") -> #REF! | P12: =COUNTIFS('GLOBAL LOG'!$D$6:$D$128,$C12,'GLOBAL LOG'!#REF!,"Low") -> #REF! | Q12: =COUNTIFS('GLOBAL LOG'!$D$6:$D$128,$C12,'GLOBAL LOG'!#REF!,"High") -> #REF! | R12: =COUNTIFS('GLOBAL LOG'!$D$6:$D$128,$C12,'GLOBAL LOG'!#REF!,"Med") -> #REF! | S12: =COUNTIFS('GLOBAL LOG'!$D$6:$D$128,$C12,'GLOBAL LOG'!#REF!,"Low") -> #REF! | T12: =COUNTIFS('GLOBAL LOG'!$D$6:$D$128,$C12,'GLOBAL LOG'!#REF!,"Completed") -> #REF! | U12: =COUNTIFS('GLOBAL LOG'!$D$6:$D$128,$C12,'GLOBAL LOG'!#REF!,"Contracting") -> #REF! | V12: =COUNTIFS('GLOBAL LOG'!$D$6:$D$128,$C12,'GLOBAL LOG'!#REF!,"Negotiations") -> #REF! | W12: =COUNTIFS('GLOBAL LOG'!$D$6:$D$128,$C12,'GLOBAL LOG'!#REF!,"ICT") -> #REF! | X12: =COUNTIFS('GLOBAL LOG'!$D$6:$D$128,$C12,'GLOBAL LOG'!#REF!,"Hopper") -> #REF! | Y12: =SUMIF('GLOBAL LOG'!$D$6:$D$128,$C12,'GLOBAL LOG'!$Q$6:$Q$128) -> 0 | Z12: =SUMIF('GLOBAL LOG'!$D$6:$D$128,$C12,'GLOBAL LOG'!$R$6:$R$128) -> 0 | AA12: =Y12+Z12 -> 0 | AB12: =SUMIF('GLOBAL LOG'!$D$6:$D$128,C12,'GLOBAL LOG'!#REF!) -> #REF! | AD12: AerCap | AE12: #REF! | AG12: Delta Air Lines | AH12: 59 | AJ12: FedEx Corporation | AK12: 6.96 | AM12: Delta Air Lines | AN12: 59
C13: Aeroflot Russian Airlines | D13: =COUNTIFS('GLOBAL LOG'!$D$6:$D$128,C13,'GLOBAL LOG'!$K$6:$K$128,"<>") -> 0 | E13: =COUNTIFS('GLOBAL LOG'!$D$6:$D$128,C13,'GLOBAL LOG'!#REF!,"Yes") -> #REF! | F13: =SUMIF('GLOBAL LOG'!$D$6:$D$128,COUNT!C13,'GLOBAL LOG'!#REF!) -> #REF! | G13: =COUNTIFS('GLOBAL LOG'!$E$6:$E$128,G$10,'GLOBAL LOG'!$D$6:$D$128,$C13) -> 0 | H13: =COUNTIFS('GLOBAL LOG'!$E$6:$E$128,H$10,'GLOBAL LOG'!$D$6:$D$128,$C13) -> 0 | I13: =COUNTIFS('GLOBAL LOG'!$E$6:$E$128,I$10,'GLOBAL LOG'!$D$6:$D$128,$C13) -> 0 | J13: =COUNTIFS('GLOBAL LOG'!$E$6:$E$128,J$10,'GLOBAL LOG'!$D$6:$D$128,$C13) -> 0 | K13: =COUNTIFS('GLOBAL LOG'!$E$6:$E$128,K$10,'GLOBAL LOG'!$D$6:$D$128,$C13) -> 0 | L13: =COUNTIFS('GLOBAL LOG'!$E$6:$E$128,L$10,'GLOBAL LOG'!$D$6:$D$128,$C13) -> 0 | M13: =COUNTIFS('GLOBAL LOG'!$E$6:$E$128,M$10,'GLOBAL LOG'!$D$6:$D$128,$C13) -> 0 | N13: =COUNTIFS('GLOBAL LOG'!$D$6:$D$128,$C13,'GLOBAL LOG'!#REF!,"High") -> #REF! | O13: =COUNTIFS('GLOBAL LOG'!$D$6:$D$128,$C13,'GLOBAL LOG'!#REF!,"Med") -> #REF! | P13: =COUNTIFS('GLOBAL LOG'!$D$6:$D$128,$C13,'GLOBAL LOG'!#REF!,"Low") -> #REF! | Q13: =COUNTIFS('GLOBAL LOG'!$D$6:$D$128,$C13,'GLOBAL LOG'!#REF!,"High") -> #REF! | R13: =COUNTIFS('GLOBAL LOG'!$D$6:$D$128,$C13,'GLOBAL LOG'!#REF!,"Med") -> #REF! | S13: =COUNTIFS('GLOBAL LOG'!$D$6:$D$128,$C13,'GLOBAL LOG'!#REF!,"Low") -> #REF! | T13: =COUNTIFS('GLOBAL LOG'!$D$6:$D$128,$C13,'GLOBAL LOG'!#REF!,"Completed") -> #REF! | U13: =COUNTIFS('GLOBAL LOG'!$D$6:$D$128,$C13,'GLOBAL LOG'!#REF!,"Contracting") -> #REF! | V13: =COUNTIFS('GLOBAL LOG'!$D$6:$D$128,$C13,'GLOBAL LOG'!#REF!,"Negotiations") -> #REF! | W13: =COUNTIFS('GLOBAL LOG'!$D$6:$D$128,$C13,'GLOBAL LOG'!#REF!,"ICT") -> #REF! | X13: =COUNTIFS('GLOBAL LOG'!$D$6:$D$128,$C13,'GLOBAL LOG'!#REF!,"Hopper") -> #REF! | Y13: =SUMIF('GLOBAL LOG'!$D$6:$D$128,$C13,'GLOBAL LOG'!$Q$6:$Q$128) -> 0 | Z13: =SUMIF('GLOBAL LOG'!$D$6:$D$128,$C13,'GLOBAL LOG'!$R$6:$R$128) -> 0 | AA13: =Y13+Z13 -> 0 | AB13: =SUMIF('GLOBAL LOG'!$D$6:$D$128,C13,'GLOBAL LOG'!#REF!) -> #REF! | AD13: Aeroflot Russian Airlines | AE13: #REF! | AG13: Ethiopian Airlines | AH13: 23 | AJ13: Aer Lingus | AK13: 0 | AM13: Air China | AN13: 38.9
C14: Aerolineas | D14: =COUNTIFS('GLOBAL LOG'!$D$6:$D$128,C14,'GLOBAL LOG'!$K$6:$K$128,"<>") -> 0 | E14: =COUNTIFS('GLOBAL LOG'!$D$6:$D$128,C14,'GLOBAL LOG'!#REF!,"Yes") -> #REF! | F14: =SUMIF('GLOBAL LOG'!$D$6:$D$128,COUNT!C14,'GLOBAL LOG'!#REF!) -> #REF! | G14: =COUNTIFS('GLOBAL LOG'!$E$6:$E$128,G$10,'GLOBAL LOG'!$D$6:$D$128,$C14) -> 0 | H14: =COUNTIFS('GLOBAL LOG'!$E$6:$E$128,H$10,'GLOBAL LOG'!$D$6:$D$128,$C14) -> 0 | I14: =COUNTIFS('GLOBAL LOG'!$E$6:$E$128,I$10,'GLOBAL LOG'!$D$6:$D$128,$C14) -> 0 | J14: =COUNTIFS('GLOBAL LOG'!$E$6:$E$128,J$10,'GLOBAL LOG'!$D$6:$D$128,$C14) -> 0 | K14: =COUNTIFS('GLOBAL LOG'!$E$6:$E$128,K$10,'GLOBAL LOG'!$D$6:$D$128,$C14) -> 0 | L14: =COUNTIFS('GLOBAL LOG'!$E$6:$E$128,L$10,'GLOBAL LOG'!$D$6:$D$128,$C14) -> 0 | M14: =COUNTIFS('GLOBAL LOG'!$E$6:$E$128,M$10,'GLOBAL LOG'!$D$6:$D$128,$C14) -> 0 | N14: =COUNTIFS('GLOBAL LOG'!$D$6:$D$128,$C14,'GLOBAL LOG'!#REF!,"High") -> #REF! | O14: =COUNTIFS('GLOBAL LOG'!$D$6:$D$128,$C14,'GLOBAL LOG'!#REF!,"Med") -> #REF! | P14: =COUNTIFS('GLOBAL LOG'!$D$6:$D$128,$C14,'GLOBAL LOG'!#REF!,"Low") -> #REF! | Q14: =COUNTIFS('GLOBAL LOG'!$D$6:$D$128,$C14,'GLOBAL LOG'!#REF!,"High") -> #REF! | R14: =COUNTIFS('GLOBAL LOG'!$D$6:$D$128,$C14,'GLOBAL LOG'!#REF!,"Med") -> #REF! | S14: =COUNTIFS('GLOBAL LOG'!$D$6:$D$128,$C14,'GLOBAL LOG'!#REF!,"Low") -> #REF! | T14: =COUNTIFS('GLOBAL LOG'!$D$6:$D$128,$C14,'GLOBAL LOG'!#REF!,"Completed") -> #REF! | U14: =COUNTIFS('GLOBAL LOG'!$D$6:$D$128,$C14,'GLOBAL LOG'!#REF!,"Contracting") -> #REF! | V14: =COUNTIFS('GLOBAL LOG'!$D$6:$D$128,$C14,'GLOBAL LOG'!#REF!,"Negotiations") -> #REF! | W14: =COUNTIFS('GLOBAL LOG'!$D$6:$D$128,$C14,'GLOBAL LOG'!#REF!,"ICT") -> #REF! | X14: =COUNTIFS('GLOBAL LOG'!$D$6:$D$128,$C14,'GLOBAL LOG'!#REF!,"Hopper") -> #REF! | Y14: =SUMIF('GLOBAL LOG'!$D$6:$D$128,$C14,'GLOBAL LOG'!$Q$6:$Q$128) -> 0 | Z14: =SUMIF('GLOBAL LOG'!$D$6:$D$128,$C14,'GLOBAL LOG'!$R$6:$R$128) -> 0 | AA14: =Y14+Z14 -> 0 | AB14: =SUMIF('GLOBAL LOG'!$D$6:$D$128,C14,'GLOBAL LOG'!#REF!) -> #REF! | AD14: Aerolineas | AE14: #REF! | AG14: FedEx Corporation | AH14: 6.43 | AJ14: AerCap | AK14: 0 | AM14: Ethiopian Airlines | AN14: 23
C15: Air Algerie | D15: =COUNTIFS('GLOBAL LOG'!$D$6:$D$128,C15,'GLOBAL LOG'!$K$6:$K$128,"<>") -> 0 | E15: =COUNTIFS('GLOBAL LOG'!$D$6:$D$128,C15,'GLOBAL LOG'!#REF!,"Yes") -> #REF! | F15: =SUMIF('GLOBAL LOG'!$D$6:$D$128,COUNT!C15,'GLOBAL LOG'!#REF!) -> #REF! | G15: =COUNTIFS('GLOBAL LOG'!$E$6:$E$128,G$10,'GLOBAL LOG'!$D$6:$D$128,$C15) -> 0 | H15: =COUNTIFS('GLOBAL LOG'!$E$6:$E$128,H$10,'GLOBAL LOG'!$D$6:$D$128,$C15) -> 0 | I15: =COUNTIFS('GLOBAL LOG'!$E$6:$E$128,I$10,'GLOBAL LOG'!$D$6:$D$128,$C15) -> 0 | J15: =COUNTIFS('GLOBAL LOG'!$E$6:$E$128,J$10,'GLOBAL LOG'!$D$6:$D$128,$C15) -> 0 | K15: =COUNTIFS('GLOBAL LOG'!$E$6:$E$128,K$10,'GLOBAL LOG'!$D$6:$D$128,$C15) -> 0 | L15: =COUNTIFS('GLOBAL LOG'!$E$6:$E$128,L$10,'GLOBAL LOG'!$D$6:$D$128,$C15) -> 0 | M15: =COUNTIFS('GLOBAL LOG'!$E$6:$E$128,M$10,'GLOBAL LOG'!$D$6:$D$128,$C15) -> 0 | N15: =COUNTIFS('GLOBAL LOG'!$D$6:$D$128,$C15,'GLOBAL LOG'!#REF!,"High") -> #REF! | O15: =COUNTIFS('GLOBAL LOG'!$D$6:$D$128,$C15,'GLOBAL LOG'!#REF!,"Med") -> #REF! | P15: =COUNTIFS('GLOBAL LOG'!$D$6:$D$128,$C15,'GLOBAL LOG'!#REF!,"Low") -> #REF! | Q15: =COUNTIFS('GLOBAL LOG'!$D$6:$D$128,$C15,'GLOBAL LOG'!#REF!,"High") -> #REF! | R15: =COUNTIFS('GLOBAL LOG'!$D$6:$D$128,$C15,'GLOBAL LOG'!#REF!,"Med") -> #REF! | S15: =COUNTIFS('GLOBAL LOG'!$D$6:$D$128,$C15,'GLOBAL LOG'!#REF!,"Low") -> #REF! | T15: =COUNTIFS('GLOBAL LOG'!$D$6:$D$128,$C15,'GLOBAL LOG'!#REF!,"Completed") -> #REF! | U15: =COUNTIFS('GLOBAL LOG'!$D$6:$D$128,$C15,'GLOBAL LOG'!#REF!,"Contracting") -> #REF! | V15: =COUNTIFS('GLOBAL LOG'!$D$6:$D$128,$C15,'GLOBAL LOG'!#REF!,"Negotiations") -> #REF! | W15: =COUNTIFS('GLOBAL LOG'!$D$6:$D$128,$C15,'GLOBAL LOG'!#REF!,"ICT") -> #REF! | X15: =COUNTIFS('GLOBAL LOG'!$D$6:$D$128,$C15,'GLOBAL LOG'!#REF!,"Hopper") -> #REF! | Y15: =SUMIF('GLOBAL LOG'!$D$6:$D$128,$C15,'GLOBAL LOG'!$Q$6:$Q$128) -> 0 | Z15: =SUMIF('GLOBAL LOG'!$D$6:$D$128,$C15,'GLOBAL LOG'!$R$6:$R$128) -> 0 | AA15: =Y15+Z15 -> 0 | AB15: =SUMIF('GLOBAL LOG'!$D$6:$D$128,C15,'GLOBAL LOG'!#REF!) -> #REF! | AD15: Air Algerie | AE15: #REF! | AG15: Air China | AH15: 5.3 | AJ15: Aeroflot Russian Airlines | AK15: 0 | AM15: FedEx Corporation | AN15: 13.39
C16: Air Austral | D16: =COUNTIFS('GLOBAL LOG'!$D$6:$D$128,C16,'GLOBAL LOG'!$K$6:$K$128,"<>") -> 0 | E16: =COUNTIFS('GLOBAL LOG'!$D$6:$D$128,C16,'GLOBAL LOG'!#REF!,"Yes") -> #REF! | F16: =SUMIF('GLOBAL LOG'!$D$6:$D$128,COUNT!C16,'GLOBAL LOG'!#REF!) -> #REF! | G16: =COUNTIFS('GLOBAL LOG'!$E$6:$E$128,G$10,'GLOBAL LOG'!$D$6:$D$128,$C16) -> 0 | H16: =COUNTIFS('GLOBAL LOG'!$E$6:$E$128,H$10,'GLOBAL LOG'!$D$6:$D$128,$C16) -> 0 | I16: =COUNTIFS('GLOBAL LOG'!$E$6:$E$128,I$10,'GLOBAL LOG'!$D$6:$D$128,$C16) -> 0 | J16: =COUNTIFS('GLOBAL LOG'!$E$6:$E$128,J$10,'GLOBAL LOG'!$D$6:$D$128,$C16) -> 0 | K16: =COUNTIFS('GLOBAL LOG'!$E$6:$E$128,K$10,'GLOBAL LOG'!$D$6:$D$128,$C16) -> 0 | L16: =COUNTIFS('GLOBAL LOG'!$E$6:$E$128,L$10,'GLOBAL LOG'!$D$6:$D$128,$C16) -> 0 | M16: =COUNTIFS('GLOBAL LOG'!$E$6:$E$128,M$10,'GLOBAL LOG'!$D$6:$D$128,$C16) -> 0 | N16: =COUNTIFS('GLOBAL LOG'!$D$6:$D$128,$C16,'GLOBAL LOG'!#REF!,"High") -> #REF! | O16: =COUNTIFS('GLOBAL LOG'!$D$6:$D$128,$C16,'GLOBAL LOG'!#REF!,"Med") -> #REF! | P16: =COUNTIFS('GLOBAL LOG'!$D$6:$D$128,$C16,'GLOBAL LOG'!#REF!,"Low") -> #REF! | Q16: =COUNTIFS('GLOBAL LOG'!$D$6:$D$128,$C16,'GLOBAL LOG'!#REF!,"High") -> #REF! | R16: =COUNTIFS('GLOBAL LOG'!$D$6:$D$128,$C16,'GLOBAL LOG'!#REF!,"Med") -> #REF! | S16: =COUNTIFS('GLOBAL LOG'!$D$6:$D$128,$C16,'GLOBAL LOG'!#REF!,"Low") -> #REF! | T16: =COUNTIFS('GLOBAL LOG'!$D$6:$D$128,$C16,'GLOBAL LOG'!#REF!,"Completed") -> #REF! | U16: =COUNTIFS('GLOBAL LOG'!$D$6:$D$128,$C16,'GLOBAL LOG'!#REF!,"Contracting") -> #REF! | V16: =COUNTIFS('GLOBAL LOG'!$D$6:$D$128,$C16,'GLOBAL LOG'!#REF!,"Negotiations") -> #REF! | W16: =COUNTIFS('GLOBAL LOG'!$D$6:$D$128,$C16,'GLOBAL LOG'!#REF!,"ICT") -> #REF! | X16: =COUNTIFS('GLOBAL LOG'!$D$6:$D$128,$C16,'GLOBAL LOG'!#REF!,"Hopper") -> #REF! | Y16: =SUMIF('GLOBAL LOG'!$D$6:$D$128,$C16,'GLOBAL LOG'!$Q$6:$Q$128) -> 0 | Z16: =SUMIF('GLOBAL LOG'!$D$6:$D$128,$C16,'GLOBAL LOG'!$R$6:$R$128) -> 0 | AA16: =Y16+Z16 -> 0 | AB16: =SUMIF('GLOBAL LOG'!$D$6:$D$128,C16,'GLOBAL LOG'!#REF!) -> #REF! | AD16: Air Austral | AE16: #REF! | AG16: China Southern | AH16: 5 | AJ16: Aerolineas | AK16: 0 | AM16: China Southern | AN16: 5
C17: Air Belgium | D17: =COUNTIFS('GLOBAL LOG'!$D$6:$D$128,C17,'GLOBAL LOG'!$K$6:$K$128,"<>") -> 0 | E17: =COUNTIFS('GLOBAL LOG'!$D$6:$D$128,C17,'GLOBAL LOG'!#REF!,"Yes") -> #REF! | F17: =SUMIF('GLOBAL LOG'!$D$6:$D$128,COUNT!C17,'GLOBAL LOG'!#REF!) -> #REF! | G17: =COUNTIFS('GLOBAL LOG'!$E$6:$E$128,G$10,'GLOBAL LOG'!$D$6:$D$128,$C17) -> 0 | H17: =COUNTIFS('GLOBAL LOG'!$E$6:$E$128,H$10,'GLOBAL LOG'!$D$6:$D$128,$C17) -> 0 | I17: =COUNTIFS('GLOBAL LOG'!$E$6:$E$128,I$10,'GLOBAL LOG'!$D$6:$D$128,$C17) -> 0 | J17: =COUNTIFS('GLOBAL LOG'!$E$6:$E$128,J$10,'GLOBAL LOG'!$D$6:$D$128,$C17) -> 0 | K17: =COUNTIFS('GLOBAL LOG'!$E$6:$E$128,K$10,'GLOBAL LOG'!$D$6:$D$128,$C17) -> 0 | L17: =COUNTIFS('GLOBAL LOG'!$E$6:$E$128,L$10,'GLOBAL LOG'!$D$6:$D$128,$C17) -> 0 | M17: =COUNTIFS('GLOBAL LOG'!$E$6:$E$128,M$10,'GLOBAL LOG'!$D$6:$D$128,$C17) -> 0 | N17: =COUNTIFS('GLOBAL LOG'!$D$6:$D$128,$C17,'GLOBAL LOG'!#REF!,"High") -> #REF! | O17: =COUNTIFS('GLOBAL LOG'!$D$6:$D$128,$C17,'GLOBAL LOG'!#REF!,"Med") -> #REF! | P17: =COUNTIFS('GLOBAL LOG'!$D$6:$D$128,$C17,'GLOBAL LOG'!#REF!,"Low") -> #REF! | Q17: =COUNTIFS('GLOBAL LOG'!$D$6:$D$128,$C17,'GLOBAL LOG'!#REF!,"High") -> #REF! | R17: =COUNTIFS('GLOBAL LOG'!$D$6:$D$128,$C17,'GLOBAL LOG'!#REF!,"Med") -> #REF! | S17: =COUNTIFS('GLOBAL LOG'!$D$6:$D$128,$C17,'GLOBAL LOG'!#REF!,"Low") -> #REF! | T17: =COUNTIFS('GLOBAL LOG'!$D$6:$D$128,$C17,'GLOBAL LOG'!#REF!,"Completed") -> #REF! | U17: =COUNTIFS('GLOBAL LOG'!$D$6:$D$128,$C17,'GLOBAL LOG'!#REF!,"Contracting") -> #REF! | V17: =COUNTIFS('GLOBAL LOG'!$D$6:$D$128,$C17,'GLOBAL LOG'!#REF!,"Negotiations") -> #REF! | W17: =COUNTIFS('GLOBAL LOG'!$D$6:$D$128,$C17,'GLOBAL LOG'!#REF!,"ICT") -> #REF! | X17: =COUNTIFS('GLOBAL LOG'!$D$6:$D$128,$C17,'GLOBAL LOG'!#REF!,"Hopper") -> #REF! | Y17: =SUMIF('GLOBAL LOG'!$D$6:$D$128,$C17,'GLOBAL LOG'!$Q$6:$Q$128) -> 0 | Z17: =SUMIF('GLOBAL LOG'!$D$6:$D$128,$C17,'GLOBAL LOG'!$R$6:$R$128) -> 0 | AA17: =Y17+Z17 -> 0 | AB17: =SUMIF('GLOBAL LOG'!$D$6:$D$128,C17,'GLOBAL LOG'!#REF!) -> #REF! | AD17: Air Belgium | AE17: #REF! | AG17: Japan Airlines | AH17: 3.2 | AJ17: Air Algerie | AK17: 0 | AM17: Japan Airlines | AN17: 3.2
C18: Air Canada | D18: =COUNTIFS('GLOBAL LOG'!$D$6:$D$128,C18,'GLOBAL LOG'!$K$6:$K$128,"<>") -> 0 | E18: =COUNTIFS('GLOBAL LOG'!$D$6:$D$128,C18,'GLOBAL LOG'!#REF!,"Yes") -> #REF! | F18: =SUMIF('GLOBAL LOG'!$D$6:$D$128,COUNT!C18,'GLOBAL LOG'!#REF!) -> #REF! | G18: =COUNTIFS('GLOBAL LOG'!$E$6:$E$128,G$10,'GLOBAL LOG'!$D$6:$D$128,$C18) -> 0 | H18: =COUNTIFS('GLOBAL LOG'!$E$6:$E$128,H$10,'GLOBAL LOG'!$D$6:$D$128,$C18) -> 0 | I18: =COUNTIFS('GLOBAL LOG'!$E$6:$E$128,I$10,'GLOBAL LOG'!$D$6:$D$128,$C18) -> 0 | J18: =COUNTIFS('GLOBAL LOG'!$E$6:$E$128,J$10,'GLOBAL LOG'!$D$6:$D$128,$C18) -> 0 | K18: =COUNTIFS('GLOBAL LOG'!$E$6:$E$128,K$10,'GLOBAL LOG'!$D$6:$D$128,$C18) -> 0 | L18: =COUNTIFS('GLOBAL LOG'!$E$6:$E$128,L$10,'GLOBAL LOG'!$D$6:$D$128,$C18) -> 0 | M18: =COUNTIFS('GLOBAL LOG'!$E$6:$E$128,M$10,'GLOBAL LOG'!$D$6:$D$128,$C18) -> 0 | N18: =COUNTIFS('GLOBAL LOG'!$D$6:$D$128,$C18,'GLOBAL LOG'!#REF!,"High") -> #REF! | O18: =COUNTIFS('GLOBAL LOG'!$D$6:$D$128,$C18,'GLOBAL LOG'!#REF!,"Med") -> #REF! | P18: =COUNTIFS('GLOBAL LOG'!$D$6:$D$128,$C18,'GLOBAL LOG'!#REF!,"Low") -> #REF! | Q18: =COUNTIFS('GLOBAL LOG'!$D$6:$D$128,$C18,'GLOBAL LOG'!#REF!,"High") -> #REF! | R18: =COUNTIFS('GLOBAL LOG'!$D$6:$D$128,$C18,'GLOBAL LOG'!#REF!,"Med") -> #REF! | S18: =COUNTIFS('GLOBAL LOG'!$D$6:$D$128,$C18,'GLOBAL LOG'!#REF!,"Low") -> #REF! | T18: =COUNTIFS('GLOBAL LOG'!$D$6:$D$128,$C18,'GLOBAL LOG'!#REF!,"Completed") -> #REF! | U18: =COUNTIFS('GLOBAL LOG'!$D$6:$D$128,$C18,'GLOBAL LOG'!#REF!,"Contracting") -> #REF! | V18: =COUNTIFS('GLOBAL LOG'!$D$6:$D$128,$C18,'GLOBAL LOG'!#REF!,"Negotiations") -> #REF! | W18: =COUNTIFS('GLOBAL LOG'!$D$6:$D$128,$C18,'GLOBAL LOG'!#REF!,"ICT") -> #REF! | X18: =COUNTIFS('GLOBAL LOG'!$D$6:$D$128,$C18,'GLOBAL LOG'!#REF!,"Hopper") -> #REF! | Y18: =SUMIF('GLOBAL LOG'!$D$6:$D$128,$C18,'GLOBAL LOG'!$Q$6:$Q$128) -> 0 | Z18: =SUMIF('GLOBAL LOG'!$D$6:$D$128,$C18,'GLOBAL LOG'!$R$6:$R$128) -> 0 | AA18: =Y18+Z18 -> 0 | AB18: =SUMIF('GLOBAL LOG'!$D$6:$D$128,C18,'GLOBAL LOG'!#REF!) -> #REF! | AD18: Air Canada | AE18: #REF! | AG18: Aer Lingus | AH18: 0 | AJ18: Air Austral | AK18: 0 | AM18: Aer Lingus | AN18: 0
C19: Air Caraibes Atlantique | D19: =COUNTIFS('GLOBAL LOG'!$D$6:$D$128,C19,'GLOBAL LOG'!$K$6:$K$128,"<>") -> 0 | E19: =COUNTIFS('GLOBAL LOG'!$D$6:$D$128,C19,'GLOBAL LOG'!#REF!,"Yes") -> #REF! | F19: =SUMIF('GLOBAL LOG'!$D$6:$D$128,COUNT!C19,'GLOBAL LOG'!#REF!) -> #REF! | G19: =COUNTIFS('GLOBAL LOG'!$E$6:$E$128,G$10,'GLOBAL LOG'!$D$6:$D$128,$C19) -> 0 | H19: =COUNTIFS('GLOBAL LOG'!$E$6:$E$128,H$10,'GLOBAL LOG'!$D$6:$D$128,$C19) -> 0 | I19: =COUNTIFS('GLOBAL LOG'!$E$6:$E$128,I$10,'GLOBAL LOG'!$D$6:$D$128,$C19) -> 0 | J19: =COUNTIFS('GLOBAL LOG'!$E$6:$E$128,J$10,'GLOBAL LOG'!$D$6:$D$128,$C19) -> 0 | K19: =COUNTIFS('GLOBAL LOG'!$E$6:$E$128,K$10,'GLOBAL LOG'!$D$6:$D$128,$C19) -> 0 | L19: =COUNTIFS('GLOBAL LOG'!$E$6:$E$128,L$10,'GLOBAL LOG'!$D$6:$D$128,$C19) -> 0 | M19: =COUNTIFS('GLOBAL LOG'!$E$6:$E$128,M$10,'GLOBAL LOG'!$D$6:$D$128,$C19) -> 0 | N19: =COUNTIFS('GLOBAL LOG'!$D$6:$D$128,$C19,'GLOBAL LOG'!#REF!,"High") -> #REF! | O19: =COUNTIFS('GLOBAL LOG'!$D$6:$D$128,$C19,'GLOBAL LOG'!#REF!,"Med") -> #REF! | P19: =COUNTIFS('GLOBAL LOG'!$D$6:$D$128,$C19,'GLOBAL LOG'!#REF!,"Low") -> #REF! | Q19: =COUNTIFS('GLOBAL LOG'!$D$6:$D$128,$C19,'GLOBAL LOG'!#REF!,"High") -> #REF! | R19: =COUNTIFS('GLOBAL LOG'!$D$6:$D$128,$C19,'GLOBAL LOG'!#REF!,"Med") -> #REF! | S19: =COUNTIFS('GLOBAL LOG'!$D$6:$D$128,$C19,'GLOBAL LOG'!#REF!,"Low") -> #REF! | T19: =COUNTIFS('GLOBAL LOG'!$D$6:$D$128,$C19,'GLOBAL LOG'!#REF!,"Completed") -> #REF! | U19: =COUNTIFS('GLOBAL LOG'!$D$6:$D$128,$C19,'GLOBAL LOG'!#REF!,"Contracting") -> #REF! | V19: =COUNTIFS('GLOBAL LOG'!$D$6:$D$128,$C19,'GLOBAL LOG'!#REF!,"Negotiations") -> #REF! | W19: =COUNTIFS('GLOBAL LOG'!$D$6:$D$128,$C19,'GLOBAL LOG'!#REF!,"ICT") -> #REF! | X19: =COUNTIFS('GLOBAL LOG'!$D$6:$D$128,$C19,'GLOBAL LOG'!#REF!,"Hopper") -> #REF! | Y19: =SUMIF('GLOBAL LOG'!$D$6:$D$128,$C19,'GLOBAL LOG'!$Q$6:$Q$128) -> 0 | Z19: =SUMIF('GLOBAL LOG'!$D$6:$D$128,$C19,'GLOBAL LOG'!$R$6:$R$128) -> 0 | AA19: =Y19+Z19 -> 0 | AB19: =SUMIF('GLOBAL LOG'!$D$6:$D$128,C19,'GLOBAL LOG'!#REF!) -> #REF! | AD19: Air Caraibes Atlantique | AE19: #REF! | AG19: AerCap | AH19: 0 | AJ19: Air Belgium | AK19: 0 | AM19: AerCap | AN19: 0
C20: Air China | D20: =COUNTIFS('GLOBAL LOG'!$D$6:$D$128,C20,'GLOBAL LOG'!$K$6:$K$128,"<>") -> 1 | E20: =COUNTIFS('GLOBAL LOG'!$D$6:$D$128,C20,'GLOBAL LOG'!#REF!,"Yes") -> #REF! | F20: =SUMIF('GLOBAL LOG'!$D$6:$D$128,COUNT!C20,'GLOBAL LOG'!#REF!) -> #REF! | G20: =COUNTIFS('GLOBAL LOG'!$E$6:$E$128,G$10,'GLOBAL LOG'!$D$6:$D$128,$C20) -> 2 | H20: =COUNTIFS('GLOBAL LOG'!$E$6:$E$128,H$10,'GLOBAL LOG'!$D$6:$D$128,$C20) -> 0 | I20: =COUNTIFS('GLOBAL LOG'!$E$6:$E$128,I$10,'GLOBAL LOG'!$D$6:$D$128,$C20) -> 1 | J20: =COUNTIFS('GLOBAL LOG'!$E$6:$E$128,J$10,'GLOBAL LOG'!$D$6:$D$128,$C20) -> 0 | K20: =COUNTIFS('GLOBAL LOG'!$E$6:$E$128,K$10,'GLOBAL LOG'!$D$6:$D$128,$C20) -> 0 | L20: =COUNTIFS('GLOBAL LOG'!$E$6:$E$128,L$10,'GLOBAL LOG'!$D$6:$D$128,$C20) -> 0 | M20: =COUNTIFS('GLOBAL LOG'!$E$6:$E$128,M$10,'GLOBAL LOG'!$D$6:$D$128,$C20) -> 0 | N20: =COUNTIFS('GLOBAL LOG'!$D$6:$D$128,$C20,'GLOBAL LOG'!#REF!,"High") -> #REF! | O20: =COUNTIFS('GLOBAL LOG'!$D$6:$D$128,$C20,'GLOBAL LOG'!#REF!,"Med") -> #REF! | P20: =COUNTIFS('GLOBAL LOG'!$D$6:$D$128,$C20,'GLOBAL LOG'!#REF!,"Low") -> #REF! | Q20: =COUNTIFS('GLOBAL LOG'!$D$6:$D$128,$C20,'GLOBAL LOG'!#REF!,"High") -> #REF! | R20: =COUNTIFS('GLOBAL LOG'!$D$6:$D$128,$C20,'GLOBAL LOG'!#REF!,"Med") -> #REF! | S20: =COUNTIFS('GLOBAL LOG'!$D$6:$D$128,$C20,'GLOBAL LOG'!#REF!,"Low") -> #REF! | T20: =COUNTIFS('GLOBAL LOG'!$D$6:$D$128,$C20,'GLOBAL LOG'!#REF!,"Completed") -> #REF! | U20: =COUNTIFS('GLOBAL LOG'!$D$6:$D$128,$C20,'GLOBAL LOG'!#REF!,"Contracting") -> #REF! | V20: =COUNTIFS('GLOBAL LOG'!$D$6:$D$128,$C20,'GLOBAL LOG'!#REF!,"Negotiations") -> #REF! | W20: =COUNTIFS('GLOBAL LOG'!$D$6:$D$128,$C20,'GLOBAL LOG'!#REF!,"ICT") -> #REF! | X20: =COUNTIFS('GLOBAL LOG'!$D$6:$D$128,$C20,'GLOBAL LOG'!#REF!,"Hopper") -> #REF! | Y20: =SUMIF('GLOBAL LOG'!$D$6:$D$128,$C20,'GLOBAL LOG'!$Q$6:$Q$128) -> 5.3 | Z20: =SUMIF('GLOBAL LOG'!$D$6:$D$128,$C20,'GLOBAL LOG'!$R$6:$R$128) -> 33.6 | AA20: =Y20+Z20 -> 38.9 | AB20: =SUMIF('GLOBAL LOG'!$D$6:$D$128,C20,'GLOBAL LOG'!#REF!) -> #REF! | AD20: Air China | AE20: #REF! | AG20: Aeroflot Russian Airlines | AH20: 0 | AJ20: Air Canada | AK20: 0 | AM20: Aeroflot Russian Airlines | AN20: 0
C21: Air Europa Lineas Aereas S.A.U. | D21: =COUNTIFS('GLOBAL LOG'!$D$6:$D$128,C21,'GLOBAL LOG'!$K$6:$K$128,"<>") -> 0 | E21: =COUNTIFS('GLOBAL LOG'!$D$6:$D$128,C21,'GLOBAL LOG'!#REF!,"Yes") -> #REF! | F21: =SUMIF('GLOBAL LOG'!$D$6:$D$128,COUNT!C21,'GLOBAL LOG'!#REF!) -> #REF! | G21: =COUNTIFS('GLOBAL LOG'!$E$6:$E$128,G$10,'GLOBAL LOG'!$D$6:$D$128,$C21) -> 0 | H21: =COUNTIFS('GLOBAL LOG'!$E$6:$E$128,H$10,'GLOBAL LOG'!$D$6:$D$128,$C21) -> 0 | I21: =COUNTIFS('GLOBAL LOG'!$E$6:$E$128,I$10,'GLOBAL LOG'!$D$6:$D$128,$C21) -> 0 | J21: =COUNTIFS('GLOBAL LOG'!$E$6:$E$128,J$10,'GLOBAL LOG'!$D$6:$D$128,$C21) -> 0 | K21: =COUNTIFS('GLOBAL LOG'!$E$6:$E$128,K$10,'GLOBAL LOG'!$D$6:$D$128,$C21) -> 0 | L21: =COUNTIFS('GLOBAL LOG'!$E$6:$E$128,L$10,'GLOBAL LOG'!$D$6:$D$128,$C21) -> 0 | M21: =COUNTIFS('GLOBAL LOG'!$E$6:$E$128,M$10,'GLOBAL LOG'!$D$6:$D$128,$C21) -> 0 | N21: =COUNTIFS('GLOBAL LOG'!$D$6:$D$128,$C21,'GLOBAL LOG'!#REF!,"High") -> #REF! | O21: =COUNTIFS('GLOBAL LOG'!$D$6:$D$128,$C21,'GLOBAL LOG'!#REF!,"Med") -> #REF! | P21: =COUNTIFS('GLOBAL LOG'!$D$6:$D$128,$C21,'GLOBAL LOG'!#REF!,"Low") -> #REF! | Q21: =COUNTIFS('GLOBAL LOG'!$D$6:$D$128,$C21,'GLOBAL LOG'!#REF!,"High") -> #REF! | R21: =COUNTIFS('GLOBAL LOG'!$D$6:$D$128,$C21,'GLOBAL LOG'!#REF!,"Med") -> #REF! | S21: =COUNTIFS('GLOBAL LOG'!$D$6:$D$128,$C21,'GLOBAL LOG'!#REF!,"Low") -> #REF! | T21: =COUNTIFS('GLOBAL LOG'!$D$6:$D$128,$C21,'GLOBAL LOG'!#REF!,"Completed") -> #REF! | U21: =COUNTIFS('GLOBAL LOG'!$D$6:$D$128,$C21,'GLOBAL LOG'!#REF!,"Contracting") -> #REF! | V21: =COUNTIFS('GLOBAL LOG'!$D$6:$D$128,$C21,'GLOBAL LOG'!#REF!,"Negotiations") -> #REF! | W21: =COUNTIFS('GLOBAL LOG'!$D$6:$D$128,$C21,'GLOBAL LOG'!#REF!,"ICT") -> #REF! | X21: =COUNTIFS('GLOBAL LOG'!$D$6:$D$128,$C21,'GLOBAL LOG'!#REF!,"Hopper") -> #REF! | Y21: =SUMIF('GLOBAL LOG'!$D$6:$D$128,$C21,'GLOBAL LOG'!$Q$6:$Q$128) -> 0 | Z21: =SUMIF('GLOBAL LOG'!$D$6:$D$128,$C21,'GLOBAL LOG'!$R$6:$R$128) -> 0 | AA21: =Y21+Z21 -> 0 | AB21: =SUMIF('GLOBAL LOG'!$D$6:$D$128,C21,'GLOBAL LOG'!#REF!) -> #REF! | AD21: Air Europa Lineas Aereas S.A.U. | AE21: #REF! | AG21: Aerolineas | AH21: 0 | AJ21: Air Caraibes Atlantique | AK21: 0 | AM21: Aerolineas | AN21: 0
C22: Air France | D22: =COUNTIFS('GLOBAL LOG'!$D$6:$D$128,C22,'GLOBAL LOG'!$K$6:$K$128,"<>") -> 0 | E22: =COUNTIFS('GLOBAL LOG'!$D$6:$D$128,C22,'GLOBAL LOG'!#REF!,"Yes") -> #REF! | F22: =SUMIF('GLOBAL LOG'!$D$6:$D$128,COUNT!C22,'GLOBAL LOG'!#REF!) -> #REF! | G22: =COUNTIFS('GLOBAL LOG'!$E$6:$E$128,G$10,'GLOBAL LOG'!$D$6:$D$128,$C22) -> 0 | H22: =COUNTIFS('GLOBAL LOG'!$E$6:$E$128,H$10,'GLOBAL LOG'!$D$6:$D$128,$C22) -> 0 | I22: =COUNTIFS('GLOBAL LOG'!$E$6:$E$128,I$10,'GLOBAL LOG'!$D$6:$D$128,$C22) -> 0 | J22: =COUNTIFS('GLOBAL LOG'!$E$6:$E$128,J$10,'GLOBAL LOG'!$D$6:$D$128,$C22) -> 0 | K22: =COUNTIFS('GLOBAL LOG'!$E$6:$E$128,K$10,'GLOBAL LOG'!$D$6:$D$128,$C22) -> 0 | L22: =COUNTIFS('GLOBAL LOG'!$E$6:$E$128,L$10,'GLOBAL LOG'!$D$6:$D$128,$C22) -> 0 | M22: =COUNTIFS('GLOBAL LOG'!$E$6:$E$128,M$10,'GLOBAL LOG'!$D$6:$D$128,$C22) -> 0 | N22: =COUNTIFS('GLOBAL LOG'!$D$6:$D$128,$C22,'GLOBAL LOG'!#REF!,"High") -> #REF! | O22: =COUNTIFS('GLOBAL LOG'!$D$6:$D$128,$C22,'GLOBAL LOG'!#REF!,"Med") -> #REF! | P22: =COUNTIFS('GLOBAL LOG'!$D$6:$D$128,$C22,'GLOBAL LOG'!#REF!,"Low") -> #REF! | Q22: =COUNTIFS('GLOBAL LOG'!$D$6:$D$128,$C22,'GLOBAL LOG'!#REF!,"High") -> #REF! | R22: =COUNTIFS('GLOBAL LOG'!$D$6:$D$128,$C22,'GLOBAL LOG'!#REF!,"Med") -> #REF! | S22: =COUNTIFS('GLOBAL LOG'!$D$6:$D$128,$C22,'GLOBAL LOG'!#REF!,"Low") -> #REF! | T22: =COUNTIFS('GLOBAL LOG'!$D$6:$D$128,$C22,'GLOBAL LOG'!#REF!,"Completed") -> #REF! | U22: =COUNTIFS('GLOBAL LOG'!$D$6:$D$128,$C22,'GLOBAL LOG'!#REF!,"Contracting") -> #REF! | V22: =COUNTIFS('GLOBAL LOG'!$D$6:$D$128,$C22,'GLOBAL LOG'!#REF!,"Negotiations") -> #REF! | W22: =COUNTIFS('GLOBAL LOG'!$D$6:$D$128,$C22,'GLOBAL LOG'!#REF!,"ICT") -> #REF! | X22: =COUNTIFS('GLOBAL LOG'!$D$6:$D$128,$C22,'GLOBAL LOG'!#REF!,"Hopper") -> #REF! | Y22: =SUMIF('GLOBAL LOG'!$D$6:$D$128,$C22,'GLOBAL LOG'!$Q$6:$Q$128) -> 0 | Z22: =SUMIF('GLOBAL LOG'!$D$6:$D$128,$C22,'GLOBAL LOG'!$R$6:$R$128) -> 0 | AA22: =Y22+Z22 -> 0 | AB22: =SUMIF('GLOBAL LOG'!$D$6:$D$128,C22,'GLOBAL LOG'!#REF!) -> #REF! | AD22: Air France | AE22: #REF! | AG22: Air Algerie | AH22: 0 | AJ22: Air Europa Lineas Aereas S.A.U. | AK22: 0 | AM22: Air Algerie | AN22: 0
C23: Air Greenland | D23: =COUNTIFS('GLOBAL LOG'!$D$6:$D$128,C23,'GLOBAL LOG'!$K$6:$K$128,"<>") -> 0 | E23: =COUNTIFS('GLOBAL LOG'!$D$6:$D$128,C23,'GLOBAL LOG'!#REF!,"Yes") -> #REF! | F23: =SUMIF('GLOBAL LOG'!$D$6:$D$128,COUNT!C23,'GLOBAL LOG'!#REF!) -> #REF! | G23: =COUNTIFS('GLOBAL LOG'!$E$6:$E$128,G$10,'GLOBAL LOG'!$D$6:$D$128,$C23) -> 0 | H23: =COUNTIFS('GLOBAL LOG'!$E$6:$E$128,H$10,'GLOBAL LOG'!$D$6:$D$128,$C23) -> 0 | I23: =COUNTIFS('GLOBAL LOG'!$E$6:$E$128,I$10,'GLOBAL LOG'!$D$6:$D$128,$C23) -> 0 | J23: =COUNTIFS('GLOBAL LOG'!$E$6:$E$128,J$10,'GLOBAL LOG'!$D$6:$D$128,$C23) -> 0 | K23: =COUNTIFS('GLOBAL LOG'!$E$6:$E$128,K$10,'GLOBAL LOG'!$D$6:$D$128,$C23) -> 0 | L23: =COUNTIFS('GLOBAL LOG'!$E$6:$E$128,L$10,'GLOBAL LOG'!$D$6:$D$128,$C23) -> 0 | M23: =COUNTIFS('GLOBAL LOG'!$E$6:$E$128,M$10,'GLOBAL LOG'!$D$6:$D$128,$C23) -> 0 | N23: =COUNTIFS('GLOBAL LOG'!$D$6:$D$128,$C23,'GLOBAL LOG'!#REF!,"High") -> #REF! | O23: =COUNTIFS('GLOBAL LOG'!$D$6:$D$128,$C23,'GLOBAL LOG'!#REF!,"Med") -> #REF! | P23: =COUNTIFS('GLOBAL LOG'!$D$6:$D$128,$C23,'GLOBAL LOG'!#REF!,"Low") -> #REF! | Q23: =COUNTIFS('GLOBAL LOG'!$D$6:$D$128,$C23,'GLOBAL LOG'!#REF!,"High") -> #REF! | R23: =COUNTIFS('GLOBAL LOG'!$D$6:$D$128,$C23,'GLOBAL LOG'!#REF!,"Med") -> #REF! | S23: =COUNTIFS('GLOBAL LOG'!$D$6:$D$128,$C23,'GLOBAL LOG'!#REF!,"Low") -> #REF! | T23: =COUNTIFS('GLOBAL LOG'!$D$6:$D$128,$C23,'GLOBAL LOG'!#REF!,"Completed") -> #REF! | U23: =COUNTIFS('GLOBAL LOG'!$D$6:$D$128,$C23,'GLOBAL LOG'!#REF!,"Contracting") -> #REF! | V23: =COUNTIFS('GLOBAL LOG'!$D$6:$D$128,$C23,'GLOBAL LOG'!#REF!,"Negotiations") -> #REF! | W23: =COUNTIFS('GLOBAL LOG'!$D$6:$D$128,$C23,'GLOBAL LOG'!#REF!,"ICT") -> #REF! | X23: =COUNTIFS('GLOBAL LOG'!$D$6:$D$128,$C23,'GLOBAL LOG'!#REF!,"Hopper") -> #REF! | Y23: =SUMIF('GLOBAL LOG'!$D$6:$D$128,$C23,'GLOBAL LOG'!$Q$6:$Q$128) -> 0 | Z23: =SUMIF('GLOBAL LOG'!$D$6:$D$128,$C23,'GLOBAL LOG'!$R$6:$R$128) -> 0 | AA23: =Y23+Z23 -> 0 | AB23: =SUMIF('GLOBAL LOG'!$D$6:$D$128,C23,'GLOBAL LOG'!#REF!) -> #REF! | AD23: Air Greenland | AE23: #REF! | AG23: Air Austral | AH23: 0 | AJ23: Air France | AK23: 0 | AM23: Air Austral | AN23: 0
... C162: VallJet | D162: =COUNTIFS('GLOBAL LOG'!$D$6:$D$128,C162,'GLOBAL LOG'!$K$6:$K$128,"<>") -> 0 | E162: =COUNTIFS('GLOBAL LOG'!$D$6:$D$128,C162,'GLOBAL LOG'!#REF!,"Yes") -> #REF! | F162: =SUMIF('GLOBAL LOG'!$D$6:$D$128,COUNT!C162,'GLOBAL LOG'!#REF!) -> #REF! | G162: =COUNTIFS('GLOBAL LOG'!$E$6:$E$128,G$10,'GLOBAL LOG'!$D$6:$D$128,$C162) -> 0 | H162: =COUNTIFS('GLOBAL LOG'!$E$6:$E$128,H$10,'GLOBAL LOG'!$D$6:$D$128,$C162) -> 0 | I162: =COUNTIFS('GLOBAL LOG'!$E$6:$E$128,I$10,'GLOBAL LOG'!$D$6:$D$128,$C162) -> 0 | J162: =COUNTIFS('GLOBAL LOG'!$E$6:$E$128,J$10,'GLOBAL LOG'!$D$6:$D$128,$C162) -> 0 | K162: =COUNTIFS('GLOBAL LOG'!$E$6:$E$128,K$10,'GLOBAL LOG'!$D$6:$D$128,$C162) -> 0 | L162: =COUNTIFS('GLOBAL LOG'!$E$6:$E$128,L$10,'GLOBAL LOG'!$D$6:$D$128,$C162) -> 0 | M162: =COUNTIFS('GLOBAL LOG'!$E$6:$E$128,M$10,'GLOBAL LOG'!$D$6:$D$128,$C162) -> 0 | N162: =COUNTIFS('GLOBAL LOG'!$D$6:$D$128,$C162,'GLOBAL LOG'!#REF!,"High") -> #REF! | O162: =COUNTIFS('GLOBAL LOG'!$D$6:$D$128,$C162,'GLOBAL LOG'!#REF!,"Med") -> #REF! | P162: =COUNTIFS('GLOBAL LOG'!$D$6:$D$128,$C162,'GLOBAL LOG'!#REF!,"Low") -> #REF! | Q162: =COUNTIFS('GLOBAL LOG'!$D$6:$D$128,$C162,'GLOBAL LOG'!#REF!,"High") -> #REF! | R162: =COUNTIFS('GLOBAL LOG'!$D$6:$D$128,$C162,'GLOBAL LOG'!#REF!,"Med") -> #REF! | S162: =COUNTIFS('GLOBAL LOG'!$D$6:$D$128,$C162,'GLOBAL LOG'!#REF!,"Low") -> #REF! | T162: =COUNTIFS('GLOBAL LOG'!$D$6:$D$128,$C162,'GLOBAL LOG'!#REF!,"Completed") -> #REF! | U162: =COUNTIFS('GLOBAL LOG'!$D$6:$D$128,$C162,'GLOBAL LOG'!#REF!,"Contracting") -> #REF! | V162: =COUNTIFS('GLOBAL LOG'!$D$6:$D$128,$C162,'GLOBAL LOG'!#REF!,"Negotiations") -> #REF! | W162: =COUNTIFS('GLOBAL LOG'!$D$6:$D$128,$C162,'GLOBAL LOG'!#REF!,"ICT") -> #REF! | X162: =COUNTIFS('GLOBAL LOG'!$D$6:$D$128,$C162,'GLOBAL LOG'!#REF!,"Hopper") -> #REF! | Y162: =SUMIF('GLOBAL LOG'!$D$6:$D$128,$C162,'GLOBAL LOG'!$Q$6:$Q$128) -> 0 | Z162: =SUMIF('GLOBAL LOG'!$D$6:$D$128,$C162,'GLOBAL LOG'!$R$6:$R$128) -> 0 | AA162: =Y162+Z162 -> 0 | AB162: =SUMIF('GLOBAL LOG'!$D$6:$D$128,C162,'GLOBAL LOG'!#REF!) -> #REF! | AD162: VallJet | AE162: #REF! | AG162: VallJet | AH162: 0 | AJ162: VallJet | AK162: 0 | AM162: VallJet | AN162: 0
D163: =COUNTIFS('GLOBAL LOG'!$D$6:$D$128,C163,'GLOBAL LOG'!$K$6:$K$128,"<>") -> 0 | E163: =COUNTIFS('GLOBAL LOG'!$D$6:$D$128,C163,'GLOBAL LOG'!#REF!,"Yes") -> #REF! | F163: =SUMIF('GLOBAL LOG'!$D$6:$D$128,COUNT!C163,'GLOBAL LOG'!#REF!) -> #REF! | G163: =COUNTIFS('GLOBAL LOG'!$E$6:$E$128,G$10,'GLOBAL LOG'!$D$6:$D$128,$C163) -> 0 | H163: =COUNTIFS('GLOBAL LOG'!$E$6:$E$128,H$10,'GLOBAL LOG'!$D$6:$D$128,$C163) -> 0 | I163: =COUNTIFS('GLOBAL LOG'!$E$6:$E$128,I$10,'GLOBAL LOG'!$D$6:$D$128,$C163) -> 0 | J163: =COUNTIFS('GLOBAL LOG'!$E$6:$E$128,J$10,'GLOBAL LOG'!$D$6:$D$128,$C163) -> 0 | K163: =COUNTIFS('GLOBAL LOG'!$E$6:$E$128,K$10,'GLOBAL LOG'!$D$6:$D$128,$C163) -> 0 | L163: =COUNTIFS('GLOBAL LOG'!$E$6:$E$128,L$10,'GLOBAL LOG'!$D$6:$D$128,$C163) -> 0 | M163: =COUNTIFS('GLOBAL LOG'!$E$6:$E$128,M$10,'GLOBAL LOG'!$D$6:$D$128,$C163) -> 0 | N163: =COUNTIFS('GLOBAL LOG'!$D$6:$D$128,$C163,'GLOBAL LOG'!#REF!,"High") -> #REF! | O163: =COUNTIFS('GLOBAL LOG'!$D$6:$D$128,$C163,'GLOBAL LOG'!#REF!,"Med") -> #REF! | P163: =COUNTIFS('GLOBAL LOG'!$D$6:$D$128,$C163,'GLOBAL LOG'!#REF!,"Low") -> #REF! | Q163: =COUNTIFS('GLOBAL LOG'!$D$6:$D$128,$C163,'GLOBAL LOG'!#REF!,"High") -> #REF! | R163: =COUNTIFS('GLOBAL LOG'!$D$6:$D$128,$C163,'GLOBAL LOG'!#REF!,"Med") -> #REF! | S163: =COUNTIFS('GLOBAL LOG'!$D$6:$D$128,$C163,'GLOBAL LOG'!#REF!,"Low") -> #REF! | T163: =COUNTIFS('GLOBAL LOG'!$D$6:$D$128,$C163,'GLOBAL LOG'!#REF!,"Completed") -> #REF! | U163: =COUNTIFS('GLOBAL LOG'!$D$6:$D$128,$C163,'GLOBAL LOG'!#REF!,"Contracting") -> #REF! | V163: =COUNTIFS('GLOBAL LOG'!$D$6:$D$128,$C163,'GLOBAL LOG'!#REF!,"Negotiations") -> #REF! | W163: =COUNTIFS('GLOBAL LOG'!$D$6:$D$128,$C163,'GLOBAL LOG'!#REF!,"ICT") -> #REF! | X163: =COUNTIFS('GLOBAL LOG'!$D$6:$D$128,$C163,'GLOBAL LOG'!#REF!,"Hopper") -> #REF! | Y163: =SUMIF('GLOBAL LOG'!$D$6:$D$128,$C163,'GLOBAL LOG'!$Q$6:$Q$128) -> 0 | Z163: =SUMIF('GLOBAL LOG'!$D$6:$D$128,$C163,'GLOBAL LOG'!$R$6:$R$128) -> 0 | AA163: =Y163+Z163 -> 0 | AB163: =SUMIF('GLOBAL LOG'!$D$6:$D$128,C163,'GLOBAL LOG'!#REF!) -> #REF! | AD163: 0 | AE163: #REF! | AG163: 0 | AH163: 0 | AJ163: 0 | AK163: 0 | AM163: 0 | AN163: 0
