Workbook
Name Accounts: [1]INPUT!#REF!
Name Milestones: Table711[]
Name Milestones: #REF!
Name Project_Timeline: #REF!

Sheet L2
C3: OPP LOG SHEET | V3: Hopper | Z3: OPP LOG SHEET | BO3: RESOURCE PRIORITIZATION
V5: ICT Estimates
S6: 45861
V7: Contract
C8: AWAY DAY DATE | E8: 45768
BO9: High Priority | BP9: Med Priority | BQ9: Low Priority | BR9: Not Required
Q10: ICT Evaluations | BO10: 3 | BP10: 2 | BQ10: 1
Q12: SUMS: | S12: =SUM(S15:S99) -> 1834.032 | T12: =SUM(T15:T99) -> 151.85373 | U12: =SUM(U15:U99) -> 218.2044 | V12: =SUM(V15:V99) -> 370.05813 | Z12: Existing Deal | AM12: New Deal | AZ12: Supporting Financial Information | BI12: To Go | BO12: Priority
M13: =SUM($N$15:$N$513) -> 10.73 | N13: =SUM($O$15:$O$513) -> 0 | Z13: Cash Reciepts | AF13: In Year Profit | AM13: Cash Reciepts | AS13: In Year Profit
C14: # | D14: Project | E14: Programme | F14: Customer | G14: Region | H14: Asks | I14: Type of Opportunity | J14: Levers | K14: Priority | L14: SPE related | M14: No,of SPE | N14: CRP% | O14: External Probability | P14: Internal Complexity | Q14: Status | R14: Evaluation Level | S14: Term Benefit | T14: 2026 | U14: 2027 | V14: Sum of 26/27 | Z14: 2025 | AA14: 2026 | AB14: 2027 | AC14: 2028 | AD14: 2029 | AE14: 2030 | AF14: 2025 | AG14: 2026 | AH14: 2027 | AI14: 2028 | AJ14: 2029 | AK14: 2030 | AM14: 2025 | AN14: 2026 | AO14: 2027 | AP14: 2028 | AQ14: 2029 | AR14: 2030 | AS14: 2025 | AT14: 2026 | AU14: 2027 | AV14: 2028 | AW14: 2029 | AX14: 2030 | AZ14: Deal Benefits | BA14: Expected Deal Costs | BB14: In-year Profit Impact | BC14: 5YP Profit Improvement | BD14: Term Profit Imprvement | BE14: Total CRP Term Revnue | BF14: Total CRP Term Margin | BG14: CRP Margin % | BI14: Term Revenue | BJ14: Term Cost | BK14: Term Profit | BO14: Account Management | BP14: Contract Management | BQ14: Service Business | BR14: Business Evalautaion | BS14: Sales & Contracting | BT14: Customer Operations
C15: 1 | D15: {=IF('MEA LOG'!D15:Q100="","",'MEA LOG'!D15:Q100)} -> FiniQ II | E15: Trent XWB-84 | F15: Emirates | G15: MEA | H15: 3 year-extension + LRU Management + 23 a/c | I15: TCA Amendments | J15: XWB MRO - OWS Support - 97k & EP Pricing | K15: 1 | N15: 0 | O15: High | P15: Low | Q15: Completed | S15: =231*1.48 -> 341.88 | V15: =SUM(T15+U15) -> 0 | Y15: 0 | Z15: 0 | AA15: 0 | AB15: 0 | AC15: 0 | AD15: 0 | AE15: 0 | AF15: 0 | AG15: 0 | AH15: 0 | AI15: 0 | AJ15: 0 | AK15: 0 | AL15: 0 | AM15: 0 | AN15: 0 | AO15: 0 | AP15: 0 | AQ15: 0 | AR15: 0 | AS15: 0 | AT15: 0 | AU15: 0 | AV15: 0 | AW15: 0 | AX15: 0 | AZ15: 0 | BA15: 0 | BB15: 0 | BC15: 0 | BD15: 0 | BE15: 0 | BF15: 0 | BI15: 0 | BJ15: 0 | BK15: 0 | BO15: 1 | BP15: 1 | BQ15: 1 | BR15: 1 | BS15: 1 | BT15: 1 | BU15: 1 | BV15: 1 | BW15: 1 | BX15: 1 | BY15: 1 | BZ15: 1 | CA15: 1 | CB15: 1 | CC15: 1 | CD15: 1 | CE15: 1
C16: =C15+1 -> 2 | D16: FiniQ III | E16: Trent XWB-84 | F16: Emirates | G16: MEA | H16: OWS - eliminate $20k remedy | I16: Cost Reduction | J16: New Campaign | K16: 1 | N16: 0 | O16: High | P16: Low | Q16: Contracting | S16: 54 | T16: 0 | U16: 3 | V16: =SUM(T16+U16) -> 3 | Y16: 0 | Z16: 0 | AA16: 0 | AB16: 0 | AC16: 0 | AD16: 0 | AE16: 0 | AF16: 0 | AG16: 0 | AH16: 0 | AI16: 0 | AJ16: 0 | AK16: 0 | AL16: 0 | AM16: 0 | AN16: 0 | AO16: 0 | AP16: 0 | AQ16: 0 | AR16: 0 | AS16: 0 | AT16: 0 | AU16: 0 | AV16: 0 | AW16: 0 | AX16: 0 | AZ16: 0 | BA16: 0 | BB16: 0 | BC16: 0 | BD16: 0 | BE16: 0 | BF16: 0 | BI16: 0 | BJ16: 0 | BK16: 0 | BO16: 1 | BP16: 1 | BQ16: 1 | BR16: 1 | BS16: 1 | BT16: 1 | BU16: 1 | BV16: 1 | BW16: 1 | BX16: 1 | BY16: 1 | BZ16: 1 | CA16: 1 | CB16: 1 | CC16: 1 | CD16: 1 | CE16: 1
C17: =C16+1 -> 3 | D17: IDK | E17: Trent XWB-84 | F17: Emirates | G17: MEA | H17: Additional 3 x SPE (10 %to 12%) | I17: SPE increase | J17: New Campaign | K17: 2 | L17: yes | M17: 3 | N17: 0 | O17: Low | P17: Med | Q17: Hopper | S17: 50 | V17: =SUM(T17+U17) -> 0 | Y17: 0 | Z17: 0 | AA17: 0 | AB17: 0 | AC17: 0 | AD17: 0 | AE17: 0 | AF17: 0 | AG17: 0 | AH17: 0 | AI17: 0 | AJ17: 0 | AK17: 0 | AL17: 0 | AM17: 0 | AN17: 0 | AO17: 0 | AP17: 0 | AQ17: 0 | AR17: 0 | AS17: 0 | AT17: 0 | AU17: 0 | AV17: 0 | AW17: 0 | AX17: 0 | AZ17: 0 | BA17: 0 | BB17: 0 | BC17: 0 | BD17: 0 | BE17: 0 | BF17: 0 | BI17: 0 | BJ17: 0 | BK17: 0 | BO17: 1 | BP17: 1 | BQ17: 1 | BR17: 1 | BS17: 1 | BT17: 1 | BU17: 1 | BV17: 1 | BW17: 1 | BX17: 1 | BY17: 1 | BZ17: 1 | CA17: 1 | CB17: 1 | CC17: 1 | CD17: 1 | CE17: 1
C18: =C17+1 -> 4 | D18: IDK | E18: Trent XWB-84 | F18: Emirates | G18: MEA | H18: Eliminate NDSES Cost via DAT | I18: Cost Reduction | J18: New Campaign/Settlement | K18: 2 | N18: 0 | O18: Med | P18: Med | Q18: ICT | S18: 11.4 | V18: =SUM(T18+U18) -> 0 | Y18: 0 | Z18: 0 | AA18: 0 | AB18: 0 | AC18: 0 | AD18: 0 | AE18: 0 | AF18: 0 | AG18: 0 | AH18: 0 | AI18: 0 | AJ18: 0 | AK18: 0 | AL18: 0 | AM18: 0 | AN18: 0 | AO18: 0 | AP18: 0 | AQ18: 0 | AR18: 0 | AS18: 0 | AT18: 0 | AU18: 0 | AV18: 0 | AW18: 0 | AX18: 0 | AZ18: 0 | BA18: 0 | BB18: 0 | BC18: 0 | BD18: 0 | BE18: 0 | BF18: 0 | BI18: 0 | BJ18: 0 | BK18: 0 | BO18: 1 | BP18: 1 | BQ18: 1 | BR18: 1 | BS18: 1 | BT18: 1 | BU18: 1 | BV18: 1 | BW18: 1 | BX18: 1 | BY18: 1 | BZ18: 1 | CA18: 1 | CB18: 1 | CC18: 1 | CD18: 1 | CE18: 1
C19: =C18+1 -> 5 | D19: IDK | E19: Trent XWB-84 | F19: Emirates | G19: MEA | H19: Increase in escalation from 2% to 3% | I19: TCA Amendments | J19: XWB MRO - OWS Support - 97k & EP Pricing | K19: 2 | N19: 0 | O19: Low | P19: Low | Q19: Hopper | S19: 170 | V19: =SUM(T19+U19) -> 0 | Y19: 0 | Z19: 0 | AA19: 0 | AB19: 0 | AC19: 0 | AD19: 0 | AE19: 0 | AF19: 0 | AG19: 0 | AH19: 0 | AI19: 0 | AJ19: 0 | AK19: 0 | AL19: 0 | AM19: 0 | AN19: 0 | AO19: 0 | AP19: 0 | AQ19: 0 | AR19: 0 | AS19: 0 | AT19: 0 | AU19: 0 | AV19: 0 | AW19: 0 | AX19: 0 | AZ19: 0 | BA19: 0 | BB19: 0 | BC19: 0 | BD19: 0 | BE19: 0 | BF19: 0 | BI19: 0 | BJ19: 0 | BK19: 0 | BO19: 1 | BP19: 1 | BQ19: 1 | BR19: 1 | BS19: 1 | BT19: 1 | BU19: 1 | BV19: 1 | BW19: 1 | BX19: 1 | BY19: 1 | BZ19: 1 | CA19: 1 | CB19: 1 | CC19: 1 | CD19: 1 | CE19: 1
C20: =C19+1 -> 6 | D20: IDK | E20: Trent XWB-84 | F20: Emirates | G20: MEA | H20: Introduce Precedent Matrix | I20: TCA Amendments | J20: XWB MRO - OWS Support - 97k & EP Pricing | K20: 2 | N20: 0 | O20: Low | P20: Med | Q20: Hopper | S20: 50 | V20: =SUM(T20+U20) -> 0 | Y20: 0 | Z20: 0 | AA20: 0 | AB20: 0 | AC20: 0 | AD20: 0 | AE20: 0 | AF20: 0 | AG20: 0 | AH20: 0 | AI20: 0 | AJ20: 0 | AK20: 0 | AL20: 0 | AM20: 0 | AN20: 0 | AO20: 0 | AP20: 0 | AQ20: 0 | AR20: 0 | AS20: 0 | AT20: 0 | AU20: 0 | AV20: 0 | AW20: 0 | AX20: 0 | AZ20: 0 | BA20: 0 | BB20: 0 | BC20: 0 | BD20: 0 | BE20: 0 | BF20: 0 | BI20: 0 | BJ20: 0 | BK20: 0 | BO20: 1 | BP20: 1 | BQ20: 1 | BR20: 1 | BS20: 1 | BT20: 1 | BU20: 1 | BV20: 1 | BW20: 1 | BX20: 1 | BY20: 1 | BZ20: 1 | CA20: 1 | CB20: 1 | CC20: 1 | CD20: 1 | CE20: 1
C21: =C20+1 -> 7 | D21: Selassi | E21: Trent XWB-84 | F21: Ethiopia | G21: MEA | H21: SPE Pull forward | I21: TCA Amendments | J21: AOG Risk | K21: 1 | L21: yes | M21: 1 | N21: 0.49 | O21: Low | P21: Low | Q21: Completed | S21: 10 | T21: 1 | U21: 1 | V21: =SUM(T21+U21) -> 2 | Y21: 0 | Z21: 0 | AA21: 0 | AB21: 0 | AC21: 0 | AD21: 0 | AE21: 0 | AF21: 0 | AG21: 0 | AH21: 0 | AI21: 0 | AJ21: 0 | AK21: 0 | AL21: 0 | AM21: 0 | AN21: 0 | AO21: 0 | AP21: 0 | AQ21: 0 | AR21: 0 | AS21: 0 | AT21: 0 | AU21: 0 | AV21: 0 | AW21: 0 | AX21: 0 | AZ21: 0 | BA21: 0 | BB21: 0 | BC21: 0 | BD21: 0 | BE21: 0 | BF21: 0 | BI21: 0 | BJ21: 0 | BK21: 0
C22: =C21+1 -> 8 | D22: Selassi | E22: Trent XWB-84 | F22: Ethiopia | G22: MEA | H22: Incremental SPE | I22: SPE increase | J22: 2 Addition a/c | K22: 1 | L22: yes | M22: 1 | N22: 0 | O22: High | P22: Low | Q22: Negotiations | S22: 3 | T22: 0 | U22: 3 | V22: 3 | Y22: 0 | Z22: 0 | AA22: 0 | AB22: 0 | AC22: 0 | AD22: 0 | AE22: 0 | AF22: 0 | AG22: 0 | AH22: 0 | AI22: 0 | AJ22: 0 | AK22: 0 | AL22: 0 | AM22: 0 | AN22: 0 | AO22: 0 | AP22: 0 | AQ22: 0 | AR22: 0 | AS22: 0 | AT22: 0 | AU22: 0 | AV22: 0 | AW22: 0 | AX22: 0 | AZ22: 0 | BA22: 0 | BB22: 0 | BC22: 0 | BD22: 0 | BE22: 0 | BF22: 0 | BI22: 0 | BJ22: 0 | BK22: 0
C23: =C22+1 -> 9 | D23: Selassi | E23: Trent 1000 | F23: Ethiopia | G23: MEA | H23: Incremental SPE | I23: SPE increase | J23: Campaign | K23: 1 | L23: yes | N23: 0.54 | O23: Med | P23: Low | Q23: Hopper | S23: 33 | T23: =S23/12 -> 2.75 | U23: =S23/12 -> 2.75 | V23: 5.5 | Y23: 0 | Z23: 0 | AA23: 0 | AB23: 0 | AC23: 0 | AD23: 0 | AE23: 0 | AF23: 0 | AG23: 0 | AH23: 0 | AI23: 0 | AJ23: 0 | AK23: 0 | AL23: 0 | AM23: 0 | AN23: 0 | AO23: 0 | AP23: 0 | AQ23: 0 | AR23: 0 | AS23: 0 | AT23: 0 | AU23: 0 | AV23: 0 | AW23: 0 | AX23: 0 | AZ23: 0 | BA23: 0 | BB23: 0 | BC23: 0 | BD23: 0 | BE23: 0 | BF23: 0 | BI23: 0 | BJ23: 0 | BK23: 0
C24: =C23+1 -> 10 | D24: Selassi | E24: Trent 1000 | F24: Ethiopia | G24: MEA | H24: Min Term Extension (life) | I24: Term Extension | J24: Campaign | K24: 1 | N24: 0.54 | O24: Med | P24: Med | Q24: Hopper | S24: 43 | T24: 5.92 | U24: 0 | V24: =SUM(T24+U24) -> 5.92 | Y24: 0 | Z24: 0 | AA24: 0 | AB24: 0 | AC24: 0 | AD24: 0 | AE24: 0 | AF24: 0 | AG24: 0 | AH24: 0 | AI24: 0 | AJ24: 0 | AK24: 0 | AL24: 0 | AM24: 0 | AN24: 0 | AO24: 0 | AP24: 0 | AQ24: 0 | AR24: 0 | AS24: 0 | AT24: 0 | AU24: 0 | AV24: 0 | AW24: 0 | AX24: 0 | AZ24: 0 | BA24: 0 | BB24: 0 | BC24: 0 | BD24: 0 | BE24: 0 | BF24: 0 | BI24: 0 | BJ24: 0 | BK24: 0
C25: =C24+1 -> 11 | D25: Selassi II | E25: Trent XWB-84 | F25: Ethiopia | G25: MEA | H25: Min Term Extension | I25: Term Extension | J25: Campaign | K25: 1 | N25: 0.49 | O25: Med | P25: Med | Q25: Hopper | S25: 30 | T25: 0 | U25: 30 | V25: =SUM(T25+U25) -> 30 | Y25: 0 | Z25: 0 | AA25: 0 | AB25: 0 | AC25: 0 | AD25: 0 | AE25: 0 | AF25: 0 | AG25: 0 | AH25: 0 | AI25: 0 | AJ25: 0 | AK25: 0 | AL25: 0 | AM25: 0 | AN25: 0 | AO25: 0 | AP25: 0 | AQ25: 0 | AR25: 0 | AS25: 0 | AT25: 0 | AU25: 0 | AV25: 0 | AW25: 0 | AX25: 0 | AZ25: 0 | BA25: 0 | BB25: 0 | BC25: 0 | BD25: 0 | BE25: 0 | BF25: 0 | BI25: 0 | BJ25: 0 | BK25: 0
C26: =C25+1 -> 12 | D26: Selassi II | E26: Trent XWB-84 | F26: Ethiopia | G26: MEA | H26: Increase escalation | I26: TCA Amendments | J26: Campaign | K26: 1 | N26: 0.49 | O26: Low | P26: Low | Q26: Hopper | S26: 11.84 | T26: 0 | U26: 2.368 | V26: =SUM(T26+U26) -> 2.368 | Y26: 0 | Z26: 0 | AA26: 0 | AB26: 0 | AC26: 0 | AD26: 0 | AE26: 0 | AF26: 0 | AG26: 0 | AH26: 0 | AI26: 0 | AJ26: 0 | AK26: 0 | AL26: 0 | AM26: 0 | AN26: 0 | AO26: 0 | AP26: 0 | AQ26: 0 | AR26: 0 | AS26: 0 | AT26: 0 | AU26: 0 | AV26: 0 | AW26: 0 | AX26: 0 | AZ26: 0 | BA26: 0 | BB26: 0 | BC26: 0 | BD26: 0 | BE26: 0 | BF26: 0 | BI26: 0 | BJ26: 0 | BK26: 0
C27: =C26+1 -> 13 | D27: Selassi II | E27: Trent XWB-84 | F27: Ethiopia | G27: MEA | H27: Credit Back Removal | I27: TCA Amendments | J27: Campaign | K27: 1 | N27: 0.49 | O27: Med | P27: Med | Q27: Hopper | S27: 4.44 | T27: 0 | U27: 1.48 | V27: =SUM(T27+U27) -> 1.48 | Y27: 0 | Z27: 0 | AA27: 0 | AB27: 0 | AC27: 0 | AD27: 0 | AE27: 0 | AF27: 0 | AG27: 0 | AH27: 0 | AI27: 0 | AJ27: 0 | AK27: 0 | AL27: 0 | AM27: 0 | AN27: 0 | AO27: 0 | AP27: 0 | AQ27: 0 | AR27: 0 | AS27: 0 | AT27: 0 | AU27: 0 | AV27: 0 | AW27: 0 | AX27: 0 | AZ27: 0 | BA27: 0 | BB27: 0 | BC27: 0 | BD27: 0 | BE27: 0 | BF27: 0 | BI27: 0 | BJ27: 0 | BK27: 0
C28: =C27+1 -> 14 | D28: Burgundy | E28: Trent XWB-97 | F28: Qatar | G28: MEA | H28: SPE Pull-forward | I28: TCA Amendments | J28: Increased SPE Discount | K28: 1 | L28: yes | N28: 0.87 | O28: High | P28: Low | Q28: Completed | S28: 90 | T28: 0 | U28: 0 | V28: =SUM(T28+U28) -> 0 | Y28: 0 | Z28: 0 | AA28: 0 | AB28: 0 | AC28: 0 | AD28: 0 | AE28: 0 | AF28: 0 | AG28: 0 | AH28: 0 | AI28: 0 | AJ28: 0 | AK28: 0 | AL28: 0 | AM28: 0 | AN28: 0 | AO28: 0 | AP28: 0 | AQ28: 0 | AR28: 0 | AS28: 0 | AT28: 0 | AU28: 0 | AV28: 0 | AW28: 0 | AX28: 0 | AZ28: 0 | BA28: 0 | BB28: 0 | BC28: 0 | BD28: 0 | BE28: 0 | BF28: 0 | BI28: 0 | BJ28: 0 | BK28: 0
C29: =C28+1 -> 15 | D29: Burgundy II | E29: Trent XWB-84 | F29: Qatar | G29: MEA | H29: Exit for convenience removal -84 | I29: TCA Amendments | J29: Term Extension | K29: 1 | N29: 0.77 | O29: High | P29: High | Q29: Contracting | S29: 68.08 | T29: 68.08 | U29: 0 | V29: =SUM(T29+U29) -> 68.08 | Y29: 0 | Z29: 0 | AA29: 0 | AB29: 0 | AC29: 0 | AD29: 0 | AE29: 0 | AF29: 0 | AG29: 0 | AH29: 0 | AI29: 0 | AJ29: 0 | AK29: 0 | AL29: 0 | AM29: 0 | AN29: 0 | AO29: 0 | AP29: 0 | AQ29: 0 | AR29: 0 | AS29: 0 | AT29: 0 | AU29: 0 | AV29: 0 | AW29: 0 | AX29: 0 | AZ29: 0 | BA29: 0 | BB29: 0 | BC29: 0 | BD29: 0 | BE29: 0 | BF29: 0 | BI29: 0 | BJ29: 0 | BK29: 0 | BO29: 1 | BP29: 1 | BQ29: 1 | BR29: 1 | BS29: 1 | BT29: 1 | BU29: 1 | BV29: 1 | BW29: 1 | BX29: 1 | BY29: 1 | BZ29: 1 | CA29: 1 | CB29: 1 | CC29: 1 | CD29: 1 | CE29: 1
C30: =C29+1 -> 16 | D30: Burgundy III | E30: Trent XWB-97 | F30: Qatar | G30: MEA | H30: Exit for convenience removal -97 | I30: TCA Amendments | J30: Term Extension | K30: 2 | N30: 0.87 | O30: Low | P30: High | Q30: Hopper | S30: 45.88 | T30: 0 | U30: 45.88 | V30: =SUM(T30+U30) -> 45.88 | Y30: 0 | Z30: 0 | AA30: 0 | AB30: 0 | AC30: 0 | AD30: 0 | AE30: 0 | AF30: 0 | AG30: 0 | AH30: 0 | AI30: 0 | AJ30: 0 | AK30: 0 | AL30: 0 | AM30: 0 | AN30: 0 | AO30: 0 | AP30: 0 | AQ30: 0 | AR30: 0 | AS30: 0 | AT30: 0 | AU30: 0 | AV30: 0 | AW30: 0 | AX30: 0 | AZ30: 0 | BA30: 0 | BB30: 0 | BC30: 0 | BD30: 0 | BE30: 0 | BF30: 0 | BI30: 0 | BJ30: 0 | BK30: 0
C31: =C30+1 -> 17 | D31: QA | E31: Trent 500 | F31: Qatar Amiri | G31: MEA | H31: Sell 1 x SPE | I31: SPE increase | J31: Upsell | K31: 1 | L31: yes | M31: 1 | N31: 0 | O31: Med | P31: Med | Q31: Contracting | S31: 7.5 | T31: 5 | U31: 0 | V31: =SUM(T31+U31) -> 5 | Y31: 0 | Z31: 0 | AA31: 0 | AB31: 0 | AC31: 0 | AD31: 0 | AE31: 0 | AF31: 0 | AG31: 0 | AH31: 0 | AI31: 0 | AJ31: 0 | AK31: 0 | AL31: 0 | AM31: 0 | AN31: 0 | AO31: 0 | AP31: 0 | AQ31: 0 | AR31: 0 | AS31: 0 | AT31: 0 | AU31: 0 | AV31: 0 | AW31: 0 | AX31: 0 | AZ31: 0 | BA31: 0 | BB31: 0 | BC31: 0 | BD31: 0 | BE31: 0 | BF31: 0 | BI31: 0 | BJ31: 0 | BK31: 0
C32: =C31+1 -> 18 | D32: Horus | E32: Trent 1000 | F32: Egypt | G32: MEA | H32: Correct the CRP!! | I32: TCA Amendments | J32: Min Term extension | K32: 2 | N32: 0.18 | O32: Med | P32: Low | Q32: ICT | T32: 0 | U32: 0 | V32: =SUM(T32+U32) -> 0 | Y32: 0 | Z32: 0 | AA32: 0 | AB32: 0 | AC32: 0 | AD32: 0 | AE32: 0 | AF32: 0 | AG32: 0 | AH32: 0 | AI32: 0 | AJ32: 0 | AK32: 0 | AL32: 0 | AM32: 0 | AN32: 0 | AO32: 0 | AP32: 0 | AQ32: 0 | AR32: 0 | AS32: 0 | AT32: 0 | AU32: 0 | AV32: 0 | AW32: 0 | AX32: 0 | AZ32: 0 | BA32: 0 | BB32: 0 | BC32: 0 | BD32: 0 | BE32: 0 | BF32: 0 | BI32: 0 | BJ32: 0 | BK32: 0
C33: =C32+1 -> 19 | D33: Horus II | E33: Trent 700 | F33: Egypt | G33: MEA | H33: Term Extension | I33: Term Extension | J33: Existing Pricing | K33: 1 | N33: 0.11 | O33: High | P33: Med | Q33: ICT | S33: 120 | T33: 3 | U33: 14 | V33: =SUM(T33+U33) -> 17 | Y33: 0 | Z33: 0 | AA33: 0 | AB33: 0 | AC33: 0 | AD33: 0 | AE33: 0 | AF33: 0 | AG33: 0 | AH33: 0 | AI33: 0 | AJ33: 0 | AK33: 0 | AL33: 0 | AM33: 0 | AN33: 0 | AO33: 0 | AP33: 0 | AQ33: 0 | AR33: 0 | AS33: 0 | AT33: 0 | AU33: 0 | AV33: 0 | AW33: 0 | AX33: 0 | AZ33: 0 | BA33: 0 | BB33: 0 | BC33: 0 | BD33: 0 | BE33: 0 | BF33: 0 | BI33: 0 | BJ33: 0 | BK33: 0
C34: =C33+1 -> 20 | D34: Horus III | E34: Trent 1000 | F34: Egypt | G34: MEA | H34: Transportation Service Buy Out | I34: TCA Amendments | K34: 2 | N34: 0.18 | O34: Low | P34: Med | Q34: Cancelled | S34: 138.24 | T34: 0 | U34: 20 | V34: =SUM(T34+U34) -> 20 | Y34: 0 | Z34: 0 | AA34: 0 | AB34: 0 | AC34: 0 | AD34: 0 | AE34: 0 | AF34: 0 | AG34: 0 | AH34: 0 | AI34: 0 | AJ34: 0 | AK34: 0 | AL34: 0 | AM34: 0 | AN34: 0 | AO34: 0 | AP34: 0 | AQ34: 0 | AR34: 0 | AS34: 0 | AT34: 0 | AU34: 0 | AV34: 0 | AW34: 0 | AX34: 0 | AZ34: 0 | BA34: 0 | BB34: 0 | BC34: 0 | BD34: 0 | BE34: 0 | BF34: 0 | BI34: 0 | BJ34: 0 | BK34: 0
C35: =C34+1 -> 21 | D35: Horus IV | E35: Trent XWB-84 | F35: Egypt | G35: MEA | H35: PAS Upsell | I35: Service Upsells | K35: 1 | O35: Low | P35: Low | Q35: Cancelled | S35: 7.2 | T35: 0.6 | U35: 0.6 | V35: =SUM(T35+U35) -> 1.2 | Y35: 0 | Z35: 0 | AA35: 0 | AB35: 0 | AC35: 0 | AD35: 0 | AE35: 0 | AF35: 0 | AG35: 0 | AH35: 0 | AI35: 0 | AJ35: 0 | AK35: 0 | AL35: 0 | AM35: 0 | AN35: 0 | AO35: 0 | AP35: 0 | AQ35: 0 | AR35: 0 | AS35: 0 | AT35: 0 | AU35: 0 | AV35: 0 | AW35: 0 | AX35: 0 | AZ35: 0 | BA35: 0 | BB35: 0 | BC35: 0 | BD35: 0 | BE35: 0 | BF35: 0 | BI35: 0 | BJ35: 0 | BK35: 0
C36: =C35+1 -> 22 | D36: Turk | E36: Trent 700 | F36: Turkmenistan | G36: MEA | H36: SelectCare Upsell | I36: Service Upsells | K36: 2 | O36: Low | P36: Med | Q36: Cancelled | S36: 30 | T36: 0 | U36: 7.5 | V36: =SUM(T36+U36) -> 7.5 | Y36: 0 | Z36: 0 | AA36: 0 | AB36: 0 | AC36: 0 | AD36: 0 | AE36: 0 | AF36: 0 | AG36: 0 | AH36: 0 | AI36: 0 | AJ36: 0 | AK36: 0 | AL36: 0 | AM36: 0 | AN36: 0 | AO36: 0 | AP36: 0 | AQ36: 0 | AR36: 0 | AS36: 0 | AT36: 0 | AU36: 0 | AV36: 0 | AW36: 0 | AX36: 0 | AZ36: 0 | BA36: 0 | BB36: 0 | BC36: 0 | BD36: 0 | BE36: 0 | BF36: 0 | BI36: 0 | BJ36: 0 | BK36: 0
C37: =C36+1 -> 23 | D37: Qanot | E37: Trent 700 | F37: Qanot Sharq | G37: MEA | H37: TCA Life Upsell 2 x A330CEO | I37: New a/c | K37: 2 | O37: Low | P37: Med | Q37: Cancelled | S37: 36 | T37: 0 | U37: 0 | V37: =SUM(T37+U37) -> 0 | Y37: 0 | Z37: 0 | AA37: 0 | AB37: 0 | AC37: 0 | AD37: 0 | AE37: 0 | AF37: 0 | AG37: 0 | AH37: 0 | AI37: 0 | AJ37: 0 | AK37: 0 | AL37: 0 | AM37: 0 | AN37: 0 | AO37: 0 | AP37: 0 | AQ37: 0 | AR37: 0 | AS37: 0 | AT37: 0 | AU37: 0 | AV37: 0 | AW37: 0 | AX37: 0 | AZ37: 0 | BA37: 0 | BB37: 0 | BC37: 0 | BD37: 0 | BE37: 0 | BF37: 0 | BI37: 0 | BJ37: 0 | BK37: 0
C38: =C37+1 -> 24 | D38: SW | E38: RB211-524 | F38: Silkway | G38: MEA | H38: Increase in Green Time by 12k cycles | I38: TCA Amendments | K38: 1 | N38: 0 | O38: Low | P38: High | Q38: Cancelled | S38: 25.2 | T38: 12.6 | U38: 12.6 | V38: =SUM(T38+U38) -> 25.2 | Y38: 0 | Z38: 0 | AA38: 0 | AB38: 0 | AC38: 0 | AD38: 0 | AE38: 0 | AF38: 0 | AG38: 0 | AH38: 0 | AI38: 0 | AJ38: 0 | AK38: 0 | AL38: 0 | AM38: 0 | AN38: 0 | AO38: 0 | AP38: 0 | AQ38: 0 | AR38: 0 | AS38: 0 | AT38: 0 | AU38: 0 | AV38: 0 | AW38: 0 | AX38: 0 | AZ38: 0 | BA38: 0 | BB38: 0 | BC38: 0 | BD38: 0 | BE38: 0 | BF38: 0 | BI38: 0 | BJ38: 0 | BK38: 0 | BO38: 1 | BP38: 1 | BQ38: 1 | BR38: 1 | BS38: 1 | BT38: 1 | BU38: 1 | BV38: 1 | BW38: 1 | BX38: 1 | BY38: 1 | BZ38: 1 | CA38: 1 | CB38: 1 | CC38: 1 | CD38: 1 | CE38: 1
C39: =C38+1 -> 25 | D39: Sen | E39: Trent 7000 | F39: Senegal | G39: MEA | H39: Collect debt | I39: Other | K39: 2 | N39: 0.54 | O39: Low | P39: Med | Q39: Cancelled | S39: 10 | T39: 0 | U39: 10 | V39: =SUM(T39+U39) -> 10 | Y39: 0 | Z39: 0 | AA39: 0 | AB39: 0 | AC39: 0 | AD39: 0 | AE39: 0 | AF39: 0 | AG39: 0 | AH39: 0 | AI39: 0 | AJ39: 0 | AK39: 0 | AL39: 0 | AM39: 0 | AN39: 0 | AO39: 0 | AP39: 0 | AQ39: 0 | AR39: 0 | AS39: 0 | AT39: 0 | AU39: 0 | AV39: 0 | AW39: 0 | AX39: 0 | AZ39: 0 | BA39: 0 | BB39: 0 | BC39: 0 | BD39: 0 | BE39: 0 | BF39: 0 | BI39: 0 | BJ39: 0 | BK39: 0
C40: =C39+1 -> 26 | D40: Viva Algeria | E40: Trent 7000 | F40: Air Algerie | G40: MEA | H40: Additional SPE | I40: SPE increase | K40: 1 | L40: yes | O40: High | P40: Low | Q40: Completed | S40: 20 | T40: 0 | U40: 20 | V40: =SUM(T40+U40) -> 20 | Y40: 0 | Z40: 0 | AA40: 0 | AB40: 0 | AC40: 0 | AD40: 0 | AE40: 0 | AF40: 0 | AG40: 0 | AH40: 0 | AI40: 0 | AJ40: 0 | AK40: 0 | AL40: 0 | AM40: 0 | AN40: 0 | AO40: 0 | AP40: 0 | AQ40: 0 | AR40: 0 | AS40: 0 | AT40: 0 | AU40: 0 | AV40: 0 | AW40: 0 | AX40: 0 | AZ40: 0 | BA40: 0 | BB40: 0 | BC40: 0 | BD40: 0 | BE40: 0 | BF40: 0 | BI40: 0 | BJ40: 0 | BK40: 0
C41: =C40+1 -> 27 | D41: Dhabi I | E41: Trent XWB-97 | F41: Etihad | G41: MEA | H41: TCA Reconciliation (CRP Improvement) | I41: TCA Amendments | K41: 1 | N41: 0.09 | O41: High | P41: Med | Q41: Completed | S41: 60 | T41: 5 | U41: 1 | V41: =SUM(T41+U41) -> 6 | Y41: 0 | Z41: 0 | AA41: 0 | AB41: 0 | AC41: 0 | AD41: 0 | AE41: 0 | AF41: 0 | AG41: 0 | AH41: 0 | AI41: 0 | AJ41: 0 | AK41: 0 | AL41: 0 | AM41: 0 | AN41: 0 | AO41: 0 | AP41: 0 | AQ41: 0 | AR41: 0 | AS41: 0 | AT41: 0 | AU41: 0 | AV41: 0 | AW41: 0 | AX41: 0 | AZ41: 0 | BA41: 0 | BB41: 0 | BC41: 0 | BD41: 0 | BE41: 0 | BF41: 0 | BI41: 0 | BJ41: 0 | BK41: 0
C42: =C41+1 -> 28 | D42: Dhabi II | E42: Trent XWB-97 | F42: Etihad | G42: MEA | H42: Transportation Service Buy Out for first 12 | I42: TCA Amendments | K42: 3 | N42: 0.09 | O42: Low | P42: High | Q42: Hopper | S42: 17.76 | T42: 0 | U42: 1.48 | V42: =SUM(T42+U42) -> 1.48 | Y42: 0 | Z42: 0 | AA42: 0 | AB42: 0 | AC42: 0 | AD42: 0 | AE42: 0 | AF42: 0 | AG42: 0 | AH42: 0 | AI42: 0 | AJ42: 0 | AK42: 0 | AL42: 0 | AM42: 0 | AN42: 0 | AO42: 0 | AP42: 0 | AQ42: 0 | AR42: 0 | AS42: 0 | AT42: 0 | AU42: 0 | AV42: 0 | AW42: 0 | AX42: 0 | AZ42: 0 | BA42: 0 | BB42: 0 | BC42: 0 | BD42: 0 | BE42: 0 | BF42: 0 | BI42: 0 | BJ42: 0 | BK42: 0
C43: =C42+1 -> 29 | D43: Saud | E43: Trent 700 | F43: Saudia | G43: MEA | H43: Regional Fleet NDSES improvement | I43: Cost Reduction | K43: 1 | N43: 0.31 | O43: High | P43: Med | Q43: Completed | T43: 0 | U43: 0 | V43: =SUM(T43+U43) -> 0 | Y43: 0 | Z43: 0 | AA43: 0 | AB43: 0 | AC43: 0 | AD43: 0 | AE43: 0 | AF43: 0 | AG43: 0 | AH43: 0 | AI43: 0 | AJ43: 0 | AK43: 0 | AL43: 0 | AM43: 0 | AN43: 0 | AO43: 0 | AP43: 0 | AQ43: 0 | AR43: 0 | AS43: 0 | AT43: 0 | AU43: 0 | AV43: 0 | AW43: 0 | AX43: 0 | AZ43: 0 | BA43: 0 | BB43: 0 | BC43: 0 | BD43: 0 | BE43: 0 | BF43: 0 | BI43: 0 | BJ43: 0 | BK43: 0
C44: =C43+1 -> 30 | D44: Saud II | E44: Trent 700 | F44: Saudia | G44: MEA | H44: Extend Classic | I44: Term Extension | J44: Term Extension | K44: 2 | N44: 0.29 | O44: Low | P44: Med | Q44: Hopper | S44: 21.46 | T44: 0 | U44: 0 | V44: =SUM(T44+U44) -> 0 | Y44: 0 | Z44: 0 | AA44: 0 | AB44: 0 | AC44: 0 | AD44: 0 | AE44: 0 | AF44: 0 | AG44: 0 | AH44: 0 | AI44: 0 | AJ44: 0 | AK44: 0 | AL44: 0 | AM44: 0 | AN44: 0 | AO44: 0 | AP44: 0 | AQ44: 0 | AR44: 0 | AS44: 0 | AT44: 0 | AU44: 0 | AV44: 0 | AW44: 0 | AX44: 0 | AZ44: 0 | BA44: 0 | BB44: 0 | BC44: 0 | BD44: 0 | BE44: 0 | BF44: 0 | BI44: 0 | BJ44: 0 | BK44: 0
...

Sheet L3
C3: OPP LOG SHEET | V3: Hopper | Z3: FINANCIAL CRITERIA | BO3: RESOURCE PRIORITIZATION
V5: ICT Estimates
S6: 45861
V7: Contract
C8: AWAY DAY DATE | E8: 45768
BO9: High Priority | BP9: Med Priority | BQ9: Low Priority | BR9: Not Required
Q10: Contracting Actuals | BO10: 3 | BP10: 2 | BQ10: 1
Q12: SUMS: | S12: =SUM(S15:S99) -> 1536.232 | T12: =SUM(T15:T99) -> 159.04607 | U12: =SUM(U15:U99) -> 183.99273 | V12: =SUM(V15:V99) -> 343.0388 | Z12: Existing Deal | AM12: New Deal | AZ12: Supporting Financial Information | BI12: To Go | BO12: Priority
M13: =SUM($N$15:$N$513) -> 10.73 | N13: =SUM($O$15:$O$513) -> 0 | Z13: Cash Reciepts | AF13: In Year Profit | AM13: Cash Reciepts | AS13: In Year Profit
C14: # | D14: Project | E14: Programme | F14: Customer | G14: Region | H14: Asks | I14: Type of Opportunity | J14: Levers | K14: Priority | L14: SPE related | M14: No,of SPE | N14: CRP% | O14: External Probability | P14: Internal Complexity | Q14: Status | R14: Evaluation Level | S14: Term Benefit | T14: 2026 | U14: 2027 | V14: Sum of 26/27 | Z14: 2025 | AA14: 2026 | AB14: 2027 | AC14: 2028 | AD14: 2029 | AE14: 2030 | AF14: 2025 | AG14: 2026 | AH14: 2027 | AI14: 2028 | AJ14: 2029 | AK14: 2030 | AM14: 2025 | AN14: 2026 | AO14: 2027 | AP14: 2028 | AQ14: 2029 | AR14: 2030 | AS14: 2025 | AT14: 2026 | AU14: 2027 | AV14: 2028 | AW14: 2029 | AX14: 2030 | AZ14: Deal Benefits | BA14: Expected Deal Costs | BB14: In-year Profit Impact | BC14: 5YP Profit Improvement | BD14: Term Profit Imprvement | BE14: Total CRP Term Revnue | BF14: Total CRP Term Margin | BG14: CRP Margin % | BI14: Term Revenue | BJ14: Term Cost | BK14: Term Profit | BO14: Account Management | BP14: Contract Management | BQ14: Service Business | BR14: Business Evalautaion | BS14: Sales & Contracting | BT14: Customer Operations
C15: 1 | D15: {=IF('MEA LOG'!D15:Q100="","",'MEA LOG'!D15:Q100)} -> FiniQ II | E15: Trent XWB-84 | F15: Emirates | G15: MEA | H15: 3 year-extension + LRU Management + 23 a/c | I15: TCA Amendments | J15: XWB MRO - OWS Support - 97k & EP Pricing | K15: 1 | N15: 0 | O15: High | P15: Low | Q15: Completed | S15: =231*1.48 -> 341.88 | V15: =SUM(T15+U15) -> 0 | Y15: 0 | Z15: 0 | AA15: 0 | AB15: 0 | AC15: 0 | AD15: 0 | AE15: 0 | AF15: 0 | AG15: 0 | AH15: 0 | AI15: 0 | AJ15: 0 | AK15: 0 | AL15: 0 | AM15: 0 | AN15: 0 | AO15: 0 | AP15: 0 | AQ15: 0 | AR15: 0 | AS15: 0 | AT15: 0 | AU15: 0 | AV15: 0 | AW15: 0 | AX15: 0 | AZ15: 0 | BA15: 0 | BB15: 0 | BC15: 0 | BD15: 0 | BE15: 0 | BF15: 0 | BI15: 0 | BJ15: 0 | BK15: 0 | BO15: 1 | BP15: 1 | BQ15: 1 | BR15: 1 | BS15: 1 | BT15: 1 | BU15: 1 | BV15: 1 | BW15: 1 | BX15: 1 | BY15: 1 | BZ15: 1 | CA15: 1 | CB15: 1 | CC15: 1 | CD15: 1 | CE15: 1
C16: =C15+1 -> 2 | D16: FiniQ III | E16: Trent XWB-84 | F16: Emirates | G16: MEA | H16: OWS - eliminate $20k remedy | I16: Cost Reduction | J16: New Campaign | K16: 1 | N16: 0 | O16: High | P16: Low | Q16: Contracting | S16: 54 | T16: 20.8 | U16: 20.8 | V16: =SUM(T16+U16) -> 41.6 | Y16: 0 | Z16: 0 | AA16: 0 | AB16: 0 | AC16: 0 | AD16: 0 | AE16: 0 | AF16: 0 | AG16: 0 | AH16: 0 | AI16: 0 | AJ16: 0 | AK16: 0 | AL16: 0 | AM16: 0 | AN16: 0 | AO16: 0 | AP16: 0 | AQ16: 0 | AR16: 0 | AS16: 0 | AT16: 0 | AU16: 0 | AV16: 0 | AW16: 0 | AX16: 0 | AZ16: 0 | BA16: 0 | BB16: 0 | BC16: 0 | BD16: 0 | BE16: 0 | BF16: 0 | BI16: 0 | BJ16: 0 | BK16: 0 | BO16: 1 | BP16: 1 | BQ16: 1 | BR16: 1 | BS16: 1 | BT16: 1 | BU16: 1 | BV16: 1 | BW16: 1 | BX16: 1 | BY16: 1 | BZ16: 1 | CA16: 1 | CB16: 1 | CC16: 1 | CD16: 1 | CE16: 1
C17: =C16+1 -> 3 | D17: IDK | E17: Trent XWB-84 | F17: Emirates | G17: MEA | H17: Additional 3 x SPE (10 %to 12%) | I17: SPE increase | J17: New Campaign | K17: 2 | L17: yes | M17: 3 | N17: 0 | O17: Low | P17: Med | Q17: Hopper | S17: 50 | V17: =SUM(T17+U17) -> 0 | Y17: 0 | Z17: 0 | AA17: 0 | AB17: 0 | AC17: 0 | AD17: 0 | AE17: 0 | AF17: 0 | AG17: 0 | AH17: 0 | AI17: 0 | AJ17: 0 | AK17: 0 | AL17: 0 | AM17: 0 | AN17: 0 | AO17: 0 | AP17: 0 | AQ17: 0 | AR17: 0 | AS17: 0 | AT17: 0 | AU17: 0 | AV17: 0 | AW17: 0 | AX17: 0 | AZ17: 0 | BA17: 0 | BB17: 0 | BC17: 0 | BD17: 0 | BE17: 0 | BF17: 0 | BI17: 0 | BJ17: 0 | BK17: 0 | BO17: 1 | BP17: 1 | BQ17: 1 | BR17: 1 | BS17: 1 | BT17: 1 | BU17: 1 | BV17: 1 | BW17: 1 | BX17: 1 | BY17: 1 | BZ17: 1 | CA17: 1 | CB17: 1 | CC17: 1 | CD17: 1 | CE17: 1
C18: =C17+1 -> 4 | D18: IDK | E18: Trent XWB-84 | F18: Emirates | G18: MEA | H18: Eliminate NDSES Cost via DAT | I18: Cost Reduction | J18: New Campaign/Settlement | K18: 2 | N18: 0 | O18: Med | P18: Med | Q18: ICT | S18: 11.4 | V18: =SUM(T18+U18) -> 0 | Y18: 0 | Z18: 0 | AA18: 0 | AB18: 0 | AC18: 0 | AD18: 0 | AE18: 0 | AF18: 0 | AG18: 0 | AH18: 0 | AI18: 0 | AJ18: 0 | AK18: 0 | AL18: 0 | AM18: 0 | AN18: 0 | AO18: 0 | AP18: 0 | AQ18: 0 | AR18: 0 | AS18: 0 | AT18: 0 | AU18: 0 | AV18: 0 | AW18: 0 | AX18: 0 | AZ18: 0 | BA18: 0 | BB18: 0 | BC18: 0 | BD18: 0 | BE18: 0 | BF18: 0 | BI18: 0 | BJ18: 0 | BK18: 0 | BO18: 1 | BP18: 1 | BQ18: 1 | BR18: 1 | BS18: 1 | BT18: 1 | BU18: 1 | BV18: 1 | BW18: 1 | BX18: 1 | BY18: 1 | BZ18: 1 | CA18: 1 | CB18: 1 | CC18: 1 | CD18: 1 | CE18: 1
C19: =C18+1 -> 5 | D19: IDK | E19: Trent XWB-84 | F19: Emirates | G19: MEA | H19: Increase in escalation from 2% to 3% | I19: TCA Amendments | J19: XWB MRO - OWS Support - 97k & EP Pricing | K19: 2 | N19: 0 | O19: Low | P19: Low | Q19: Hopper | S19: 170 | V19: =SUM(T19+U19) -> 0 | Y19: 0 | Z19: 0 | AA19: 0 | AB19: 0 | AC19: 0 | AD19: 0 | AE19: 0 | AF19: 0 | AG19: 0 | AH19: 0 | AI19: 0 | AJ19: 0 | AK19: 0 | AL19: 0 | AM19: 0 | AN19: 0 | AO19: 0 | AP19: 0 | AQ19: 0 | AR19: 0 | AS19: 0 | AT19: 0 | AU19: 0 | AV19: 0 | AW19: 0 | AX19: 0 | AZ19: 0 | BA19: 0 | BB19: 0 | BC19: 0 | BD19: 0 | BE19: 0 | BF19: 0 | BI19: 0 | BJ19: 0 | BK19: 0 | BO19: 1 | BP19: 1 | BQ19: 1 | BR19: 1 | BS19: 1 | BT19: 1 | BU19: 1 | BV19: 1 | BW19: 1 | BX19: 1 | BY19: 1 | BZ19: 1 | CA19: 1 | CB19: 1 | CC19: 1 | CD19: 1 | CE19: 1
C20: =C19+1 -> 6 | D20: IDK | E20: Trent XWB-84 | F20: Emirates | G20: MEA | H20: Introduce Precedent Matrix | I20: TCA Amendments | J20: XWB MRO - OWS Support - 97k & EP Pricing | K20: 2 | N20: 0 | O20: Low | P20: Med | Q20: Hopper | S20: 50 | V20: =SUM(T20+U20) -> 0 | Y20: 0 | Z20: 0 | AA20: 0 | AB20: 0 | AC20: 0 | AD20: 0 | AE20: 0 | AF20: 0 | AG20: 0 | AH20: 0 | AI20: 0 | AJ20: 0 | AK20: 0 | AL20: 0 | AM20: 0 | AN20: 0 | AO20: 0 | AP20: 0 | AQ20: 0 | AR20: 0 | AS20: 0 | AT20: 0 | AU20: 0 | AV20: 0 | AW20: 0 | AX20: 0 | AZ20: 0 | BA20: 0 | BB20: 0 | BC20: 0 | BD20: 0 | BE20: 0 | BF20: 0 | BI20: 0 | BJ20: 0 | BK20: 0 | BO20: 1 | BP20: 1 | BQ20: 1 | BR20: 1 | BS20: 1 | BT20: 1 | BU20: 1 | BV20: 1 | BW20: 1 | BX20: 1 | BY20: 1 | BZ20: 1 | CA20: 1 | CB20: 1 | CC20: 1 | CD20: 1 | CE20: 1
C21: =C20+1 -> 7 | D21: Selassi | E21: Trent XWB-84 | F21: Ethiopia | G21: MEA | H21: SPE Pull forward | I21: TCA Amendments | J21: AOG Risk | K21: 1 | L21: yes | M21: 1 | N21: 0.49 | O21: Low | P21: Low | Q21: Completed | S21: 10 | T21: 1 | U21: 1 | V21: =SUM(T21+U21) -> 2 | Y21: 0 | Z21: 0 | AA21: 0 | AB21: 0 | AC21: 0 | AD21: 0 | AE21: 0 | AF21: 0 | AG21: 0 | AH21: 0 | AI21: 0 | AJ21: 0 | AK21: 0 | AL21: 0 | AM21: 0 | AN21: 0 | AO21: 0 | AP21: 0 | AQ21: 0 | AR21: 0 | AS21: 0 | AT21: 0 | AU21: 0 | AV21: 0 | AW21: 0 | AX21: 0 | AZ21: 0 | BA21: 0 | BB21: 0 | BC21: 0 | BD21: 0 | BE21: 0 | BF21: 0 | BI21: 0 | BJ21: 0 | BK21: 0
C22: =C21+1 -> 8 | D22: Selassi | E22: Trent XWB-84 | F22: Ethiopia | G22: MEA | H22: Incremental SPE | I22: SPE increase | J22: 2 Addition a/c | K22: 1 | L22: yes | M22: 1 | N22: 0 | O22: High | P22: Low | Q22: Negotiations | S22: 0 | T22: 0 | U22: 0 | V22: 0 | Y22: 0 | Z22: 0 | AA22: 0 | AB22: 0 | AC22: 0 | AD22: 0 | AE22: 0 | AF22: 0 | AG22: 0 | AH22: 0 | AI22: 0 | AJ22: 0 | AK22: 0 | AL22: 0 | AM22: 0 | AN22: 0 | AO22: 0 | AP22: 0 | AQ22: 0 | AR22: 0 | AS22: 0 | AT22: 0 | AU22: 0 | AV22: 0 | AW22: 0 | AX22: 0 | AZ22: 0 | BA22: 0 | BB22: 0 | BC22: 0 | BD22: 0 | BE22: 0 | BF22: 0 | BI22: 0 | BJ22: 0 | BK22: 0
C23: =C22+1 -> 9 | D23: Selassi | E23: Trent 1000 | F23: Ethiopia | G23: MEA | H23: Incremental SPE | I23: SPE increase | J23: Campaign | K23: 1 | L23: yes | N23: 0.54 | O23: Med | P23: Low | Q23: Hopper | S23: 33 | T23: =S23/12 -> 2.75 | U23: =S23/12 -> 2.75 | V23: 5.5 | Y23: 0 | Z23: 0 | AA23: 0 | AB23: 0 | AC23: 0 | AD23: 0 | AE23: 0 | AF23: 0 | AG23: 0 | AH23: 0 | AI23: 0 | AJ23: 0 | AK23: 0 | AL23: 0 | AM23: 0 | AN23: 0 | AO23: 0 | AP23: 0 | AQ23: 0 | AR23: 0 | AS23: 0 | AT23: 0 | AU23: 0 | AV23: 0 | AW23: 0 | AX23: 0 | AZ23: 0 | BA23: 0 | BB23: 0 | BC23: 0 | BD23: 0 | BE23: 0 | BF23: 0 | BI23: 0 | BJ23: 0 | BK23: 0
C24: =C23+1 -> 10 | D24: Selassi | E24: Trent 1000 | F24: Ethiopia | G24: MEA | H24: Min Term Extension (life) | I24: Term Extension | J24: Campaign | K24: 1 | N24: 0.54 | O24: Med | P24: Med | Q24: Hopper | S24: 43 | T24: 5.92 | U24: 0 | V24: =SUM(T24+U24) -> 5.92 | Y24: 0 | Z24: 0 | AA24: 0 | AB24: 0 | AC24: 0 | AD24: 0 | AE24: 0 | AF24: 0 | AG24: 0 | AH24: 0 | AI24: 0 | AJ24: 0 | AK24: 0 | AL24: 0 | AM24: 0 | AN24: 0 | AO24: 0 | AP24: 0 | AQ24: 0 | AR24: 0 | AS24: 0 | AT24: 0 | AU24: 0 | AV24: 0 | AW24: 0 | AX24: 0 | AZ24: 0 | BA24: 0 | BB24: 0 | BC24: 0 | BD24: 0 | BE24: 0 | BF24: 0 | BI24: 0 | BJ24: 0 | BK24: 0
C25: =C24+1 -> 11 | D25: Selassi II | E25: Trent XWB-84 | F25: Ethiopia | G25: MEA | H25: Min Term Extension | I25: Term Extension | J25: Campaign | K25: 1 | N25: 0.49 | O25: Med | P25: Med | Q25: Hopper | S25: 30 | T25: 0 | U25: 30 | V25: =SUM(T25+U25) -> 30 | Y25: 0 | Z25: 0 | AA25: 0 | AB25: 0 | AC25: 0 | AD25: 0 | AE25: 0 | AF25: 0 | AG25: 0 | AH25: 0 | AI25: 0 | AJ25: 0 | AK25: 0 | AL25: 0 | AM25: 0 | AN25: 0 | AO25: 0 | AP25: 0 | AQ25: 0 | AR25: 0 | AS25: 0 | AT25: 0 | AU25: 0 | AV25: 0 | AW25: 0 | AX25: 0 | AZ25: 0 | BA25: 0 | BB25: 0 | BC25: 0 | BD25: 0 | BE25: 0 | BF25: 0 | BI25: 0 | BJ25: 0 | BK25: 0
C26: =C25+1 -> 12 | D26: Selassi II | E26: Trent XWB-84 | F26: Ethiopia | G26: MEA | H26: Increase escalation | I26: TCA Amendments | J26: Campaign | K26: 1 | N26: 0.49 | O26: Low | P26: Low | Q26: Hopper | S26: 11.84 | T26: 2.368 | U26: 2.368 | V26: =SUM(T26+U26) -> 4.736 | Y26: 0 | Z26: 0 | AA26: 0 | AB26: 0 | AC26: 0 | AD26: 0 | AE26: 0 | AF26: 0 | AG26: 0 | AH26: 0 | AI26: 0 | AJ26: 0 | AK26: 0 | AL26: 0 | AM26: 0 | AN26: 0 | AO26: 0 | AP26: 0 | AQ26: 0 | AR26: 0 | AS26: 0 | AT26: 0 | AU26: 0 | AV26: 0 | AW26: 0 | AX26: 0 | AZ26: 0 | BA26: 0 | BB26: 0 | BC26: 0 | BD26: 0 | BE26: 0 | BF26: 0 | BI26: 0 | BJ26: 0 | BK26: 0
C27: =C26+1 -> 13 | D27: Selassi II | E27: Trent XWB-84 | F27: Ethiopia | G27: MEA | H27: Credit Back Removal | I27: TCA Amendments | J27: Campaign | K27: 1 | N27: 0.49 | O27: Med | P27: Med | Q27: Hopper | S27: 4.44 | T27: 1.48 | U27: 1.48 | V27: =SUM(T27+U27) -> 2.96 | Y27: 0 | Z27: 0 | AA27: 0 | AB27: 0 | AC27: 0 | AD27: 0 | AE27: 0 | AF27: 0 | AG27: 0 | AH27: 0 | AI27: 0 | AJ27: 0 | AK27: 0 | AL27: 0 | AM27: 0 | AN27: 0 | AO27: 0 | AP27: 0 | AQ27: 0 | AR27: 0 | AS27: 0 | AT27: 0 | AU27: 0 | AV27: 0 | AW27: 0 | AX27: 0 | AZ27: 0 | BA27: 0 | BB27: 0 | BC27: 0 | BD27: 0 | BE27: 0 | BF27: 0 | BI27: 0 | BJ27: 0 | BK27: 0
C28: =C27+1 -> 14 | D28: Burgundy | E28: Trent XWB-97 | F28: Qatar | G28: MEA | H28: SPE Pull-forward | I28: TCA Amendments | J28: Increased SPE Discount | K28: 1 | L28: yes | N28: 0.87 | O28: High | P28: Low | Q28: Completed | S28: 90 | T28: 0 | U28: 0 | V28: =SUM(T28+U28) -> 0 | Y28: 0 | Z28: 0 | AA28: 0 | AB28: 0 | AC28: 0 | AD28: 0 | AE28: 0 | AF28: 0 | AG28: 0 | AH28: 0 | AI28: 0 | AJ28: 0 | AK28: 0 | AL28: 0 | AM28: 0 | AN28: 0 | AO28: 0 | AP28: 0 | AQ28: 0 | AR28: 0 | AS28: 0 | AT28: 0 | AU28: 0 | AV28: 0 | AW28: 0 | AX28: 0 | AZ28: 0 | BA28: 0 | BB28: 0 | BC28: 0 | BD28: 0 | BE28: 0 | BF28: 0 | BI28: 0 | BJ28: 0 | BK28: 0
C29: =C28+1 -> 15 | D29: Burgundy II | E29: Trent XWB-84 | F29: Qatar | G29: MEA | H29: Exit for convenience removal -84 | I29: TCA Amendments | J29: Term Extension | K29: 1 | N29: 0.77 | O29: High | P29: High | Q29: Contracting | S29: 68.08 | T29: 68.08 | U29: 0 | V29: =SUM(T29+U29) -> 68.08 | Y29: 0 | Z29: 0 | AA29: 0 | AB29: 0 | AC29: 0 | AD29: 0 | AE29: 0 | AF29: 0 | AG29: 0 | AH29: 0 | AI29: 0 | AJ29: 0 | AK29: 0 | AL29: 0 | AM29: 0 | AN29: 0 | AO29: 0 | AP29: 0 | AQ29: 0 | AR29: 0 | AS29: 0 | AT29: 0 | AU29: 0 | AV29: 0 | AW29: 0 | AX29: 0 | AZ29: 0 | BA29: 0 | BB29: 0 | BC29: 0 | BD29: 0 | BE29: 0 | BF29: 0 | BI29: 0 | BJ29: 0 | BK29: 0 | BO29: 1 | BP29: 1 | BQ29: 1 | BR29: 1 | BS29: 1 | BT29: 1 | BU29: 1 | BV29: 1 | BW29: 1 | BX29: 1 | BY29: 1 | BZ29: 1 | CA29: 1 | CB29: 1 | CC29: 1 | CD29: 1 | CE29: 1
C30: =C29+1 -> 16 | D30: Burgundy III | E30: Trent XWB-97 | F30: Qatar | G30: MEA | H30: Exit for convenience removal -97 | I30: TCA Amendments | J30: Term Extension | K30: 2 | N30: 0.87 | O30: Low | P30: High | Q30: Hopper | S30: 45.88 | T30: 0 | U30: 45.88 | V30: =SUM(T30+U30) -> 45.88 | Y30: 0 | Z30: 0 | AA30: 0 | AB30: 0 | AC30: 0 | AD30: 0 | AE30: 0 | AF30: 0 | AG30: 0 | AH30: 0 | AI30: 0 | AJ30: 0 | AK30: 0 | AL30: 0 | AM30: 0 | AN30: 0 | AO30: 0 | AP30: 0 | AQ30: 0 | AR30: 0 | AS30: 0 | AT30: 0 | AU30: 0 | AV30: 0 | AW30: 0 | AX30: 0 | AZ30: 0 | BA30: 0 | BB30: 0 | BC30: 0 | BD30: 0 | BE30: 0 | BF30: 0 | BI30: 0 | BJ30: 0 | BK30: 0
C31: =C30+1 -> 17 | D31: QA | E31: Trent 500 | F31: Qatar Amiri | G31: MEA | H31: Sell 1 x SPE | I31: SPE increase | J31: Upsell | K31: 1 | L31: yes | M31: 1 | N31: 0 | O31: Med | P31: Med | Q31: Contracting | S31: 7.5 | T31: 5 | U31: 0 | V31: =SUM(T31+U31) -> 5 | Y31: 0 | Z31: 0 | AA31: 0 | AB31: 0 | AC31: 0 | AD31: 0 | AE31: 0 | AF31: 0 | AG31: 0 | AH31: 0 | AI31: 0 | AJ31: 0 | AK31: 0 | AL31: 0 | AM31: 0 | AN31: 0 | AO31: 0 | AP31: 0 | AQ31: 0 | AR31: 0 | AS31: 0 | AT31: 0 | AU31: 0 | AV31: 0 | AW31: 0 | AX31: 0 | AZ31: 0 | BA31: 0 | BB31: 0 | BC31: 0 | BD31: 0 | BE31: 0 | BF31: 0 | BI31: 0 | BJ31: 0 | BK31: 0
C32: =C31+1 -> 18 | D32: Horus | E32: Trent 1000 | F32: Egypt | G32: MEA | H32: Correct the CRP!! | I32: TCA Amendments | J32: Min Term extension | K32: 2 | N32: 0.18 | O32: Med | P32: Low | Q32: ICT | S32: 0 | T32: 0 | U32: 0 | V32: =SUM(T32+U32) -> 0 | Y32: 0 | Z32: 0 | AA32: 0 | AB32: 0 | AC32: 0 | AD32: 0 | AE32: 0 | AF32: 0 | AG32: 0 | AH32: 0 | AI32: 0 | AJ32: 0 | AK32: 0 | AL32: 0 | AM32: 0 | AN32: 0 | AO32: 0 | AP32: 0 | AQ32: 0 | AR32: 0 | AS32: 0 | AT32: 0 | AU32: 0 | AV32: 0 | AW32: 0 | AX32: 0 | AZ32: 0 | BA32: 0 | BB32: 0 | BC32: 0 | BD32: 0 | BE32: 0 | BF32: 0 | BI32: 0 | BJ32: 0 | BK32: 0
C33: =C32+1 -> 19 | D33: Horus II | E33: Trent 700 | F33: Egypt | G33: MEA | H33: Term Extension | I33: Term Extension | J33: Existing Pricing | K33: 1 | N33: 0.11 | O33: High | P33: Med | Q33: ICT | S33: 7.4 | T33: 0 | U33: 0 | V33: =SUM(T33+U33) -> 0 | Y33: 0 | Z33: 0 | AA33: 0 | AB33: 0 | AC33: 0 | AD33: 0 | AE33: 0 | AF33: 0 | AG33: 0 | AH33: 0 | AI33: 0 | AJ33: 0 | AK33: 0 | AL33: 0 | AM33: 0 | AN33: 0 | AO33: 0 | AP33: 0 | AQ33: 0 | AR33: 0 | AS33: 0 | AT33: 0 | AU33: 0 | AV33: 0 | AW33: 0 | AX33: 0 | AZ33: 0 | BA33: 0 | BB33: 0 | BC33: 0 | BD33: 0 | BE33: 0 | BF33: 0 | BI33: 0 | BJ33: 0 | BK33: 0
C34: =C33+1 -> 20 | D34: Horus III | E34: Trent 1000 | F34: Egypt | G34: MEA | H34: Transportation Service Buy Out | I34: TCA Amendments | K34: 2 | N34: 0.18 | O34: Low | P34: Med | Q34: Cancelled | S34: 138.24 | T34: 0 | U34: 20 | V34: =SUM(T34+U34) -> 20 | Y34: 0 | Z34: 0 | AA34: 0 | AB34: 0 | AC34: 0 | AD34: 0 | AE34: 0 | AF34: 0 | AG34: 0 | AH34: 0 | AI34: 0 | AJ34: 0 | AK34: 0 | AL34: 0 | AM34: 0 | AN34: 0 | AO34: 0 | AP34: 0 | AQ34: 0 | AR34: 0 | AS34: 0 | AT34: 0 | AU34: 0 | AV34: 0 | AW34: 0 | AX34: 0 | AZ34: 0 | BA34: 0 | BB34: 0 | BC34: 0 | BD34: 0 | BE34: 0 | BF34: 0 | BI34: 0 | BJ34: 0 | BK34: 0
C35: =C34+1 -> 21 | D35: Horus IV | E35: Trent XWB-84 | F35: Egypt | G35: MEA | H35: PAS Upsell | I35: Service Upsells | K35: 1 | O35: Low | P35: Low | Q35: Cancelled | S35: 7.2 | T35: 0.6 | U35: 0.6 | V35: =SUM(T35+U35) -> 1.2 | Y35: 0 | Z35: 0 | AA35: 0 | AB35: 0 | AC35: 0 | AD35: 0 | AE35: 0 | AF35: 0 | AG35: 0 | AH35: 0 | AI35: 0 | AJ35: 0 | AK35: 0 | AL35: 0 | AM35: 0 | AN35: 0 | AO35: 0 | AP35: 0 | AQ35: 0 | AR35: 0 | AS35: 0 | AT35: 0 | AU35: 0 | AV35: 0 | AW35: 0 | AX35: 0 | AZ35: 0 | BA35: 0 | BB35: 0 | BC35: 0 | BD35: 0 | BE35: 0 | BF35: 0 | BI35: 0 | BJ35: 0 | BK35: 0
C36: =C35+1 -> 22 | D36: Turk | E36: Trent 700 | F36: Turkmenistan | G36: MEA | H36: SelectCare Upsell | I36: Service Upsells | K36: 2 | O36: Low | P36: Med | Q36: Cancelled | S36: 30 | T36: 0 | U36: 7.5 | V36: =SUM(T36+U36) -> 7.5 | Y36: 0 | Z36: 0 | AA36: 0 | AB36: 0 | AC36: 0 | AD36: 0 | AE36: 0 | AF36: 0 | AG36: 0 | AH36: 0 | AI36: 0 | AJ36: 0 | AK36: 0 | AL36: 0 | AM36: 0 | AN36: 0 | AO36: 0 | AP36: 0 | AQ36: 0 | AR36: 0 | AS36: 0 | AT36: 0 | AU36: 0 | AV36: 0 | AW36: 0 | AX36: 0 | AZ36: 0 | BA36: 0 | BB36: 0 | BC36: 0 | BD36: 0 | BE36: 0 | BF36: 0 | BI36: 0 | BJ36: 0 | BK36: 0
C37: =C36+1 -> 23 | D37: Qanot | E37: Trent 700 | F37: Qanot Sharq | G37: MEA | H37: TCA Life Upsell 2 x A330CEO | I37: New a/c | K37: 2 | O37: Low | P37: Med | Q37: Cancelled | S37: 36 | T37: 0 | U37: 0 | V37: =SUM(T37+U37) -> 0 | Y37: 0 | Z37: 0 | AA37: 0 | AB37: 0 | AC37: 0 | AD37: 0 | AE37: 0 | AF37: 0 | AG37: 0 | AH37: 0 | AI37: 0 | AJ37: 0 | AK37: 0 | AL37: 0 | AM37: 0 | AN37: 0 | AO37: 0 | AP37: 0 | AQ37: 0 | AR37: 0 | AS37: 0 | AT37: 0 | AU37: 0 | AV37: 0 | AW37: 0 | AX37: 0 | AZ37: 0 | BA37: 0 | BB37: 0 | BC37: 0 | BD37: 0 | BE37: 0 | BF37: 0 | BI37: 0 | BJ37: 0 | BK37: 0
C38: =C37+1 -> 24 | D38: SW | E38: RB211-524 | F38: Silkway | G38: MEA | H38: Increase in Green Time by 12k cycles | I38: TCA Amendments | K38: 1 | N38: 0 | O38: Low | P38: High | Q38: Cancelled | S38: 25.2 | T38: 12.6 | U38: 12.6 | V38: =SUM(T38+U38) -> 25.2 | Y38: 0 | Z38: 0 | AA38: 0 | AB38: 0 | AC38: 0 | AD38: 0 | AE38: 0 | AF38: 0 | AG38: 0 | AH38: 0 | AI38: 0 | AJ38: 0 | AK38: 0 | AL38: 0 | AM38: 0 | AN38: 0 | AO38: 0 | AP38: 0 | AQ38: 0 | AR38: 0 | AS38: 0 | AT38: 0 | AU38: 0 | AV38: 0 | AW38: 0 | AX38: 0 | AZ38: 0 | BA38: 0 | BB38: 0 | BC38: 0 | BD38: 0 | BE38: 0 | BF38: 0 | BI38: 0 | BJ38: 0 | BK38: 0 | BO38: 1 | BP38: 1 | BQ38: 1 | BR38: 1 | BS38: 1 | BT38: 1 | BU38: 1 | BV38: 1 | BW38: 1 | BX38: 1 | BY38: 1 | BZ38: 1 | CA38: 1 | CB38: 1 | CC38: 1 | CD38: 1 | CE38: 1
C39: =C38+1 -> 25 | D39: Sen | E39: Trent 7000 | F39: Senegal | G39: MEA | H39: Collect debt | I39: Other | K39: 2 | N39: 0.54 | O39: Low | P39: Med | Q39: Cancelled | S39: 10 | T39: 0 | U39: 10 | V39: =SUM(T39+U39) -> 10 | Y39: 0 | Z39: 0 | AA39: 0 | AB39: 0 | AC39: 0 | AD39: 0 | AE39: 0 | AF39: 0 | AG39: 0 | AH39: 0 | AI39: 0 | AJ39: 0 | AK39: 0 | AL39: 0 | AM39: 0 | AN39: 0 | AO39: 0 | AP39: 0 | AQ39: 0 | AR39: 0 | AS39: 0 | AT39: 0 | AU39: 0 | AV39: 0 | AW39: 0 | AX39: 0 | AZ39: 0 | BA39: 0 | BB39: 0 | BC39: 0 | BD39: 0 | BE39: 0 | BF39: 0 | BI39: 0 | BJ39: 0 | BK39: 0
C40: =C39+1 -> 26 | D40: Viva Algeria | E40: Trent 7000 | F40: Air Algerie | G40: MEA | H40: Additional SPE | I40: SPE increase | K40: 1 | L40: yes | O40: High | P40: Low | Q40: Completed | S40: 20 | T40: 0 | U40: 20 | V40: =SUM(T40+U40) -> 20 | Y40: 0 | Z40: 0 | AA40: 0 | AB40: 0 | AC40: 0 | AD40: 0 | AE40: 0 | AF40: 0 | AG40: 0 | AH40: 0 | AI40: 0 | AJ40: 0 | AK40: 0 | AL40: 0 | AM40: 0 | AN40: 0 | AO40: 0 | AP40: 0 | AQ40: 0 | AR40: 0 | AS40: 0 | AT40: 0 | AU40: 0 | AV40: 0 | AW40: 0 | AX40: 0 | AZ40: 0 | BA40: 0 | BB40: 0 | BC40: 0 | BD40: 0 | BE40: 0 | BF40: 0 | BI40: 0 | BJ40: 0 | BK40: 0
C41: =C40+1 -> 27 | D41: Dhabi I | E41: Trent XWB-97 | F41: Etihad | G41: MEA | H41: TCA Reconciliation (CRP Improvement) | I41: TCA Amendments | K41: 1 | N41: 0.09 | O41: High | P41: Med | Q41: Completed | S41: 60 | T41: 5 | U41: 1 | V41: =SUM(T41+U41) -> 6 | Y41: 0 | Z41: 0 | AA41: 0 | AB41: 0 | AC41: 0 | AD41: 0 | AE41: 0 | AF41: 0 | AG41: 0 | AH41: 0 | AI41: 0 | AJ41: 0 | AK41: 0 | AL41: 0 | AM41: 0 | AN41: 0 | AO41: 0 | AP41: 0 | AQ41: 0 | AR41: 0 | AS41: 0 | AT41: 0 | AU41: 0 | AV41: 0 | AW41: 0 | AX41: 0 | AZ41: 0 | BA41: 0 | BB41: 0 | BC41: 0 | BD41: 0 | BE41: 0 | BF41: 0 | BI41: 0 | BJ41: 0 | BK41: 0
C42: =C41+1 -> 28 | D42: Dhabi II | E42: Trent XWB-97 | F42: Etihad | G42: MEA | H42: Transportation Service Buy Out for first 12 | I42: TCA Amendments | K42: 3 | N42: 0.09 | O42: Low | P42: High | Q42: Hopper | S42: 17.76 | T42: 1.48 | U42: 1.48 | V42: =SUM(T42+U42) -> 2.96 | Y42: 0 | Z42: 0 | AA42: 0 | AB42: 0 | AC42: 0 | AD42: 0 | AE42: 0 | AF42: 0 | AG42: 0 | AH42: 0 | AI42: 0 | AJ42: 0 | AK42: 0 | AL42: 0 | AM42: 0 | AN42: 0 | AO42: 0 | AP42: 0 | AQ42: 0 | AR42: 0 | AS42: 0 | AT42: 0 | AU42: 0 | AV42: 0 | AW42: 0 | AX42: 0 | AZ42: 0 | BA42: 0 | BB42: 0 | BC42: 0 | BD42: 0 | BE42: 0 | BF42: 0 | BI42: 0 | BJ42: 0 | BK42: 0
C43: =C42+1 -> 29 | D43: Saud | E43: Trent 700 | F43: Saudia | G43: MEA | H43: Regional Fleet NDSES improvement | I43: Cost Reduction | K43: 1 | N43: 0.31 | O43: High | P43: Med | Q43: Completed | T43: 0 | U43: 0 | V43: =SUM(T43+U43) -> 0 | Y43: 0 | Z43: 0 | AA43: 0 | AB43: 0 | AC43: 0 | AD43: 0 | AE43: 0 | AF43: 0 | AG43: 0 | AH43: 0 | AI43: 0 | AJ43: 0 | AK43: 0 | AL43: 0 | AM43: 0 | AN43: 0 | AO43: 0 | AP43: 0 | AQ43: 0 | AR43: 0 | AS43: 0 | AT43: 0 | AU43: 0 | AV43: 0 | AW43: 0 | AX43: 0 | AZ43: 0 | BA43: 0 | BB43: 0 | BC43: 0 | BD43: 0 | BE43: 0 | BF43: 0 | BI43: 0 | BJ43: 0 | BK43: 0
C44: =C43+1 -> 30 | D44: Saud II | E44: Trent 700 | F44: Saudia | G44: MEA | H44: Extend Classic | I44: Term Extension | J44: Term Extension | K44: 2 | N44: 0.29 | O44: Low | P44: Med | Q44: Hopper | S44: 21.46 | T44: 1.788333 | U44: 1.78833 | V44: =SUM(T44+U44) -> 3.576663 | Y44: 0 | Z44: 0 | AA44: 0 | AB44: 0 | AC44: 0 | AD44: 0 | AE44: 0 | AF44: 0 | AG44: 0 | AH44: 0 | AI44: 0 | AJ44: 0 | AK44: 0 | AL44: 0 | AM44: 0 | AN44: 0 | AO44: 0 | AP44: 0 | AQ44: 0 | AR44: 0 | AS44: 0 | AT44: 0 | AU44: 0 | AV44: 0 | AW44: 0 | AX44: 0 | AZ44: 0 | BA44: 0 | BB44: 0 | BC44: 0 | BD44: 0 | BE44: 0 | BF44: 0 | BI44: 0 | BJ44: 0 | BK44: 0
...

Sheet Summary
F2: Strategic | K2: Financials
C3: Project | D3: Customer | E3: Programme | F3: Kam Pack Complete | G3: CRP Deep Dive Complete | H3: Risk Review Complete | I3: Contract DCR Complete | J3: O&V Review Complete | K3: Current CRP Margin | L3: Onerous Provision | M3: Current CRP % | N3: 2024 onerous release | O3: 2025 onerous release | P3: 5YP improvement (cash or profit?) | U3: Overall Pack Improvement
P4: 2025 | Q4: 2026 | R4: 2027 | S4: 2028 | T4: 2029
B5: Launched | C5: Finiq | D5: Emirates | E5: Trent 900 | K5: -710.44 | L5: -437 | M5: -0.664 | N5: 0 | O5: -437
C6: Burgundy | D6: Qatar | E6: Trent XWB-84 | K6: -920.05 | M6: -0.46 | N6: -6 | U6: 75
E7: Trent XWB-97 | K7: -288.62 | M7: -1.426
C8: Falcon | D8: Gulf | E8: Trent 1000 | F8: 45352 | G8: 45352 | K8: -37 | L8: -25 | M8: -0.113
B9: Pending | C9: Horus | D9: Egypt | E9: Trent 1000 | F9: 45833 | G9: 45863 | K9: -55.05 | L9: -17 | M9: -0.257
D10: Etihad | E10: Trent XWB-97
C11: WAUH | D11: Ethiopia | E11: Trent 1000 | L11: 3.7
D12: Saudia | E12: Trent 700 | K12: 570.01 | M12: 0.531
D13: Mauritus | E13: Trent 7000 | K13: -3.2 | L13: 4 | M13: -0.054
D14: Austral | E14: Trent 1000 | L14: 3.9
D15: Senegal | E15: Trent 7000 | K15: -1.42 | L15: -4.7 | M15: -0.02

Sheet Opps and Threats
E1: Total: | F1: =SUBTOTAL(9,F4:F50) -> 104.62162 | G1: =SUBTOTAL(9,G4:G50) -> 834.72 | H1: =SUBTOTAL(9,H4:H50) -> 0.77027027 | I1: =SUBTOTAL(9,I4:I50) -> 0.82432432 | J1: =SUBTOTAL(9,J4:J50) -> 0.82644788 | K1: =SUBTOTAL(9,K4:K50) -> 0.89189189 | L1: =SUBTOTAL(9,L4:L50) -> 0.72200772 | M1: =SUBTOTAL(9,M4:M50) -> 1300.18
B2: Project | C2: Programme | D2: Customer | E2: Opportunity | F2: 2024 Profit Release | G2: 2025 Profit Release | H2: 2025 | I2: 2026 | J2: 2027 | K2: 2028 | L2: 2029 | M2: Overall Pack improvement (term) | N2: Window for forecast | O2: Due date | P2: Owner | Q2: Status | R2: Comments
H3: 5YP Improvement
B4: Falcon | C4: Trent 1000 | D4: Gulf | E4: Transport reduction from $437k to $300k | F4: =6.31/1.48 -> 4.2635135 | H4: =0.45/1.48 -> 0.30405405 | I4: =0.58/1.48 -> 0.39189189 | J4: =0.58/1.4 -> 0.41428571 | K4: =0.63/1.48 -> 0.42567568 | L4: =0.5/1.4 -> 0.35714286 | M4: =8*1.48 -> 11.84 | N4: W3 2023 | O4: 45627 | P4: Georgia Chapman | Q4: On-track | R4: Challenge transportation pack assumptions
B5: Falcon | C5: Trent 1000 | D5: Gulf | E5: NDSES improvement through SPE sales | F5: =10.15/1.48 -> 6.8581081 | H5: =0.69/1.48 -> 0.46621622 | I5: =0.64/1.48 -> 0.43243243 | J5: =0.61/1.48 -> 0.41216216 | K5: =0.69/1.48 -> 0.46621622 | L5: =0.54/1.48 -> 0.36486486 | M5: =1.5*1.48 -> 2.22 | N5: W3 2023 | O5: 45627 | P5: Georgia Chapman | Q5: On-track
B6: Burgundy | C6: Trent XWB-97 | D6: Qatar | E6: SPE Pull-forward | F6: =4.7 -> 4.7 | M6: =57*1.48 -> 84.36 | N6: W3 2023 | O6: 45596 | P6: Matthew Whatley | Q6: On-track
B7: Burgundy | C7: Multiple | D7: Qatar | E7: Transportation | M7: =25*1.48 -> 37 | N7: W3 2023 | O7: 45596 | P7: Matthew Whatley | Q7: On-track
B8: Burgundy | C8: Trent XWB-84 | D8: Qatar | E8: Exit for convenience removal | F8: =60*1.48 -> 88.8 | M8: =60*1.48 -> 88.8 | N8: W3 2023 | O8: 45565 | P8: Matthew Whatley | Q8: On-track
B9: Burgundy | C9: Trent XWB-97 | D9: Qatar | E9: Exit for convenience removal | G9: =1.48*127 -> 187.96 | M9: =127*1.48 -> 187.96 | N9: W3 2023 | O9: 45961 | P9: Matthew Whatley | Q9: On-track
B10: FiniQ | C10: Trent 900 | D10: Emirates | E10: Extension | G10: =1.48*437 -> 646.76 | M10: =600*1.48 -> 888 | N10: W3 2023 | O10: 45778 | P10: Matthew Whatley | Q10: On-track
B11: FiniQ | C11: Trent XWB-84 | D11: Emirates | E11: 3 year-extension + SPEs + LRU Management | N11: W3 2023 | O11: 45565 | P11: Matthew Whatley | Q11: On-track
B12: N/A | C12: Trent 900 | D12: Emirates | E12: LRU Management optimisation | O12: 45778 | P12: Darren O'Neill
B13: N/A | C13: Trent 1000 | D13: Egypt | E13: Time on wing improvements | P13: Tim Broadhead | R13: Challenge ToW pack assumptions
B14: N/A | C14: Trent XWB-97 | D14: Uganda | E14: Regional Engine washing
B15: N/A | C15: Trent 1000 | D15: Ethiopia | E15: Contract extension/NDSES reduction
B16: N/A | C16: Multiple | D16: Qatar | E16: 3 year extension

Sheet INPUT
C3: INPUT
C8: PROBABILITY | F8: COMPLEXITY | I8: WEIGHTS | L8: YEARS
C10: PROB | D10: SCORE | F10: COMPLEXITY | G10: SCORE | I10: FACTORS | J10: WEIGHT | L10: YEAR | M10: SCORE
C11: High | D11: 3 | F11: High | G11: 1 | I11: PROB | J11: 1 | L11: 2026
C12: Med | D12: 2 | F12: Med | G12: 1 | I12: COMPLEX | J12: 1 | L12: 2027
C13: Low | D13: 1 | F13: Low | G13: 1 | L13: 2028
C14: ="-" -> - | F14: ="-" -> - | L14: 2029
L15: 2030
L16: 2031
C17: STATUS | F17: PROJECT | I17: PROJECT
C19: STATUS | F19: CUSTOMER | G19: PROEJCT | I19: PROGRAMME
C20: Hopper | F20: {=IF(_xlfn.UNIQUE('MEA LOG'!$F$15:$F$100)<>0,_xlfn.UNIQUE('MEA LOG'!$F$15:$F$100),"")} -> Emirates | G20: {=IF(_xlfn.UNIQUE('MEA LOG'!$D$15:$D$100)<>0,_xlfn.UNIQUE('MEA LOG'!$D$15:$D$100),"")} -> FiniQ II | I20: Trent XWB-84
C21: ICT | F21: Ethiopia | G21: FiniQ III | I21: Trent XWB-97
C22: Negotiations | F22: Qatar | G22: IDK | I22: Trent 1000
C23: Contracting | F23: Qatar Amiri | G23: Selassi | I23: Trent 500
C24: Completed | F24: Egypt | G24: Selassi II | I24: Trent 700
C25: Cancelled | F25: Turkmenistan | G25: Burgundy | I25: RB211-524
F26: Qanot Sharq | G26: Burgundy II | I26: Trent 7000
C27: REGIONS | F27: Silkway | G27: Burgundy III
F28: Senegal | G28: QA | I28: NORMALIZE
C29: REGIONS | F29: Air Algerie | G29: Horus
C30: Americas | F30: Etihad | G30: Horus II | I30: TERM IMPACT | J30: VALUE | L30: 26/27 | M30: VALUE
C31: APAC | F31: Saudia | G31: Horus III | I31: MAX | J31: =MAX('MEA LOG'!S15:S99) -> 341.88 | L31: MAX | M31: =MAX('MEA LOG'!V15:V99) -> 68.08
C32: Europe | F32: Tanzania | G32: Horus IV | I32: MIN | J32: =MIN('MEA LOG'!S15:S99) -> 0 | L32: MIN | M32: =MIN('MEA LOG'!V15:V99) -> 0
C33: Greater China | F33: Gulf | G33: Turk | I33: MAX-MIN | J33: =J31-J32 -> 341.88 | L33: MAX-MIN | M33: =M31-M32 -> 68.08
C34: MEA | F34: Austral | G34: Qanot
F35: Kuwait | G35: SW | I35: 26 | J35: VALUE | L35: 27 | M35: VALUE
C36: Status | F36: Mauritus | G36: Sen | I36: MAX | J36: =MAX('MEA LOG'!T15:T99) -> 68.08 | L36: MAX | M36: =MAX('MEA LOG'!U15:U99) -> 45.88
F37: Rwanda | G37: Viva Algeria | I37: MIN | J37: =MIN('MEA LOG'!T15:T99) -> 0 | L37: MIN | M37: =MIN('MEA LOG'!U15:U99) -> 0
C38: Status | F38: SAA | G38: Dhabi I | I38: MAX-MIN | J38: =J36-J37 -> 68.08 | L38: MAX-MIN | M38: =M36-M37 -> 45.88
C39: Planned | G39: Dhabi II
C40: On-Going | G40: Saud
C41: Completed | G41: Saud II
C42: Cancelled | G42: Tanz
G43: Falcon
G44: Star
G45: Q8
C46: Type | G46: Mau
C47: Cost Reduction | G47: Dodo
C48: TCA Amendments | G48: RW
...

Sheet User Guide
A1: MEA Profit Opportunites Tracker
Q2: Version: V1.0
A3: Scope
B4: MEA LOG | C4: Log Sheet where the opportunity is identifies, priority, probability and current status are assigned and monitored along with initial AM estimates
B5: ICT Estimtes | C5: Profit Estimates evaluated by the ICT
B6: Contracting | C6: Profit Impact based on the contracted levles
B7: MEA Commercial Optimisation Report
A9: Instructions
A10: 1.1 | B10: Opportunity Identification
A11: Sheet: | B11: "MEA LOG"
A13: The MEA LOG sheet will include all non financial details of the Opportunity, along with initial AM estimates
A14: The Status column (Column Q) is to be updated as the opportuntiy progress through "ICT", "Negotiations", "Contracting" till "Completed"
A16: Note: Any changes to the Asks, levers, status, or any non-finanical details should be adjusted in the MEA LOG
A18: 1.2 | B18: ICT Estimates
A19: Sheet: | B19: "L2" sheet
A21: ICT estimates,which can be accessed by clicking ICT Estimates or L2 Sheet
A24: 1.3 | B24: Contracting
A25: Sheet: | B25: "L3" sheet
A27: Contracting level profit imprvoment, which can be accessed by clicking Contrcating or L3 Sheet
A29: 2 | B29: Timeline
A30: Sheet: | B30: Timeline
A32: The sheet is used to input the planned timeline against every commercial project following the Below structure
B34: Hopper | C34: Idea Generation
C35: Approval to Launch
B36: ICT | C36: Strategy Apporval
C37: BE Generated
C38: Apprvoal
B39: Negotiations | C39: Negotiations Strategy
C40: Proposal Submitted
C41: Proposal Signed
A43: Minor steps can be added in blank cells to be viewed then in the MEA Commercial Optimisation Report
A44: Note: Please ensure that the structure and the organisation of each milestone is maintained
A46: 3 | B46: MEA Commercial Optimisation Report
A47: File: | B47: MEA Commercial Optimisation Report
A49: The MEA Commercial Optimisation report is a Power BI dashboard that uses the data stored in this workbook to visualise all commercial opportunties

Sheet COVER
C3: COMMERCIAL OPTIMISATION OPPORTUNITY REPORT
C55: OPP COUNT
C57: =SUM(COUNT!D11:D29) -> 45
C59: PROB | D59: COUNIT OF OPP | E59: % OF ALL OPP | G59: COMPLEXITY | H59: COUNIT OF OPP | I59: % OF ALL OPP | K59: STATUS | L59: COUNIT OF OPP | M59: % OF ALL OPP | O59: YEARS | P59: COUNIT OF OPP | Q59: % OF ALL OPP
C60: {=_xlfn._xlws.FILTER(INPUT!C11:C13,TRUE)} -> High | D60: =COUNTIF('MEA LOG'!$O$15:$O$99,COVER!C60) -> 11 | E60: =D60/SUM($D$60:$D$62) -> 0.24444444 | G60: {=_xlfn._xlws.FILTER(INPUT!F11:F13,TRUE)} -> High | H60: =COUNTIF('MEA LOG'!$P$15:$P$99,COVER!C60) -> 5 | I60: =H60/SUM($H$60:$H$62) -> 0.11111111 | K60: {=_xlfn._xlws.FILTER(INPUT!$C$20:$C$24,TRUE)} -> Hopper | L60: =COUNTIF('MEA LOG'!$Q$15:$Q$99,K60) -> 17 | M60: =L60/SUM($L$60:$L$64) -> 0.45945946 | O60: {=_xlfn._xlws.FILTER(INPUT!L11:L16,TRUE)} -> 2026 | P60: =COUNTIF('MEA LOG'!$T$15:$T$99,"<>") -> 36 | Q60: =P60/SUM($P$60:$P$65) -> 0.8
C61: Med | D61: =COUNTIF('MEA LOG'!$O$15:$O$99,COVER!C61) -> 15 | E61: =D61/SUM($D$60:$D$62) -> 0.33333333 | G61: Med | H61: =COUNTIF('MEA LOG'!$P$15:$P$99,COVER!C61) -> 26 | I61: =H61/SUM($H$60:$H$62) -> 0.57777778 | K61: ICT | L61: =COUNTIF('MEA LOG'!$Q$15:$Q$99,K61) -> 5 | M61: =L61/SUM($L$60:$L$64) -> 0.13513514 | O61: 2027 | P61: =COUNTIF('MEA LOG'!$U$15:$U$99,"<>") -> 35 | Q61: =P61/SUM($P$60:$P$65) -> 0.77777778
C62: Low | D62: =COUNTIF('MEA LOG'!$O$15:$O$99,COVER!C62) -> 19 | E62: =D62/SUM($D$60:$D$62) -> 0.42222222 | G62: Low | H62: =COUNTIF('MEA LOG'!$P$15:$P$99,COVER!C62) -> 14 | I62: =H62/SUM($H$60:$H$62) -> 0.31111111 | K62: Negotiations | L62: =COUNTIF('MEA LOG'!$Q$15:$Q$99,K62) -> 3 | M62: =L62/SUM($L$60:$L$64) -> 0.081081081 | O62: 2028 | P62: =($C$57-SUM($P$60:$P$61))/4 -> -6.5 | Q62: =P62/SUM($P$60:$P$65) -> -0.14444444
K63: Contracting | L63: =COUNTIF('MEA LOG'!$Q$15:$Q$99,K63) -> 3 | M63: =L63/SUM($L$60:$L$64) -> 0.081081081 | O63: 2029 | P63: =($C$57-SUM($P$60:$P$61))/4 -> -6.5 | Q63: =P63/SUM($P$60:$P$65) -> -0.14444444
K64: Completed | L64: =COUNTIF('MEA LOG'!$Q$15:$Q$99,K64) -> 9 | M64: =L64/SUM($L$60:$L$64) -> 0.24324324 | O64: 2030 | P64: =($C$57-SUM($P$60:$P$61))/4 -> -6.5 | Q64: =P64/SUM($P$60:$P$65) -> -0.14444444
O65: 2031 | P65: =($C$57-SUM($P$60:$P$61))/4 -> -6.5 | Q65: =P65/SUM($P$60:$P$65) -> -0.14444444
C80: IMPACT DIST
C82: ='MEA LOG'!S12 -> 1531.432
C84: PROB | D84: SUM OF IMPACT | E84: % OF TOTAL IMPACT | G84: COMPLEXITY | H84: SUM OF IMPACT | I84: % OF TOTAL IMPACT | K84: STATUS | L84: SUM OF IMPACT | M84: % OF TOTAL IMPACT | O84: YEARS | P84: SUM OF IMPACT | Q84: % OF TOTAL IMPACT
C85: {=_xlfn._xlws.FILTER(INPUT!C11:C13,TRUE)} -> High | D85: =SUMIF('MEA LOG'!$O$15:$O$99,COVER!C85,'MEA LOG'!$S$15:$S$99) -> 782.36 | E85: =D85/'MEA LOG'!$S$12 -> 0.51086826 | G85: {=_xlfn._xlws.FILTER(INPUT!F11:F13,TRUE)} -> High | H85: =SUMIF('MEA LOG'!$P$15:$P$99,COVER!G85,'MEA LOG'!$S$15:$S$99) -> 156.92 | I85: =H85/'MEA LOG'!$S$12 -> 0.10246619 | K85: {=_xlfn._xlws.FILTER(INPUT!$C$20:$C$24,TRUE)} -> Hopper | L85: =SUMIF('MEA LOG'!$Q$15:$Q$99,COVER!K85,'MEA LOG'!$S$15:$S$99) -> 413.72 | M85: =L85/'MEA LOG'!$S$12 -> 0.27015238 | O85: {=_xlfn._xlws.FILTER(INPUT!L11:L16,TRUE)} -> 2026 | P85: =SUM('MEA LOG'!T$15:T$99) -> 156.74607 | Q85: =P85/$C$82 -> 0.10235261
C86: Med | D86: =SUMIF('MEA LOG'!$O$15:$O$99,COVER!C86,'MEA LOG'!$S$15:$S$99) -> 211.712 | E86: =D86/'MEA LOG'!$S$12 -> 0.13824447 | G86: Med | H86: =SUMIF('MEA LOG'!$P$15:$P$99,COVER!G86,'MEA LOG'!$S$15:$S$99) -> 622.892 | I86: =H86/'MEA LOG'!$S$12 -> 0.40673827 | K86: ICT | L86: =SUMIF('MEA LOG'!$Q$15:$Q$99,COVER!K86,'MEA LOG'!$S$15:$S$99) -> 188.62 | M86: =L86/'MEA LOG'!$S$12 -> 0.12316577 | O86: 2027 | P86: =SUM('MEA LOG'!U$15:U$99) -> 183.99273 | Q86: =P86/$C$82 -> 0.12014424
C87: Low | D87: =SUMIF('MEA LOG'!$O$15:$O$99,COVER!C87,'MEA LOG'!$S$15:$S$99) -> 537.36 | E87: =D87/'MEA LOG'!$S$12 -> 0.35088727 | G87: Low | H87: =SUMIF('MEA LOG'!$P$15:$P$99,COVER!G87,'MEA LOG'!$S$15:$S$99) -> 751.62 | I87: =H87/'MEA LOG'!$S$12 -> 0.49079554 | K87: Negotiations | L87: =SUMIF('MEA LOG'!$Q$15:$Q$99,COVER!K87,'MEA LOG'!$S$15:$S$99) -> 47.88 | M87: =L87/'MEA LOG'!$S$12 -> 0.031264855 | O87: 2028 | P87: =($C$82-SUM($P$85:$P$86))/4 -> 297.6733 | Q87: =P87/$C$82 -> 0.19437579
K88: Contracting | L88: =SUMIF('MEA LOG'!$Q$15:$Q$99,COVER!K88,'MEA LOG'!$S$15:$S$99) -> 82.18 | M88: =L88/'MEA LOG'!$S$12 -> 0.053662193 | O88: 2029 | P88: =($C$82-SUM($P$85:$P$86))/4 -> 297.6733 | Q88: =P88/$C$82 -> 0.19437579
K89: Completed | L89: =SUMIF('MEA LOG'!$Q$15:$Q$99,COVER!K89,'MEA LOG'!$S$15:$S$99) -> 606.192 | M89: =L89/'MEA LOG'!$S$12 -> 0.39583344 | O89: 2030 | P89: =($C$82-SUM($P$85:$P$86))/4 -> 297.6733 | Q89: =P89/$C$82 -> 0.19437579
O90: 2031 | P90: =($C$82-SUM($P$85:$P$86))/4 -> 297.6733 | Q90: =P90/$C$82 -> 0.19437579
C104: 2026
C106: =SUM('MEA LOG'!T15:T99) -> 156.74607
C108: PROB | D108: SUM OF IMPACT | E108: % OF TOTAL IMPACT | G108: COMPLEXITY | H108: SUM OF IMPACT | I108: % OF TOTAL IMPACT | K108: STATUS | L108: SUM OF IMPACT | M108: % OF TOTAL IMPACT
C109: {=_xlfn._xlws.FILTER(INPUT!C11:C13,TRUE)} -> High | D109: =SUMIF('MEA LOG'!$O$15:$O$99,COVER!C109,'MEA LOG'!$T$15:$T$99) -> 75.301666 | E109: =D109/$C$106 -> 0.48040546 | G109: {=_xlfn._xlws.FILTER(INPUT!F11:F13,TRUE)} -> High | H109: =SUMIF('MEA LOG'!$P$15:$P$99,G109,'MEA LOG'!$T$15:$T$99) -> 82.16 | I109: =H109/$C$106 -> 0.52415988 | K109: {=_xlfn._xlws.FILTER(INPUT!$C$20:$C$24,TRUE)} -> Hopper | L109: =SUMIF('MEA LOG'!$Q$15:$Q$99,COVER!K109,'MEA LOG'!$T$15:$T$99) -> 29.878 | M109: =L109/$C$106 -> 0.19061403
C110: Med | D110: =SUMIF('MEA LOG'!$O$15:$O$99,COVER!C110,'MEA LOG'!$T$15:$T$99) -> 37.2844 | E110: =D110/$C$106 -> 0.23786498 | G110: Med | H110: =SUMIF('MEA LOG'!$P$15:$P$99,G110,'MEA LOG'!$T$15:$T$99) -> 40.264733 | I110: =H110/$C$106 -> 0.25687875 | K110: ICT | L110: =SUMIF('MEA LOG'!$Q$15:$Q$99,COVER!K110,'MEA LOG'!$T$15:$T$99) -> 0.076 | M110: =L110/$C$106 -> 0.00048486065
C111: Low | D111: =SUMIF('MEA LOG'!$O$15:$O$99,COVER!C111,'MEA LOG'!$T$15:$T$99) -> 44.16 | E111: =D111/$C$106 -> 0.28172956 | G111: Low | H111: =SUMIF('MEA LOG'!$P$15:$P$99,G111,'MEA LOG'!$T$15:$T$99) -> 34.321333 | I111: =H111/$C$106 -> 0.21896137 | K111: Negotiations | L111: =SUMIF('MEA LOG'!$Q$15:$Q$99,COVER!K111,'MEA LOG'!$T$15:$T$99) -> 2.04 | M111: =L111/$C$106 -> 0.013014681
K112: Contracting | L112: =SUMIF('MEA LOG'!$Q$15:$Q$99,COVER!K112,'MEA LOG'!$T$15:$T$99) -> 70.78 | M112: =L112/$C$106 -> 0.45155838
K113: Completed | L113: =SUMIF('MEA LOG'!$Q$15:$Q$99,COVER!K113,'MEA LOG'!$T$15:$T$99) -> 38.852066 | M113: =L113/$C$106 -> 0.24786629
C128: 2027
C130: =SUM('MEA LOG'!U15:U99) -> 183.99273
C132: PROB | D132: SUM OF IMPACT | E132: % OF TOTAL IMPACT | G132: COMPLEXITY | H132: SUM OF IMPACT | I132: % OF TOTAL IMPACT | K132: STATUS | L132: SUM OF IMPACT | M132: % OF TOTAL IMPACT
C133: {=_xlfn._xlws.FILTER(INPUT!C11:C13,TRUE)} -> High | D133: =SUMIF('MEA LOG'!$O$15:$O$99,COVER!C133,'MEA LOG'!$U$15:$U$99) -> 72.78833 | E133: =D133/$C$130 -> 0.39560438 | G133: {=_xlfn._xlws.FILTER(INPUT!F11:F13,TRUE)} -> High | H133: =SUMIF('MEA LOG'!$P$15:$P$99,G133,'MEA LOG'!$U$15:$U$99) -> 59.96 | I133: =H133/$C$130 -> 0.32588244 | K133: {=_xlfn._xlws.FILTER(INPUT!$C$20:$C$24,TRUE)} -> Hopper | L133: =SUMIF('MEA LOG'!$Q$15:$Q$99,COVER!K133,'MEA LOG'!$U$15:$U$99) -> 75.758 | M133: =L133/$C$130 -> 0.41174453
