Workbook
Name Engine_Type: Sheet3!$H$2:$H$3
Name Slicer_TYPE_OF_GUARANTEE: #N/A
Name Slicer_TYPE_OF_GUARANTEE1: #N/A

Sheet MENU
M3: Emirates
M4: Trent 900 Guarantee Administration
B7: ORIGINAL GUARANTEES | D7: Guarantee | H7: Links | M7: Guarantee | Q7: Links | V7: ENHANCED GUARANTEES | X7: Guarantee | AB7: Links
D8: Aborted Take-Off | H8: Description | M8: Remote Site Removal | Q8: Description | X8: Aircraft Availability HPTB Guarantee | AB8: Description
H9: Data Entry | Q9: Data Entry | AB9: Data Entry
H10: Summary | Q10: Summary | AB10: Summary
D12: Diversion and Air Turnback | H12: Description | M12: Shop Visit Rate | Q12: Description | X12: Enhanced Shop Visit Rate | AB12: Description
H13: Data Entry | Q13: Data Entry | AB13: Data Entry
H14: Summary | Q14: Summary | AB14: Summary
D16: Emissions | H16: Description | M16: Surge (Whole Flight) | Q16: Description | X16: Enhanced HPTB Measure | AB16: Description
H17: Data Entry/Summary | Q17: Data Entry | AB17: Data Entry
Q18: Summary | AB18: Summary
D20: Engine Weight | H20: Description | M20: Uncontained Failure | Q20: Description | V20: SUMMARIES | X20: Claims Summary
H21: Data Entry/Summary | Q21: Data Entry
Q22: Summary
D24: HPT Blade or Vane Failure | H24: Description | M24: Disruption Index | Q24: Description | X24: EFH and Cycles Summary
H25: Data Entry | Q25: Data Entry
H26: Summary | Q26: Summary
D28: Fan Blade Release | H28: Description | M28: Oil Consumption | Q28: Description | X28: EFH and Cycles Data Input
H29: Data Entry | Q29: Data Entry
H30: Summary | Q30: Summary
D32: Enhanced Line Maintenance Burden | H32: Description | M32: Turbine Gas Turbine Deterioration | Q32: Description | X32: Charts
H33: Data Entry | Q33: Data Entry
H34: Summary | Q34: Summary

Sheet Sheet3
B2: ABTO | F2: Qualified | H2: Trent 972
B3: DI - Cancellation | F3: Non-qualified | H3: Enhanced Thrust Engine
B4: DI - Delay | F4: Basic
B5: DI - Shutdown | F5: Non-basic
B6: DI - Unplanned removal | F6: Open
B7: DIV & ATB
B8: FB Release
B9: HPTB or Vane
B10: Oil & HTB
B11: RSR
B12: Surge
B13: TGT Dev
B14: Uncontained Failure
B15: Non-qualified

Sheet DESCRIPTIONS
D2: EMIRATES
D3: TRENT 900 GUARANTEE ADMINISTRATION
D4: TO BE USED IN CONJUNCTION WITH PRODUCT AGREEMENT DEG9008 AND SLA1 ONLY
B6: Guarantee | C6: Abbreviation | D6: Description | E6: Remedy | F6: Emirates Reporting Obligations | G6: Reconciliation Method | H6: Specific Definitions | I6: Specific Conditions | J6: Term | K6: Reconciliation Basis
B7: Aborted Take-off | C7: ABTO | D7: Qualified Aborted Take-offs will not exceed a cumulative rate of 0.008 per 100 revenue departures. | E7: Fixed credit note of $250,000 for each excess Qualified Aborted Take-off. | F7: At the end of each 6 month period during the Term of Guarantee, Emirates will provide Rolls-Royce with the following: • a list of all aborted take-offs during such 6 month period; • such information as Rolls-Royce may reasonably require to enable Rolls-Royce to determine which aborted take-offs are Qualified Aborted Take-offs. 2) Evidence of Failure per event. | G7: Rolls-Royce’s sole obligation will be to provide the Remedy less any credits already provided on the second and each subsequent Anniversary Date if the cumulative number of Qualified Aborted Take-offs exceeds the Measure. | H7: “Qualified Aborted Take-off” means an aborted take-off during the course of a revenue departure of an Aircraft by Emirates, which has been aborted due to a power reduction (whether Commanded or un-commanded), and which is determined to have been caused solely by a Failure of a Part of the Dressed Engine (as defined in the Specification). “Commanded” power reduction means an operation by the pilot of an Aircraft which is required to be performed, and is performed, in accordance with the procedures contained in the relevant flight crew operations manual. | I7: N/A | J7: 15 years | K7: Annual
B8: Diversion and Air Turnback Guarantee | C8: DIV & ATB | D8: Qualified Events will not exceed a cumulative rate of 0.0008 per 100 revenue departures. | E8: Fixed credit note of $250,000 for each excess Qualified Event. | F8: At the end of each 6 month period during the Term of Guarantee, Emirates will provide Rolls-Royce with the following: • list of all diversions and air turnbacks during such 6 month period; and • such information as Rolls-Royce may reasonably require to enable Rolls-Royce to determine which of such diversions and air turnbacks are Qualified Events. 2) Evidence of Failure per event. | G8: Rolls-Royce’s sole obligation will be to provide the Remedy less any credits already provided on the second and each subsequent Anniversary Date if the cumulative number of Qualified Events exceeds the Measure. | H8: “Qualified Event” means the diversion of an Aircraft on a revenue flight by Emirates to another airport other than the destination or departure airport, or the return of an Aircraft on a revenue flight by Emirates to the airport of departure, which is determined to have been caused solely by a Failure of a Part of the Dressed Engine (as defined in the Specification), provided that if the event could have been prevented by timely maintenance action or the incorporation of modifications for which the parts, instructions and Service Bulletins had been made available to Emirates by Rolls-Royce, it will not constitute a Qualified Event. | I8: N/A | J8: 15 years | K8: Annual
B9: Emissions Guarantee | C9: EMISSIONS | D9: Engine Type will not exceed any of the following emission levels at certification: - Oxides of Nitrogen (NOx)- CAEP 8 Level minus 10%; - Unburned Hydrocarbons (UHC) - CAEP 8 Level minus 50%; - Carbon Monoxide (CO) - CAEP 8 Level minus 50%; - Smoke - CAEP 8 Level minus 30%. | E9: A fixed credit note equivalent to Emirates substantiated losses incurred as a direct result of Engines failing to satisfy the Measure subject to a fixed maximum value of $250,000 per Aircraft over the Term of Guarantee. | F9: At the end of each 6 month period during the Term of Guarantee, Emirates will provide Rolls-Royce with all data that it may reasonably require relating to substantiated losses due solely to Engines failing to satisfy the Measure. 2) List of departures and arrivals in and out of Customer main base airport. | G9: If Rolls-Royce is able to demonstrate compliance with the Measure at certification then this Emissions Guarantee will be considered to be satisfied in full by Rolls-Royce and there will be no further obligation by Rolls-Royce under this Guarantee. Rolls-Royce’s sole obligation will be to provide the Remedy if Rolls-Royce is unable to demonstrate compliance with the Measure. | H9: “CAEP 8 Levels” are from CAEP 8 recommendations; ICAO Annex 16, Volume 2, 3rd Edition – Amendment 7. | I9: If the Measure is not satisfied, Rolls-Royce may at its election make available at no incremental cost to Emirates modifications that will enable Engines to meet the Measure. Rolls-Royce’s liability under this Guarantee will cease if Emirates fails to incorporate such modifications as soon as practically possible. | J9: 15 years
B10: Engine Weight Guarantee | C10: WEIGHT | D10: Fleet Average Engine Weight will not exceed 6,545.34 kilograms. | E10: A credit note for excess fuel burn calculated in accordance with the Formula below, subject to a fixed maximum value of $250,000 per Aircraft over the Term of Guarantee with a fixed maximum value of $25,000 per Aircraft per year. | F10: Within 90 days of each Anniversary Date during the Term of Guarantee, Customer will provide Rolls-Royce with the following: • a report stating the cumulative Engine Flight Hours logged for the year prior to such Anniversary Date; and • such information as Rolls-Royce may reasonably require to demonstrate to its reasonable satisfaction that this Engine Weight Guarantee has not been satisfied. | G10: If at an Anniversary Date Customer can demonstrate non-compliance with the Measure by comparing the Fleet Average Engine Weight with the Measure, then Customer will submit a claim to Rolls-Royce and Rolls-Royce’s sole obligation will be to provide the Remedy. | H10: “Aviation Fuel Cost” means as mutually agreed between the Parties prior to the administration of this guarantee, either: (i) an aviation fuel cost index (representative Emirates cost of fuel) as agreed between the Parties; or (ii) the substantiated average cost to Emirates of aviation fuel, after the deduction of any applicable subsidies or Government or other allowances received by Emirates and excluding any hedging activity that may have been undertaken by Emirates. (The methodology for substantiating the average cost to Emirates of aviation fuel shall be agreed between the Parties 6 months prior to EIS). The Aviation Fuel Cost covers aviation fuel only and includes Emirates reasonably demonstrated pumping fees and taxes up to a value equivalent to fifteen percent (15%) of the net cost to Emirates of aviation fuel after excluding pumping fees and taxes). “Fleet Average Engine Weight” means the average weight of the Installed Engine(s) (including EBU and fluids) then delivered in kgs (as defined in the Specification) excluding BFE and BFE fluids at the time of delivery to the Airframer or Customer and at the first and each subsequent Anniversary Date. | I10: At its election, Rolls-Royce may provide, at no incremental cost to Customer, modifications required to reduce the weight of the Engine, where the incorporation of modifications has been demonstrated by Rolls-Royce to be capable of eliminating or reducing excess weight. In the event that Customer declines to incorporate the modifications in a reasonable timescale then the obligations of Rolls-Royce under this Engine Weight Guarantee will be reduced to reflect the reduction in weight to the Engines had such modifications been incorporated. The claim will be accompanied by the Officer’s Review Certificate as detailed in Exhibit A to Schedule 5 of the PA. | J10: 15 years | K10: Annual
B11: HPT Blade or Vane Failure Guarantee | C11: HPTB&V | D11: The occurrence of a Qualified HPT Blade Failure or Qualified HP Nozzle Guide Vane Failure during the Term of Guarantee. | E11: If during the Term of Guarantee a Qualified HPT Blade Failure or Qualified HP Nozzle Guide Vane Failure is ascertained to have occurred, then Rolls-Royce’s sole obligation shall be to provide Customer with a fixed credit note amounting to US$250,000 per event. | F11: If during the Term of Guarantee a suspected HPT Blade Failure occurs or HP Nozzle Guide Vane Failure occurs, then Customer shall submit a claim to Rolls-Royce and provide such information as Rolls-Royce may reasonably require to enable Rolls-Royce to determine if such failure is a Qualified HPT Blade Failure or Qualified HP Nozzle Guide Vane Failure. | G11: If a Qualified HP Nozzle Guide Vane Failure or Qualified HPT Blade Failure event occurs then Rolls-Royce’s sole obligation will be to provide the Remedy. | H11: “Qualified HPT Blade Failure” means the Failure of a HPT Blade, fitted to an Engine, which causes the un-commanded in-flight shutdown of an Engine and as a direct result of such Failure the Engine requires Repair at an Overhaul Base to return it to a serviceable condition excluding any Failure that is caused by FOD, or negligence by anyone other than Rolls-Royce or its sub-contractors, including but not limited to, improper operation, maintenance, repair or overhaul. “Qualified HP Nozzle Guide Vane Failure” means the Failure of a HP Nozzle Guide Vane, fitted to an Engine, which causes the un-commanded in-flight shutdown of an Engine and as a direct result of such Failure the Engine requires Repair at an Overhaul Base to return it to a serviceable condition excluding any Failure that is caused by FOD, or negligence by anyone other than Rolls-Royce or its sub-contractors, including but not limited to, improper operation, maintenance, repair or overhaul. “HPT Blade” means the high pressure turbine blade as detailed in the IPC ref 72-41-52-01 HP Turbine Blade “HP Nozzle Guide Vane” means the high pressure nozzle guide vane as detailed in the IPC ref 72-41-14-01 – HP Nozzle Guide Vanes | I11: N/A | J11: 15 years | K11: Event Based
B12: Fan Blade Release Guarantee | C12: FBR | D12: The occurrence of a Qualified Fan Blade Release. | E12: A credit note per Qualified Fan Blade Release equal to the lesser of: (a) the Qualifying Repair Costs; or (b) $1,000,000. | F12: If a fan blade release occurs during the Term of Guarantee which is suspected to be a Qualified Fan Blade Release, then Emirates will: • submit a claim to Rolls-Royce within three calendar months of such primary fan blade release; and • provide such information as Rolls-Royce may reasonably require to enable Rolls-Royce to determine if such primary fan blade release is a Qualified Fan Blade Release. | G12: If a Qualified Fan Blade Release occurs, then Rolls-Royce’s sole obligation will be to provide the Remedy. | H12: “Qualified Fan Blade Release” means the Failure of a fan blade in an Engine that causes the release of such fan blade. “Qualifying Repair Costs” means, in respect of a Qualified Fan Blade Release, the amount equal to the demonstrated cost to Emirates of repairing damage done to: (i) the Engine suffering the Qualified Fan Blade Release; and (ii) the Aircraft on which such Engine was installed at the time of such Qualified Fan Blade Release (including any one or more of the other Engines installed on such Aircraft at the time of such Qualified Fan Blade Release). in each case caused wholly and exclusively by such Qualified Fan Blade Release. | I12: • Where Rolls-Royce recommends that Emirates inspects or removes fan blades to avert what is, in Rolls-Royce’s view, a likely fan blade release and Emirates declines to inspect or remove such item at the first convenient opportunity, then Rolls-Royce’s liability under this Guarantee will cease. | J12: 15 years | K12: Event Based
B13: Enhanced Line Maintenance Burden Guarantee | C13: ELMB | D13: Line Maintenance Burden will not exceed a cumulative rate of 14 hours per 1000 Flight Hours. | E13: A fixed credit note for the excess Line Maintenance Burden multiplied by the then current Warranty Labour Rate, subject to a fixed maximum value of $250,000 per Aircraft over the Term of Guarantee. | F13: At the end of each 6 month period during the Term of Guarantee, Emirates will provide Rolls-Royce with the following: • a list of all scheduled line maintenance tasks performed during such 6 month period; and • such information as Rolls-Royce may reasonably require to enable Rolls-Royce to determine the Line Maintenance Burden. | G13: Rolls-Royce’s sole obligation will be to provide the Remedy at the end of the Term of Guarantee if the Line Maintenance Burden exceeds the Measure. | H13: “Line Maintenance Burden” means the number of hours incurred by Emirates in performing (or having performed) repeat line maintenance in accordance with either the MPD, Rolls-Royce issued non-modification Service Bulletins (NMSB), On-Wing Service Bulletins and Ground Running but excluding hours incurred in relation to “once around the fleet” inspections, troubleshooting activities, activities in relation to aircraft maintenance messages, activities in relation to electronic centralised aircraft monitoring messages and hours associated with any Airframer supplied accessory; EBU; nose cowl; thrust reverser; nacelle; Engine removal or reinstallation. “MPD” means the Airframer maintenance planning document, which captures most of the repeat inspections tasks for the Aircraft. For the purposes of this Line Maintenance Burden Guarantee, only the Engine related tasks are considered relevant. “On-Wing Service Bulletins” means Rolls-Royce issued Recommended Service Bulletins which Rolls-Royce recommends to be performed On-Wing. “Ground Running” means ground running of an Engine required following the performance of routine Line Maintenance (excluding cool down times). | I13: Specific Conditions • At its election, Rolls-Royce may provide free of charge modifications which remove the requirement to perform line maintenance. If Emirates declines to incorporate such modifications within a reasonable timescale then any hours associated with carrying out such line maintenance tasks will not be included in the calculation of Line Maintenance Burden. • At its election, Rolls-Royce may provide service mechanics to carry out line maintenance. Any hours associated with such line maintenance carried out by Rolls-Royce mechanics will not be included in the calculation of Line Maintenance Burden. • Emirates will ensure that its line maintenance personnel will receive initial and follow-up training from time-to-time on Engine maintenance troubleshooting techniques. • The times used to measure Line Maintenance Burden are the times set out in the applicable technical documentation including MPD, AMM and Rolls-Royce Service Bulletins. • Where Line Maintenance Burden tasks are not explicitly recorded within the MPD or by a NMSB, Rolls-Royce and Emirates will mutually agree the duration of the task in man hours, prior to incorporation of such task into this guarantee. | J13: 15 years | K13: End of Term
B14: Remote Sight Removal Guarantee | C14: RSM | D14: Qualified Remote Site Removals will not exceed a cumulative rate of 0.0012 per 1000 Flight Hours. | E14: A fixed credit note for demonstrated costs up to $250,000 for each excess Qualified Remote Site Removal. | F14: At the end of each 6 month period during the Term of Guarantee, Emirates will provide Rolls-Royce with the following: • a list of all remote site removals during such 6 month period; and • such information as Rolls-Royce may reasonably require to enable Rolls-Royce to determine which of such removals are Qualified Remote Site Removals. | G14: Rolls-Royce’s sole obligation will be to provide the Remedy less any credits already provided on the second and each subsequent Anniversary Date if the cumulative number of Qualified Remote Site Removals exceeds the Measure. | H14: “Qualified Remote Site Removal” means the unplanned necessary removal of an Engine from an Aircraft by Emirates which is determined to have been caused solely by a Failure of a Part of the Dressed Engine (as defined in the Specification), where the removal occurs away from Main Base, where no spare Engine is normally located, and where all reasonable endeavours to rectify the Failure on-wing through Line Maintenance actions have been exhausted. | I14: • Transportation costs of the Spare Engine to the remote site and return transportation of the removed Engine to the Overhaul Base following a Qualified Event (as defined in the TotalCare Service Agreement) are covered pursuant to the terms of the TotalCare Services Agreement. | J14: 15 years | K14: Annual
B15: Shop Visit Rate Guarantee | C15: SVR | D15: Qualified Shop Visits will not exceed a cumulative rate of 0.069 per 1000 Flight Hours. | E15: A fixed credit note of $250,000 for each excess Qualified Shop Visit. | F15: At the end of each 6 month period during the Term of Guarantee, Emirates will provide Rolls-Royce with the following: • a list of all shop visits during such 6 month period; and • such information as Rolls-Royce may reasonably require to enable Rolls-Royce to determine which shop visits are Qualified Shop Visits. | G15: Rolls-Royce’s sole obligation will be to provide the Remedy less any credits already provided on the second and each subsequent Anniversary Date if the cumulative number of Qualified Shop Visits exceeds the Measure. | H15: “Qualified Shop Visit” means an Engine shop visit that is required solely as a result of the following: (i) a Failure of a Part of the Dressed Engine (as defined in the Specification) where the shop visit was necessary to correct the Failure; or (ii) an Airworthiness Directive or recommendations contained in mandatory compliance Service Bulletins requiring compliance within a specified number of Flight Hours or Flight Cycles; or (iii) Rolls-Royce’s written recommendation to perform scheduled maintenance which requires an Engine shop visit at scheduled intervals, and requires the separation of a pair of major module mating engine flanges in order to carry out Repair. | I15: N/A | J15: 15 years or when engines become "Qualified" under the Enhanced Shop Visit Rate Guarantee | K15: Annual
B16: Surge (Whole Flight) Guarantee | C16: SURGE | D16: Qualified Surges will not exceed a cumulative rate of 0.015 per 1000 Flight Hours. | E16: A fixed credit note of $250,000 for each excess Qualified Surge. | F16: At the end of each 6 month period during the Term of Guarantee, Emirates will provide Rolls-Royce with the following: • a list of all Engine surges during such 6 month period; and • such information as Rolls-Royce may reasonably require to enable Rolls-Royce to determine which surges are Qualified Surges. | G16: Rolls-Royce’s sole obligation will be to provide the Remedy less any credits already provided on the second and each subsequent Anniversary Date if the cumulative number of Qualified Surges exceeds the Measure. | H16: “Qualified Surge” means a major aerodynamic stall and reversal of airflow at high power through an Engine (as evidenced by Emirates to Rolls-Royce’s reasonable satisfaction) during a revenue flight, due to the aerodynamic breakdown of the airflow through any of the Engine’s compressors, where such breakdown is caused for any reason except lightning strikes or as specified in Clause 10 of this Agreement. | I16: N/A | J16: 15 years | K16: Annual
B17: Uncontained Failure Guarantee | C17: UNCONT | D17: The occurrence of a Qualified Uncontained Failure. | E17: A credit note per Qualified Uncontained Failure equal to the lesser of: (a) the Qualifying Repair Costs; or (b) $1,000,000; | F17: If an uncontained failure occurs during the Term of Guarantee which is suspected to be a Qualified Uncontained Failure, then Emirates will: • submit a claim to Rolls-Royce within 3 calendar months of such uncontained failure; and • provide such information as Rolls-Royce may reasonably require to enable Rolls-Royce to determine if such uncontained failure is a Qualified Uncontained Failure. 2) Evidence of Failure per event. | G17: If a Qualified Uncontained Failure occurs, then Rolls-Royce’s sole obligation and liability will be to provide the Remedy. | H17: “Qualified Uncontained Failure” means the Failure of a Dressed Engine (as defined in the Specification) Part that causes the high energy release of a rotating Engine Part through the Engine’s nacelle envelope. “Qualifying Repair Costs” means, in respect of a Qualified Uncontained Failure, the amount equal to the demonstrated cost to Emirates of repairing damage done to: (i) the Engine suffering the Qualified Uncontained Failure; and (ii) the Aircraft on which such Engine was installed at the time of such Qualified Uncontained Failure (including any one or more of the other Engines installed on such Aircraft at the time of such Qualified Uncontained Failure). in each case caused wholly and exclusively by such Qualified Uncontained Failure. | I17: N/A | J17: 15 years | K17: Event Based
B18: Disruption Index Guarantee | C18: DI | D18: The Disruption Figure Index as calculated in Section 7 (Formula) will not exceed a cumulative rate of 0.04 per 100 revenue departures. | E18: A fixed credit note of $50,000 for each excess Qualified Delay. A fixed credit note of $250,000 for each excess Qualified Cancellation. A fixed credit note of $250,000 for each excess Qualified Unplanned Engine Removal. A fixed credit note of $250,000 for each excess Qualified Shutdown. The rate of compensation per excess Qualified Event will be calculated in accordance with the Formula. | F18: 1) List of events which Emirates consider to be "Qualified Event" as per the definition in Schedule 5 of DEG9008 .At the end of each 6 month period during the Term of Guarantee, Customer will provide Rolls-Royce with the following: • a list of all delays and cancellations during such 6 month period; • a list of all unplanned Engine removals during such 6 month period; • a list of all in-flight Engine shutdowns during such 6 month period; and • such information as Rolls-Royce may reasonably require to enable Rolls-Royce to determine which of such delays, cancellations, unplanned Engine removals and in-flight Engine shutdowns are Qualified Events. | G18: Rolls-Royce’s sole obligation will be to provide the Remedy at the end of the Term of Guarantee if the cumulative number of Qualified Events exceeds the Measure. | H18: “Qualified Event” means a Qualified Delay, Qualified Cancellation, Qualified Shutdown or Qualified Unplanned Engine Removal which is determined to have been caused solely by a Failure of a Part of the Dressed Engine (as defined in the Specification), provided that: (a) only one Qualified Event will be deemed to occur for any one Failure; and (b) if the event could have been prevented by timely maintenance action or the incorporation of any modifications for which parts, instruction and Service Bulletins had been made available to Customer by Rolls-Royce, it will not constitute a Qualified Event. • “Qualified Cancellation” means the cancellation of a revenue flight of an Aircraft by Customer, where the flight is not resumed or reinstated, with the same or a different flight number, within 24 hours of the start of the original delay leading to such cancellation, which is determined to be a Qualified Event. • “Qualified Delay” means the delay of a revenue flight of an Aircraft by Customer of 15 minutes or more after the scheduled time of departure of such flight, which is determined to be a Qualified Event. • “Qualified Unplanned Engine Removal” means the unplanned, necessary removal of an Engine from an Aircraft where: (a) the Engine is incapable of operation within Aircraft Manual limits; and (b) all reasonable endeavours to make the Engine serviceable on-wing through Line Maintenance actions have been exhausted; and (c) the removal could not have been predicted using trend monitoring or other data that was available to Customer 48 hours prior to such removal. The following will not be considered to be Qualified Unplanned Engine Removals: (i) Engine removals occurring during ‘C-Check’ or ‘D-Check’ aircraft letter checks; (ii) where Rolls-Royce provides a technical variance to Customer to allow an Engine to remain on-wing beyond the Aircraft Manual limits and Customer elects not to accept the technical variance and removes the Engine • “Qualified Shutdown” means the necessary in-flight shutdown of an Engine during the course of a revenue flight of the Aircraft by Customer. | I18: • Customer will procure and maintain at the Main Base and line stations the level of Parts and Tooling as determined pursuant to Clause 11.1(a) of this Agreement • Customer will ensure that its line maintenance personnel will receive initial and follow-up training from time to time on Engine maintenance troubleshooting techniques. | J18: 15 years | K18: End of Term
B19: Oil Consumption Guarantee | C19: OIL | D19: Qualified Oil Consumption will not exceed a cumulative rate of 0.19 litres per Flight Hour. | E19: A credit note for the excess Qualified Oil Consumption multiplied by the Oil Cost, subject to a fixed maximum value of $250,000 per Aircraft over the Term of Guarantee. | F19: 1) The number of litres of oil consumed by Engines during such 6 month period. At the end of each 6 month period during the Term of Guarantee, Emirates will provide Rolls-Royce with the following: • the number of litres of oil consumed by Engines during such 6 month period; • an Officer’s Review Certificate certifying the Oil Cost during such 6 month period; and • such information as Rolls-Royce may reasonably require to determine the Qualified Oil Consumption. | G19: Rolls-Royce’s sole obligation will be to provide the Remedy less any credits already provided on the second and each subsequent Anniversary Date if the cumulative amount of Qualified Oil Consumption exceeds the Measure. | H19: “Qualified Oil Consumption” means the volume of oil consumed by Engines during revenue flights. “Oil Cost” means the substantiated average cost to Emirates of aviation oil, after the deduction of any subsidies or other allowances received by Emirates. The Oil Cost covers aviation oil only and excludes without limitation, any fees, taxes, or surcharges. “Officer’s Review Certificate” means a certificate certifying Emirates’ Oil Cost in the format of Exhibit B to Schedule 5 of the PA. | I19: • Rolls-Royce may request that Emirates removes Engines for a shop visit, in accordance with the TotalCare Services Agreement dated on or around the date of this Agreement (Contract reference: DEG 9009), in order to eliminate or reduce oil consumption. Such request will constitute a Qualified Event as defined in the TotalCare Services Agreement. If Emirates declines to remove Engines within a reasonable timescale then Rolls-Royce’s liability under this Guarantee will cease until such shop visit is carried out. | J19: 15 years | K19: Annual
B20: Turbine Gas Turbine Deterioration Guarantee | C20: TGT | D20: The occurrence of a Qualified TGT Removal. | E20: A fixed credit note per Qualified TGT Removal of US$250,000 factored as follows: For Enhanced Thrust Engines: • decreasing pro-rata from 100% from new to 0% at 2,330 Flight Cycles run since new. For Trent 972 Engines: • decreasing pro-rata from 100% from new to 0% at 3,400 Flight Cycles run since new. | F20: If a TGT removal occurs during the Term of Guarantee which is suspected to be a Qualified TGT Removal, then Customer will: • notify Rolls-Royce within 3 days; • if requested by Rolls-Royce, arrange for a calibration run in a test cell approved by Rolls-Royce to validate the loss of TGT margin. If the Engine is found to be within the Guarantee limits, the cost of testing shall be at Customer’s expense. | G20: If a Qualified TGT Removal occurs, then Rolls-Royce’s sole obligation shall be to provide the Remedy. | H20: “Qualified TGT Removal” means the mandatory removal of an Engine from an Aircraft by Customer due solely to such Engine exceeding the TGT Red Line Limit on a revenue flight during the first 2,330 Flight Cycles run since new, with respect to Enhanced Thrust Engines and 3,400 Flight Cycles run since new, with respect to Trent 972 Engines, where such Engine requires a shop visit at an Overhaul Base to restore TGT margin, provided that: i) all reasonable endeavours to restore TGT margin on-wing through line maintenance action have been exhausted; and ii) such removal shall not be a Qualified TGT Removal if the Engine is found to be within the Guarantee limits when a calibration run in a test cell approved by Rolls-Royce is carried out. “TGT Red Line Limit” means the maximum stabilised Turbine Gas Temperature (TGT) operating limit at the maximum take-off rating, as defined in the Manuals. | I20: N/A | J20: 15 years | K20: Event Based
B21: Enhanced Shop Visit Rate Guarantee | C21: ESVRG | D21: Qualified Events will not exceed a cumulative rate of 0.069 per 1000 Flight Hours. | E21: A fixed credit note of: - US$1,250,000 for each excess Qualified HPTB Shop Visit; and - US$250,000 for each excess Qualified Shop Visit. The rate of compensation per excess Qualified Event will be calculated in accordance with the Formula. | F21: Reporting Obligations At the end of each 6 month period during the Term of Guarantee, Emirates will provide Rolls-Royce with the following: - a list of all shop visits during such 6 month period; - notification to Rolls-Royce of when each Engine has been fitted with the Improved Annulus Filler Standard in accordance with Clause 1.3 of the Amended and Restated SLA1; - notification to Rolls-Royce of when each Aircraft has been fitted with the Improved Auto-derate Software in accordance with Clause 1.3 of the Amended and Restated SLA1; - a list of which Engines have been operated on which Aircraft to enable Rolls-Royce to determine which are Qualified Engines; - a list of Engine Flight Hours by month for Qualified Engines to allow the Qualified Flight Hours to be determined. | G21: At annual intervals during the Term of Guarantee, the cumulative rate of Qualified Events will be calculated for Qualified Engines using all Qualified Flight Hours (“Cumulative Rate”) to allow performance of the Cumulative Rate against the Measure to be determined. Rolls-Royce’s sole obligation for any breach of this Enhanced Shop Visit Rate Guarantee will be to provide the Remedy less any credits already provided on the second and each subsequent Anniversary Date if the cumulative number of Qualified Events exceeds the Measure. | H21: - “Amended and Restated” means the amended and restated SLA1 dated on or around the date of this Amendment 2 to the Product Agreement. - “Final Installed Longstop Date” has the meaning given to it in the Amended and Restated SLA1. - “Improved Annulus Filler Standard” has the meaning given to it in the Amended and Restated SLA1. - “Improved Auto-derate Software” has the meaning given to it in the Amended and Restated SLA1. - “Improved HPTB Standard” has the meaning given to it in the Amended and Restated SLA1. - “Qualified Engine” means an Engine that has been (i) fitted with the Improved HPTB Standard; (ii) fitted with the Improved Annulus Filler Standard; and (iii) operated on Aircraft that uses Improved Auto-derate Software; throughout its time on wing since new or since its last Restoration Shop Visit (where such Improved HPTB Standard were fitted as new). Notwithstanding the foregoing, Engines delivered on new Aircraft after the Final Installed Longstop Date, will be deemed a Qualified Engine at the date of delivery to Emirates. Engines that have a Restoration Shop Visit after the Final Installed Longstop Date and are not determined to be a Qualified Engine solely because of the non-availability of the Improved Annulus Filler Standard, shall be deemed a Qualified Engine from the time of such Restoration Shop Visit. All Engines will be deemed Qualified Engines from their last Restoration Shop Visit prior to 31 December 2022. - “Qualified Event” means a Qualified Shop Visit or Qualified HPTB Shop Visit provided that only one Qualified Event will be deemed to occur for any one Qualified Engine shop visit. - “Qualified Flight Hours” means the Flight Hours flown by each Qualified Engine since becoming a Qualified Engine. - “Qualified HPTB Shop Visit” means a shop visit of a Qualified Engine that occurs prior to expiry of the Amended and Restated SLA1 and is required solely as a result of the Failure of the Improved HPTB Standard where the shop visit was necessary to correct the Failure. - “Qualified Shop Visit” means a shop visit of a Qualified Engine that is required solely as a result of the following: (i) a Failure of a Part of the Dressed Engine (as defined in the Specification) where the shop visit was necessary to correct the Failure; or (ii) an Airworthiness Directive or recommendations contained in mandatory compliance Service Bulletins requiring compliance within a specified number of Flight Hours or Flight Cycles; or (iii) Rolls-Royce’s written recommendation to perform scheduled maintenance which requires an Engine shop visit at scheduled intervals, and requires the separation of a pair of major module mating engine flanges in order to carry out Repair. - “+H21” has the meaning given to it in the TotalCare Agreement. | I21: The Parties acknowledge that the Improved HPTB Standard and Improved Annulus Filler Standard may be provided on new Aircraft or be retrofitted, in each case in accordance with Clause 1.2 and 1.3 of the Amended and Restated SLA1. Engines will be incorporated into this Enhanced Shop Visit Rate Guarantee upon becoming a Qualified Engine at which point such Engine will no longer be considered part of the Shop Visit Rate Guarantee. Emirates undertakes to use the Improved Auto-derate Software to the maximum extent possible. Rolls-Royce acknowledges that such usage will be subject to operational considerations by Emirates, and that usage of the Improved Auto-derate Software is not a condition to Emirates’ ability to claim under this Enhanced Shop Visit Rate Guarantee. | K21: Annual
B23: Aircraft Availability HPTB Guarantee | C23: AA HPTB | D23: - Zero Qualified HPTB Cancellations - Zero Qualified HPTB Delas - Zero Qualified HPTB Shutdowns - Zero Qualified HPTB Diversions referred to as the "Measures". | E23: For Qualified HPTB Events excluding Qualified HPTB Delays: - A fixed, cash payment of US$750,000 (subject to escalation as per Clause 1.9 in the SLA1), in the event of a failure to meet any of the Measures (excluding Qualified HPTB Delay) which necessitates immediate remedial actions to be taken at Emirates' hub in Dubai. - A fixed, cash payment of US$2,500,000 (subject to escalation as per Clause 1.9 in this SLA1), in the event of a failure to meet any of the Measures (excluding Qualified HPTB Delay) which necessitates immediate remedial actions to be taken at a location other than Emirates' hub in Dubai. For Qualified HPTB Delays: - A fixed, cash payment of US$250,000 (subject to escalation as per Clause 1.9 in SLA1). If a Failure of the HPTB, or a failure in the delivery of the SLA1 Programme entitles Emirates to claim under more than one Qualified HPTB Event, then Emirates may only claim under one of the Qualified HPTB Events (at its election). | F23: At the end of each month during the Term of Guarantee, Emirates will provide Rolls-Royce with a list of all events together with such information as Rolls-Royce may reasonably require to determine whether such events are Qualified HPTB Events for the above remedies to enable Rolls-Royce to settle the claim(s) within 30 days. | G23: The provisions of clause 8.2 (b) of the Product Agreement will apply to this Aircraft Availability HPTB Guarantee. Any event claimed under this Aircraft Availability Guarantee will be excluded from any of the other Guarantee "Measures". | H23: - "Qualified HPTB Cancellation" means where an Aircraft is unavailable to perform a scheduled revenue dlight which leads to the cancellation of the flight by Emirates where the flight is not resumed or reinstated, with the same or a different flight number, within 3 hours of the start of the original delay leading to suhc cancellation, which is caused by a Failure of the HPTB, or a failure in the delivery of the SLA1 Programme. A Qualified HPTB Cancellation can be casued by a planned or unplanned Engine removal. - "Qualified HPTB Delay" means the delay of a revenue flight of an Aircraft by Emirates of 15 minnutes or more after the scheduled time of departure of such flight, which is caused by a Failure of the HPTB, or a failure in the delivery of the SLA1 Programme. - "Qualified HPTB Shutdown" means the necessary in-flight shutdown of an Engine during the course of a revenue flight of the Aircraft by Emirates caused by a Failure of the HPTB or a dailure in the delivery of the SLA1 Programme. "Qualified HPTB Diversion" means the diversion of an Aircraft on a revenue flight by Emirates to an airport other than the destination or departure airport, or the return of an Aircraft on a revenue flight by Emirates to the airport of departure, which is determined to have been caused by a Failure of the HPTB, or a failure in the delivery of the SLA1 Programme. "Qualified HPTB Event" means a Qualified HPTB Delay, a Qualified HPTB Cancellation, a Qualified HPTB Diversion or a Qualified HPTB Shutdown. "Term of Guarantee" means the period commencing from the delviery of Aircraft #1 to Emirates and continuing until the expiration of this SLA1 in accordance with Clause 1.7. | I23: N/A | K23: Monthly
B25: Enhanced HPTB Measure | C25: EHPTB | D25: - Qualified Shop Visits will not exceed a cumulative rate of 0.0952 per 1000 Qualified Flight Hours on a 6-month rolling average basis. | E25: A fixed credit note of US$500,000 per Aircraft for each month that the Measure is exceeded, subject to a fixed cap of US$600,000,000 over the Term of the Enhanced HPTB Measure with a fixed maximum value of US$100,000,000 per year. | F25: At the end of each onth period during the Term of Enhanced HPTB Measure, Emirates will provide Rolls-Royce with the following: - a list of all shop visits during such one month period; - notification to Rolls-Royce of when each Engine has been fitted with the Improved Annulus Filler Standard in accordance with clause 1.3. of SLA1; - notification to Rolls-Royce of when each Aircraft has been fitted with the Improved Auto-derate Software in accordance with Clause 1.3 of the SLA1; - a list of which Engines have been operated on which Aircraft to enable Rolls-Royce to determine which are Qualified Engines; - a list of Engine Flight Hours by month for Qualified Engines to allow the Qualified Flight Hours to be determined; to enable Rolls-Royce to settle the claim(s) by credit note within 30 days. | G25: At monthly intervals during the Term of Enhanced HPTB Measure, the cumulative rate of Qualified HPTB Shop Visits will be calculated for Qualified Engines using all Qualified Flight Hours ("Cumulative Rate"). Once a 6 month rolling average of the Cumulative Rate can be established and monthly thereafter ("Rolling Average Rate"), perfromance of the Rolling Average Rate against the Measure will be determined. Rolls-Royce's sole oblighation will be to provide the Remedy less any credits already provided if the Rolling Average Rate of Qualified HPTB Shop Visits exceeds the Measure. | H25: - "Failure" has the meaning given to it in the Product Agreement. - "Qualified Engine" means an Engine that has been (i) fitted with the Improved HPTB Standard; (ii) fitted with the Improved Annulus Filler Standard; and (iii) operated on Aircraft that uses Improved Auto-derate Software; throughout its time on wing since new or since its last Restoration Shop Visit (as defined in the TotalCare Agreement) (where such Improved HPTB Standard HPTN were fitted as new). Notwithstanding the foregoing, Engines delivered on new Aircraft after the Final Installed Longstop Date, will be deemed a Qualified Engine at the date of delivery to Emirates. Engines that have a Restorative Shop Visit after the Final Installed Longstop Date and are not determined to be a Qualified Engine solely because of the non-availability of the Improved Annulus Filler Standard, shall be deemed a Qualified Engine from the time of such Restoration Shop Visit. All Engines will be deemed Qualified Engines from their last Restoration Shop Visit prior to 31 December 2022. - "Qualified Flight Hours" means the Flight Hours flown by each Qualified Engine since becoming a Qualified Engine. - "Qualified HPTB Shop Visit" means a shop visit of a Qualified Engine that is required solely as a result of Failure of the HPTB where the shop visit was necessary to correct the Failure. "Term of Enhanced HPTB Measure" means the period starting on signature of SLA1 until expiry of SLA1 in accordance with Clause 1.7. | I25: The Parties acknowledge that the Improved HPTB Standard and Improved Annulus Filler Standard may be provided on new Aircraft or be retrofitted, in each case in accordance with Clause 1.2 and 1.3 of the SLA1. Emirates undertakes to use the Improved Auto-derate Software to the maximum extent possible. Rolls-Royce acknowledges that such usage will be subject to operational considerations by Emirates, and that usage of the Improved Auto-derate Software is not a condition to Emirates' ability to claim under this Enhanced HPTB Measure. Except as set out in the Schedule 1, the provisions of Clause 8 of the Product Agreement will apply to this Enhanced HPTB Measure, where any reference to "Guarantee" will be construed as a reference to this Enhanced HPTB Measure. Rolls-Royce acknowledges that Emirates is entitled to make a claim under both the Enhanced Shop Visit Rate Guarantee and this Enhanced HPTB Measure. | J25: Until the expiry of SLA1 in accordance with Clause 1.7 of SLA1 | K25: Monthly

Sheet CHARTS
E3: CHARTS
D9: CLAIMS TO DATE | K9: ENHANCED LINE MAINTENANCE BURDEN
C11: Row Labels | D11: ANNUAL CREDIT NOTE VALUE | E11: Sum of CUMULATIVE CLAIM VALUE
C12: 2019 | D12: 5000 | E12: 5000
C13: 2020 | D13: 50000 | E13: 55000
C14: 2021 | D14: 700000 | E14: 755000
C15: Grand Total | D15: 755000 | E15: 815000
D36: RATE BASED GUARANTEE WEIGHT EVENTS | K36: DISRUPTION INDEX GUARANTEE EVENTS
B58: TYPE OF GUARANTEE | C58: (All)
B60: Row Labels | C60: Max of Total Events | D60: Sum of Allowable Events
B61: Year 1 | C61: 1 | D61: 3.7861706
B62: Year 2 | C62: 1 | D62: 13.39124
B63: Year 3 | C63: 1 | D63: 26.017105
B64: Year 4 | C64: 1 | D64: 26.017105
B65: Year 5 | C65: 1 | D65: 26.017105
B66: Year 6 | C66: 1 | D66: 26.017105
B67: Year 7 | C67: 1 | D67: 26.017105
B68: Year 8 | C68: 1 | D68: 26.017105
B69: Year 9 | C69: 1 | D69: 26.017105
B70: Year 10 | C70: 1 | D70: 26.017105
B71: Year 11 | C71: 1 | D71: 26.017105
B72: Year 12 | C72: 1 | D72: 26.017105
... B76: Grand Total | C76: 1 | D76: 355.39977
D78: OIL CONSUMPTION
B83: Row Labels | C83: Sum of Total Events | D83: Max of Cumulative Events
B84: Year 1 | C84: 0 | D84: 0
B85: Year 2 | C85: 2 | D85: 2
B86: Year 3 | C86: 8 | D86: 10
B87: Year 4 | C87: 0 | D87: 10
B88: Year 5 | C88: 0 | D88: 10
B89: Year 6 | C89: 0 | D89: 10
B90: Year 7 | C90: 0 | D90: 10
B91: Year 8 | C91: 0 | D91: 10
B92: Year 9 | C92: 0 | D92: 10
B93: Year 10 | C93: 0 | D93: 10
B94: Year 11 | C94: 0 | D94: 10
B95: Year 12 | C95: 0 | D95: 10
... B99: Grand Total | C99: 10 | D99: 10
C100: Row Labels | D100: Sum of Cumulative Oil Consumption/EFH | E100: Sum of Allowable Oil Consumption/EFH
C101: Year 1 | D101: 200 | E101: 169.10593
...

Sheet EFH AND REV DEPS
I2: Emirates
G3: Trent 900 Guarantee Administration
D4: Engine Flying Hours and Revenue Departures
C7: GUARANTEE YEAR
C8: END OF YEAR 1 | D8: END OF YEAR 2 | E8: END OF YEAR 3 | F8: END OF YEAR 4 | G8: END OF YEAR 5 | H8: END OF YEAR 6 | I8: END OF YEAR 7 | J8: END OF YEAR 8 | K8: END OF YEAR 9 | L8: END OF YEAR 10 | M8: END OF YEAR 11 | N8: END OF YEAR 12 | O8: END OF YEAR 13 | P8: END OF YEAR 14 | Q8: END OF YEAR 15
C9: 26/12/2016 - 31/12/2017 | D9: 01/01/2018 - 31/12/2018 | E9: 01/01/2019 - 31/12/2019 | F9: 01/01/2020 - 31/12/2020 | G9: 01/01/2021 - 31/12/2021 | H9: 01/01/2022 - 31/12/2022 | I9: 01/01/2023 - 31/12/2023 | J9: 01/01/2024 - 31/12/2024 | K9: 01/01/2025 - 31/12/2025 | L9: 01/01/2026 - 31/12/2026 | M9: 01/01/2027 - 31/12/2027 | N9: 01/01/2028 - 31/12/2028 | O9: 01/01/2029 - 31/12/2029 | P9: 01/01/2030 - 31/12/2030 | Q9: 01/01/2031 - 31/12/2031
C10: 2017 | D10: =C10+1 -> 2018 | E10: =D10+1 -> 2019 | F10: =E10+1 -> 2020 | G10: =F10+1 -> 2021 | H10: =G10+1 -> 2022 | I10: =H10+1 -> 2023 | J10: =I10+1 -> 2024 | K10: =J10+1 -> 2025 | ... Q10: =P10+1 -> 2031
B11: FLIGHT HOURS | C11: =SUMIF('HOURS&CYCLES INPUT'!$D:$D,'EFH AND REV DEPS'!C10,'HOURS&CYCLES INPUT'!$F:$F)+SUMIF('HOURS&CYCLES INPUT'!$D:$D,2016,'HOURS&CYCLES INPUT'!$F:$F) -> 89357.5 | D11: =SUMIF('HOURS&CYCLES INPUT'!$D:$D,'EFH AND REV DEPS'!D10,'HOURS&CYCLES INPUT'!$F:$F) -> 237299.8 | E11: =SUMIF('HOURS&CYCLES INPUT'!$D:$D,'EFH AND REV DEPS'!E10,'HOURS&CYCLES INPUT'!$F:$F) -> 370691.76 | F11: =SUMIF('HOURS&CYCLES INPUT'!$D:$D,'EFH AND REV DEPS'!F10,'HOURS&CYCLES INPUT'!$F:$F) -> 136928.84 | G11: =SUMIF('HOURS&CYCLES INPUT'!$D:$D,'EFH AND REV DEPS'!G10,'HOURS&CYCLES INPUT'!$F:$F) -> 188422.04 | H11: =SUMIF('HOURS&CYCLES INPUT'!$D:$D,'EFH AND REV DEPS'!H10,'HOURS&CYCLES INPUT'!$F:$F) -> 450698.16 | I11: =SUMIF('HOURS&CYCLES INPUT'!$D:$D,'EFH AND REV DEPS'!I10,'HOURS&CYCLES INPUT'!$F:$F) -> 566748.21 | J11: =SUMIF('HOURS&CYCLES INPUT'!$D:$D,'EFH AND REV DEPS'!J10,'HOURS&CYCLES INPUT'!$F:$F) -> 579715.71 | K11: =SUMIF('HOURS&CYCLES INPUT'!$D:$D,'EFH AND REV DEPS'!K10,'HOURS&CYCLES INPUT'!$F:$F) -> 542452.36 | ... Q11: =SUMIF('HOURS&CYCLES INPUT'!$D:$D,'EFH AND REV DEPS'!Q10,'HOURS&CYCLES INPUT'!$F:$F) -> 0
B12: CUM FLIGHT HOURS | C12: =C11 -> 89357.5 | D12: =C12+D11 -> 326657.3 | E12: =D12+E11 -> 697349.06 | F12: =E12+F11 -> 834277.9 | G12: =F12+G11 -> 1022699.9 | H12: =G12+H11 -> 1473398.1 | I12: =H12+I11 -> 2040146.3 | J12: =I12+J11 -> 2619862 | K12: =J12+K11 -> 3162314.4 | ... Q12: =P12+Q11 -> 3162314.4
B13: REVENUE DEPARTURES | C13: =SUMIF('HOURS&CYCLES INPUT'!$D:$D,'EFH AND REV DEPS'!C$10,'HOURS&CYCLES INPUT'!$G:$G)+SUMIF('HOURS&CYCLES INPUT'!$D:$D,2016,'HOURS&CYCLES INPUT'!$G:$G) -> 14710 | D13: =SUMIF('HOURS&CYCLES INPUT'!$D:$D,'EFH AND REV DEPS'!D$10,'HOURS&CYCLES INPUT'!$G:$G) -> 36005.08 | E13: =SUMIF('HOURS&CYCLES INPUT'!$D:$D,'EFH AND REV DEPS'!E$10,'HOURS&CYCLES INPUT'!$G:$G) -> 50131.08 | F13: =SUMIF('HOURS&CYCLES INPUT'!$D:$D,'EFH AND REV DEPS'!F$10,'HOURS&CYCLES INPUT'!$G:$G) -> 19023.84 | G13: =SUMIF('HOURS&CYCLES INPUT'!$D:$D,'EFH AND REV DEPS'!G$10,'HOURS&CYCLES INPUT'!$G:$G) -> 31733.32 | H13: =SUMIF('HOURS&CYCLES INPUT'!$D:$D,'EFH AND REV DEPS'!H$10,'HOURS&CYCLES INPUT'!$G:$G) -> 52036 | I13: =SUMIF('HOURS&CYCLES INPUT'!$D:$D,'EFH AND REV DEPS'!I$10,'HOURS&CYCLES INPUT'!$G:$G) -> 64594.82 | J13: =SUMIF('HOURS&CYCLES INPUT'!$D:$D,'EFH AND REV DEPS'!J$10,'HOURS&CYCLES INPUT'!$G:$G) -> 64578.44 | K13: =SUMIF('HOURS&CYCLES INPUT'!$D:$D,'EFH AND REV DEPS'!K$10,'HOURS&CYCLES INPUT'!$G:$G) -> 61320 | ... Q13: =SUMIF('HOURS&CYCLES INPUT'!$D:$D,'EFH AND REV DEPS'!Q$10,'HOURS&CYCLES INPUT'!$G:$G) -> 0
B14: CUM REV DEPS | C14: =C13 -> 14710 | D14: =C14+D13 -> 50715.08 | E14: =D14+E13 -> 100846.16 | F14: =E14+F13 -> 119870 | G14: =F14+G13 -> 151603.32 | H14: =G14+H13 -> 203639.32 | I14: =H14+I13 -> 268234.14 | J14: =I14+J13 -> 332812.58 | K14: =J14+K13 -> 394132.58 | ... Q14: =P14+Q13 -> 394132.58

Sheet CLAIMS SUMMARY
E3: CLAIMS SUMMARY
B7: DATE | C7: YEAR | D7: CREDIT NOTE REFERENCE | E7: GUARANTEE | F7: CREDIT NOTE VALUE | G7: CUMULATIVE CLAIM VALUE
G8: =F8 -> 0
G9: =G8+F9 -> 0
G10: =G9+F10 -> 0
G11: =G10+F11 -> 0
C12: =RIGHT(B12,4) | G12: =G11+F12 -> 0
C13: =RIGHT(B13,4) | G13: =G12+F13 -> 0
C14: =RIGHT(B14,4) | G14: =G13+F14 -> 0
C15: =RIGHT(B15,4) | G15: =G14+F15 -> 0
C16: =RIGHT(B16,4) | G16: =G15+F16 -> 0
C17: =RIGHT(B17,4) | G17: =G16+F17 -> 0
C18: =RIGHT(B18,4) | G18: =G17+F18 -> 0
C19: =RIGHT(B19,4) | G19: =G18+F19 -> 0
C20: =RIGHT(B20,4) | G20: =G19+F20 -> 0
C21: =RIGHT(B21,4) | G21: =G20+F21 -> 0
C22: =RIGHT(B22,4) | G22: =G21+F22 -> 0
C23: =RIGHT(B23,4) | G23: =G22+F23 -> 0
... C42: =RIGHT(B42,4) | G42: =G41+F42 -> 0

Sheet EVENT ENTRY
G1: Emirates | I1: Swiss Intenrational Airlines
G2: Trent 900 Guarantee Administration | N2: Stage 1 - Emirates Initial position
G3: Event Input | N3: Stage 2 - RR Initial position
N4: Stage 3 - Agreed position
B5: Date | C5: Engine Serial No. | D5: A/C No. & Position | E5: TSN or TSR (hours) (Indicate as applicable) | F5: CSN or CSR (cycles) (Indicate as applicable) | G5: Cause of event/Disruption event type (Please attach substantiating data to validate claim) | J5: Emirates Input Qualified/Non-Qualified | K5: Emirates - Justification | L5: RR Input Qualified/Non-Qualified | M5: RR - Justification | N5: Guarantee Coverage | O5: Further comments
A6: =N6 -> ABTO | B6: 42839.052 | C6: 91416 | D6: A6-EUN | G6: ACCELERATION SLOW - NON COMPLIANCE WITH MANUFACTURE PROCESSES/RULES/STANDARDS | L6: Non-qualified | M6: Non-basic | N6: ABTO
A7: =N7 -> DIV & ATB | B7: 43000.02 | C7: 91423 | D7: A6-EUP Pos 4 | G7: Compressor stall/surge | J7: Qualified | L7: Qualified | M7: VSV SYSTEM | N7: DIV & ATB
A8: =N8 -> 0 | B8: 42813 | C8: 91415 | D8: A6-EUN | G8: Major Inner FCD damage due to Operator Maintenance Error & Fan Blade Change (1-off) | L8: Non-basic | M8: NO ENGINE INVOLVEMENT
A9: =N9 -> 0 | B9: 42824.458 | C9: 91409 | D9: A6-EUM | G9: IP BLEED VALVE UPPER STARBOARD REPLACED | L9: Basic | M9: [900] BLEED VALVE FAULT
A10: =N10 -> 0 | B10: 43003.501 | C10: 91413 | D10: A6-EUN | G10: A6-EUN - ESN 91413 – ENG 2 FADEC SYS FAULT - HMU REPLACED (EK 342 – DXB / KUL) | L10: Non-basic | M10: [900] HMU MESSAGE
A11: =N11 -> 0 | B11: 43015.701 | C11: 91429 | D11: A6-EUQ | G11: ENG 4 FADEC SYS FAULT - EEC REPLACED | L11: Basic | M11: [900] EEC REMOVAL
A12: =N12 -> 0 | B12: 43104.645 | C12: 91455 | D12: A6-EUX | G12: Class 4 Fault - ACTUATOR-VSV,ENG / HARNESS-EEC TO CORE ZONE 2 CHANNEL B,ENG | L12: Non-basic
A13: =N13 -> 0 | B13: 43121.533 | C13: 91492 | D13: A6-EUV | G13: HOC Leading to AOG | L13: Basic | M13: [900] ADS D-SEAL
A14: =N14 -> 0 | B14: 43299.021 | C14: 91484 | D14: A6-EUT | G14: AOG DUE TO HIGH OIL CONSUMPTION - LEAK FROM OIL TANK SIGHTGLASS | L14: Open | M14: [900] OIL LEAK - OIL TANK SIGHT GLASS
A15: =N15 -> 0 | B15: 43320.389 | C15: 91427 | D15: A6-EUQ | G15: Engine starter control valve fault | L15: Basic | M15: [900] FAILED TO START
A16: =N16 -> 0 | B16: 43376.927 | C16: 91512 | D16: A6-EUU | G16: Engine Run Down and loss of Thrust Control - EHM Advisory Flame out Recovery | L16: Basic | M16: [900] LOSS OF THRUST CONTROL
A17: =N17 -> 0 | B17: 43380.724 | C17: 91512 | D17: A6-EUU | G17: ENG 2 FADEC SYS FAULT - Delay in LHR | L17: Basic | M17: [900] FADEC FAULT
A18: =N18 -> 0 | B18: 43433.579 | C18: 91418 | D18: A6-EUO | G18: A6-EUO # 4 ESN 91418 – Multiple ECAM messages after Engine Shut-down | L18: Basic | M18: [900] HMU REMOVAL
A19: =N19 -> 0 | B19: 43519.667 | C19: 91547 | D19: A6-EVE | G19: Emirates A380 aircraft A6-EVE position #4/91547 LOW OIL QTY | L19: Open | M19: [900] HP/IP VENT TUBE LEAK
A20: =N20 -> 0 | B20: 43526.708 | C20: 91437 | D20: A6-EVA | G20: LH VSV Actuator Replaced following CTRL SYS FAULT on Push Back | L20: Basic | M20: [900] CTL SYS FAULT
A21: =N21 -> 0 | B21: 43552.375 | C21: 91423 | D21: A6-EUP | G21: Anti-Ice PRV REPLACEMENT | L21: Non-basic | M21: [900] ANTI-ICE VALVE REMOVAL
A22: =N22 -> 0
A23: =N23 -> 0
A24: =N24 -> 0
A25: =N25 -> 0
A26: =N26 -> 0
A27: =N27 -> 0
A28: =N28 -> 0
A29: =N29 -> 0
A30: =N30 -> 0
A31: =N31 -> 0
A32: =N32 -> 0
A33: =N33 -> 0
... A59: =N59 -> 0

Sheet RATE BASED SUMMARY
H2: Emirates | J2: Swiss Intenrational Airlines
H3: Trent 900 Guarantee Administration
G4: Rate Based Guarantee Calculation Summary
C6: GUARANTEE YEAR
C7: ='EFH AND REV DEPS'!C8 -> END OF YEAR 1 | D7: ='EFH AND REV DEPS'!D8 -> END OF YEAR 2 | E7: ='EFH AND REV DEPS'!E8 -> END OF YEAR 3 | F7: ='EFH AND REV DEPS'!F8 -> END OF YEAR 4 | G7: ='EFH AND REV DEPS'!G8 -> END OF YEAR 5 | H7: ='EFH AND REV DEPS'!H8 -> END OF YEAR 6 | I7: ='EFH AND REV DEPS'!I8 -> END OF YEAR 7 | J7: ='EFH AND REV DEPS'!J8 -> END OF YEAR 8 | ... Q7: ='EFH AND REV DEPS'!Q8 -> END OF YEAR 15
C8: ='EFH AND REV DEPS'!C9 -> 26/12/2016 - 31/12/2017 | D8: ='EFH AND REV DEPS'!D9 -> 01/01/2018 - 31/12/2018 | E8: ='EFH AND REV DEPS'!E9 -> 01/01/2019 - 31/12/2019 | F8: ='EFH AND REV DEPS'!F9 -> 01/01/2020 - 31/12/2020 | G8: ='EFH AND REV DEPS'!G9 -> 01/01/2021 - 31/12/2021 | H8: ='EFH AND REV DEPS'!H9 -> 01/01/2022 - 31/12/2022 | I8: ='EFH AND REV DEPS'!I9 -> 01/01/2023 - 31/12/2023 | J8: ='EFH AND REV DEPS'!J9 -> 01/01/2024 - 31/12/2024 | ... Q8: ='EFH AND REV DEPS'!Q9 -> 01/01/2031 - 31/12/2031
B9: FLIGHT HOURS | C9: ='EFH AND REV DEPS'!C11 -> 89357.5 | D9: ='EFH AND REV DEPS'!D11 -> 237299.8 | E9: ='EFH AND REV DEPS'!E11 -> 370691.76 | F9: ='EFH AND REV DEPS'!F11 -> 136928.84 | G9: ='EFH AND REV DEPS'!G11 -> 188422.04 | H9: ='EFH AND REV DEPS'!H11 -> 450698.16 | I9: ='EFH AND REV DEPS'!I11 -> 566748.21 | J9: ='EFH AND REV DEPS'!J11 -> 579715.71 | ... Q9: ='EFH AND REV DEPS'!Q11 -> 0
B10: CUM FLIGHT HOURS | C10: ='EFH AND REV DEPS'!C12 -> 89357.5 | D10: ='EFH AND REV DEPS'!D12 -> 326657.3 | E10: ='EFH AND REV DEPS'!E12 -> 697349.06 | F10: ='EFH AND REV DEPS'!F12 -> 834277.9 | G10: ='EFH AND REV DEPS'!G12 -> 1022699.9 | H10: ='EFH AND REV DEPS'!H12 -> 1473398.1 | I10: ='EFH AND REV DEPS'!I12 -> 2040146.3 | J10: ='EFH AND REV DEPS'!J12 -> 2619862 | ... Q10: ='EFH AND REV DEPS'!Q12 -> 3162314.4
B11: REVENUE DEPARTURES | C11: ='EFH AND REV DEPS'!C13 -> 14710 | D11: ='EFH AND REV DEPS'!D13 -> 36005.08 | E11: ='EFH AND REV DEPS'!E13 -> 50131.08 | F11: ='EFH AND REV DEPS'!F13 -> 19023.84 | G11: ='EFH AND REV DEPS'!G13 -> 31733.32 | H11: ='EFH AND REV DEPS'!H13 -> 52036 | I11: ='EFH AND REV DEPS'!I13 -> 64594.82 | J11: ='EFH AND REV DEPS'!J13 -> 64578.44 | ... Q11: ='EFH AND REV DEPS'!Q13 -> 0
B12: CUM REV DEPS | C12: ='EFH AND REV DEPS'!C14 -> 14710 | D12: ='EFH AND REV DEPS'!D14 -> 50715.08 | E12: ='EFH AND REV DEPS'!E14 -> 100846.16 | F12: ='EFH AND REV DEPS'!F14 -> 119870 | G12: ='EFH AND REV DEPS'!G14 -> 151603.32 | H12: ='EFH AND REV DEPS'!H14 -> 203639.32 | I12: ='EFH AND REV DEPS'!I14 -> 268234.14 | J12: ='EFH AND REV DEPS'!J14 -> 332812.58 | ... Q12: ='EFH AND REV DEPS'!Q14 -> 394132.58
C14: GUARANTEE MONTH
A15: Year | B15: TYPE OF GUARANTEE | C15: JANUARY | D15: FEBRUARY | E15: MARCH | F15: APRIL | G15: MAY | H15: JUNE | I15: JULY | J15: AUGUST | K15: SEPTEMBER | L15: OCTOBER | M15: NOVEMBER | N15: DECEMBER | O15: Total Events | P15: Allowable Events | Q15: Remedy per Excess Event | R15: Cumulative Remedy Owed | S15: Cumulative Credit Issued | T15: Credit Due
A16: Year 1 | B16: DIV & ATB | K16: 1 | O16: =SUM(C16:N16) -> 1 | P16: =C12/100*0.008 -> 1.1768 | Q16: 250000 | R16: 0
A17: Year 1 | B17: ABTO | O17: =SUM(C17:N17) -> 0 | P17: =C12/100*0.008 -> 1.1768 | Q17: 250000 | R17: 0
A18: Year 1 | B18: RSR | O18: =SUM(C18:N18) -> 0 | P18: =C10/1000*0.0012 -> 0.107229 | Q18: 250000 | R18: 0
A19: Year 1 | B19: SURGE | O19: =SUM(C19:N19) -> 0 | P19: =C10/1000*0.015 -> 1.3403625 | Q19: 250000 | R19: 0
A20: Year 2 | B20: DIV & ATB | O20: =SUM(C20:N20)+O16 -> 1 | P20: =D12/100*0.008 -> 4.0572064 | Q20: 250000 | R20: =IF(O20>P20,SUM(Q20*SUM(O20-P20)),0) -> 0 | S20: =T16 -> 0 | T20: =IF(R20-S20>0,R20-S20,0) -> 0
A21: Year 2 | B21: ABTO | O21: =SUM(C21:N21)+O17 -> 0 | P21: =D12/100*0.008 -> 4.0572064 | Q21: 250000 | R21: =IF(O21>P21,SUM(Q21*SUM(O21-P21)),0) -> 0 | S21: 0 | T21: =IF(R21-S21>0,R21-S21,0) -> 0
A22: Year 2 | B22: RSR | O22: =SUM(C22:N22)+O18 -> 0 | P22: =D10/1000*0.0012 -> 0.39198876 | Q22: 250000 | R22: =IF(O22>P22,SUM(Q22*SUM(O22-P22)),0) -> 0 | S22: 0 | T22: =IF(R22-S22>0,R22-S22,0) -> 0
A23: Year 2 | B23: SURGE | O23: =SUM(C23:N23)+O19 -> 0 | P23: =D10/1000*0.015 -> 4.8998595 | Q23: 250000 | R23: =IF(O23>P23,SUM(Q23*SUM(O23-P23)),0) -> 0 | S23: 0 | T23: =IF(R23-S23>0,R23-S23,0) -> 0
A24: Year 3 | B24: DIV & ATB | O24: =SUM(C24:N24)+O20 -> 1 | P24: =E12/100*0.008 -> 8.0676928 | Q24: 250000 | R24: =IF(O24>P24,SUM(Q24*SUM(O24-P24)),0) -> 0 | S24: =S20+T20 -> 0 | T24: =IF(R24-S24>0,R24-S24,0) -> 0
A25: Year 3 | B25: ABTO | O25: =SUM(C25:N25)+O21 -> 0 | P25: =E12/100*0.008 -> 8.0676928 | Q25: 250000 | R25: =IF(O25>P25,SUM(Q25*SUM(O25-P25)),0) -> 0 | S25: =S21+T21 -> 0 | T25: =IF(R25-S25>0,R25-S25,0) -> 0
A26: Year 3 | B26: RSR | O26: =SUM(C26:N26)+O22 -> 0 | P26: =E10/1000*0.0012 -> 0.83681887 | Q26: 250000 | R26: =IF(O26>P26,SUM(Q26*SUM(O26-P26)),0) -> 0 | S26: =S22+T22 -> 0 | T26: =IF(R26-S26>0,R26-S26,0) -> 0
A27: Year 3 | B27: SURGE | O27: =SUM(C27:N27)+O23 -> 0 | P27: =E10/1000*0.015 -> 10.460236 | Q27: 250000 | R27: =IF(O27>P27,SUM(Q27*SUM(O27-P27)),0) -> 0 | S27: =S23+T23 -> 0 | T27: =IF(R27-S27>0,R27-S27,0) -> 0
A28: Year 4 | B28: DIV & ATB | O28: =SUM(C28:N28)+O24 -> 1 | P28: =F12/100*0.008 -> 9.5896 | Q28: 250000 | R28: =IF(O28>P28,SUM(Q28*SUM(O28-P28)),0) -> 0 | S28: =S24+T24 -> 0 | T28: =IF(R28-S28>0,R28-S28,0) -> 0
A29: Year 4 | B29: ABTO | O29: =SUM(C29:N29)+O25 -> 0 | P29: =F12/100*0.008 -> 9.5896 | Q29: 250000 | R29: =IF(O29>P29,SUM(Q29*SUM(O29-P29)),0) -> 0 | S29: =S25+T25 -> 0 | T29: =IF(R29-S29>0,R29-S29,0) -> 0
A30: Year 4 | B30: RSR | O30: =SUM(C30:N30)+O26 -> 0 | P30: =F10/1000*0.0012 -> 1.0011335 | Q30: 250000 | R30: =IF(O30>P30,SUM(Q30*SUM(O30-P30)),0) -> 0 | S30: =S26+T26 -> 0 | T30: =IF(R30-S30>0,R30-S30,0) -> 0
